<sdf version='1.6'>
  <world name='default'>
    <light name='sun' type='directional'>
      <cast_shadows>1</cast_shadows>
      <pose frame=''>0 0 10 0 -0 0</pose>
      <diffuse>0.8 0.8 0.8 1</diffuse>
      <specular>0.1 0.1 0.1 1</specular>
      <attenuation>
        <range>1000</range>
        <constant>0.9</constant>
        <linear>0.01</linear>
        <quadratic>0.001</quadratic>
      </attenuation>
      <direction>-0.5 0.5 -1</direction>
    </light>
    <model name='ground_plane'>
      <static>1</static>
      <link name='link'>
        <collision name='collision'>
          <geometry>
            <plane>
              <normal>0 0 1</normal>
              <size>100 100</size>
            </plane>
          </geometry>
          <surface>
            <friction>
              <ode>
                <mu>100</mu>
                <mu2>50</mu2>
              </ode>
              <torsional>
                <ode/>
              </torsional>
            </friction>
            <contact>
              <ode/>
            </contact>
            <bounce/>
          </surface>
          <max_contacts>10</max_contacts>
        </collision>
        <visual name='visual'>
          <cast_shadows>0</cast_shadows>
          <geometry>
            <plane>
              <normal>0 0 1</normal>
              <size>100 100</size>
            </plane>
          </geometry>
          <material>
            <script>
              <uri>file://media/materials/scripts/gazebo.material</uri>
              <name>Gazebo/Grey</name>
            </script>
          </material>
        </visual>
        <self_collide>0</self_collide>
        <kinematic>0</kinematic>
      </link>
    </model>
    <model name='iCub'>
      <self_collide>1</self_collide>
      <pose frame=''>0 0 0.6 0 -0 3.14</pose>
      <link name='root_link'>
        <pose frame=''>0 0 0 0 -0 0</pose>
        <inertial>
          <pose frame=''>0 0 0 0 -0 0</pose>
          <mass>4.72</mass>
          <inertia>
            <ixx>0.01</ixx>
            <ixy>0</ixy>
            <ixz>0</ixz>
            <iyy>0.01</iyy>
            <iyz>0</iyz>
            <izz>0.01</izz>
          </inertia>
        </inertial>
        <collision name='root_link_collision'>
          <pose frame=''>0 0 0 0 -0 0</pose>
          <geometry>
            <mesh>
              <scale>1 1 1</scale>
              <uri>model://icub/meshes/collision/icub_simple_collision_root_link.dae</uri>
            </mesh>
          </geometry>
          <max_contacts>10</max_contacts>
          <surface>
            <contact>
              <ode/>
            </contact>
            <bounce/>
            <friction>
              <torsional>
                <ode/>
              </torsional>
              <ode/>
            </friction>
          </surface>
        </collision>
        <visual name='root_link_visual'>
          <pose frame=''>0 0 0 0 -0 0</pose>
          <geometry>
            <mesh>
              <scale>1 1 1</scale>
              <uri>model://icub/meshes/visual/icub_root_link.dae</uri>
            </mesh>
          </geometry>
        </visual>
        <self_collide>0</self_collide>
        <kinematic>0</kinematic>
      </link>
      <link name='l_hip_1'>
        <pose frame=''>0 -0.0681 -0.1199 3e-06 1.57079 3.14159</pose>
        <inertial>
          <pose frame=''>0 -0.0782 0 0 -0 0</pose>
          <mass>0.754</mass>
          <inertia>
            <ixx>0.01</ixx>
            <ixy>2.059e-06</ixy>
            <ixz>1.451e-06</ixz>
            <iyy>0.01</iyy>
            <iyz>1.545e-06</iyz>
            <izz>0.01</izz>
          </inertia>
        </inertial>
        <collision name='l_hip_1_collision'>
          <pose frame=''>0 0 0 -0.785403 1.57079 -2.35619</pose>
          <geometry>
            <mesh>
              <scale>1 1 1</scale>
              <uri>model://icub/meshes/collision/icub_simple_collision_l_hip_1.dae</uri>
            </mesh>
          </geometry>
          <max_contacts>10</max_contacts>
          <surface>
            <contact>
              <ode/>
            </contact>
            <bounce/>
            <friction>
              <torsional>
                <ode/>
              </torsional>
              <ode/>
            </friction>
          </surface>
        </collision>
        <visual name='l_hip_1_visual'>
          <pose frame=''>0 0 0 -0.785403 1.57079 -2.35619</pose>
          <geometry>
            <mesh>
              <scale>1 1 1</scale>
              <uri>model://icub/meshes/visual/icub_l_hip_1.dae</uri>
            </mesh>
          </geometry>
        </visual>
        <self_collide>0</self_collide>
        <kinematic>0</kinematic>
      </link>
      <joint name='l_hip_pitch' type='revolute'>
        <child>l_hip_1</child>
        <parent>root_link</parent>
        <axis>
          <xyz>3e-06 1 0</xyz>
          <limit>
            <lower>-0.767945</lower>
            <upper>2.30383</upper>
            <effort>84</effort>
            <velocity>100</velocity>
          </limit>
          <dynamics>
            <damping>1</damping>
            <friction>0</friction>
            <spring_reference>0</spring_reference>
            <spring_stiffness>0</spring_stiffness>
          </dynamics>
          <use_parent_model_frame>1</use_parent_model_frame>
        </axis>
      </joint>
      <link name='l_hip_2'>
        <pose frame=''>0 -0.0681 -0.1199 3.14159 -7e-06 3.14159</pose>
        <inertial>
          <pose frame=''>0 0 0.03045 0 -0 0</pose>
          <mass>0.526</mass>
          <inertia>
            <ixx>0.01</ixx>
            <ixy>-7.4e-08</ixy>
            <ixz>1.0835e-05</ixz>
            <iyy>0.01</iyy>
            <iyz>-6.2e-08</iyz>
            <izz>0.01</izz>
          </inertia>
        </inertial>
        <collision name='l_hip_2_collision'>
          <pose frame=''>0 0 0 0.785363 -1.57079 2.35623</pose>
          <geometry>
            <mesh>
              <scale>1 1 1</scale>
              <uri>model://icub/meshes/collision/icub_simple_collision_l_hip_2.dae</uri>
            </mesh>
          </geometry>
          <max_contacts>10</max_contacts>
          <surface>
            <contact>
              <ode/>
            </contact>
            <bounce/>
            <friction>
              <torsional>
                <ode/>
              </torsional>
              <ode/>
            </friction>
          </surface>
        </collision>
        <visual name='l_hip_2_visual'>
          <pose frame=''>0 0 0 0.785363 -1.57079 2.35623</pose>
          <geometry>
            <mesh>
              <scale>1 1 1</scale>
              <uri>model://icub/meshes/visual/icub_l_hip_2.dae</uri>
            </mesh>
          </geometry>
        </visual>
        <self_collide>0</self_collide>
        <kinematic>0</kinematic>
      </link>
      <joint name='l_hip_roll' type='revolute'>
        <child>l_hip_2</child>
        <parent>l_hip_1</parent>
        <axis>
          <xyz>-1 3e-06 7e-06</xyz>
          <limit>
            <lower>-0.296706</lower>
            <upper>2.07694</upper>
            <effort>84</effort>
            <velocity>100</velocity>
          </limit>
          <dynamics>
            <damping>1</damping>
            <friction>0</friction>
            <spring_reference>0</spring_reference>
            <spring_stiffness>0</spring_stiffness>
          </dynamics>
          <use_parent_model_frame>1</use_parent_model_frame>
        </axis>
      </joint>
      <link name='l_hip_3'>
        <pose frame=''>-0 -0.0681 -0.1864 3.14159 -7e-06 3.14159</pose>
        <inertial>
          <pose frame=''>0 0 0 0 -0 0</pose>
          <mass>0.1</mass>
          <inertia>
            <ixx>0.01</ixx>
            <ixy>0</ixy>
            <ixz>0</ixz>
            <iyy>0.01</iyy>
            <iyz>0</iyz>
            <izz>0.01</izz>
          </inertia>
        </inertial>
        <self_collide>0</self_collide>
        <kinematic>0</kinematic>
      </link>
      <joint name='l_leg_ft_sensor' type='revolute'>
        <child>l_hip_3</child>
        <parent>l_hip_2</parent>
        <axis>
          <xyz>0 0 0</xyz>
          <limit>
            <lower>0</lower>
            <upper>0</upper>
            <effort>0</effort>
            <velocity>0</velocity>
          </limit>
          <dynamics>
            <spring_reference>0</spring_reference>
            <spring_stiffness>0</spring_stiffness>
          </dynamics>
          <use_parent_model_frame>1</use_parent_model_frame>
        </axis>
        <sensor name='left_leg_ft' type='force_torque'>
          <always_on>1</always_on>
          <update_rate>100</update_rate>
          <pose frame=''>0 0 0 0 -0 0</pose>
          <plugin name='left_leg_ft_plugin' filename='libgazebo_yarp_forcetorque.so'>
            <yarpConfigurationFile>model://icub/conf/FT/gazebo_icub_left_leg_ft.ini</yarpConfigurationFile>
          </plugin>
        </sensor>
      </joint>
      <link name='l_upper_leg'>
        <pose frame=''>0 -0.0681 -0.1199 1.57079 -7e-06 3.14159</pose>
        <inertial>
          <pose frame=''>0.00144 -0.15943 -0.00039 0 -0 0</pose>
          <mass>2.175</mass>
          <inertia>
            <ixx>0.01</ixx>
            <ixy>-6.726e-05</ixy>
            <ixz>2.267e-06</ixz>
            <iyy>0.01</iyy>
            <iyz>3.63726e-05</iyz>
            <izz>0.01</izz>
          </inertia>
        </inertial>
        <collision name='l_upper_leg_collision'>
          <pose frame=''>0 0 0 -2.67797 1.57079 -1.10716</pose>
          <geometry>
            <mesh>
              <scale>1 1 1</scale>
              <uri>model://icub/meshes/collision/icub_simple_collision_l_thigh.dae</uri>
            </mesh>
          </geometry>
          <max_contacts>10</max_contacts>
          <surface>
            <contact>
              <ode/>
            </contact>
            <bounce/>
            <friction>
              <torsional>
                <ode/>
              </torsional>
              <ode/>
            </friction>
          </surface>
        </collision>
        <visual name='l_upper_leg_visual'>
          <pose frame=''>0 0 0 -2.67797 1.57079 -1.10716</pose>
          <geometry>
            <mesh>
              <scale>1 1 1</scale>
              <uri>model://icub/meshes/visual/icub_l_thigh.dae</uri>
            </mesh>
          </geometry>
        </visual>
        <self_collide>0</self_collide>
        <kinematic>0</kinematic>
      </link>
      <joint name='l_hip_yaw' type='revolute'>
        <child>l_upper_leg</child>
        <parent>l_hip_3</parent>
        <axis>
          <xyz>7e-06 -6e-06 1</xyz>
          <limit>
            <lower>-1.37881</lower>
            <upper>1.37881</upper>
            <effort>40</effort>
            <velocity>100</velocity>
          </limit>
          <dynamics>
            <damping>1</damping>
            <friction>0</friction>
            <spring_reference>0</spring_reference>
            <spring_stiffness>0</spring_stiffness>
          </dynamics>
          <use_parent_model_frame>1</use_parent_model_frame>
        </axis>
      </joint>
      <link name='l_lower_leg'>
        <pose frame=''>-2e-06 -0.068099 -0.3435 2.09198 -1.57078 -0.521189</pose>
        <inertial>
          <pose frame=''>-0.1071 0.00182 0.00211 0 -0 0</pose>
          <mass>1.264</mass>
          <inertia>
            <ixx>0.01</ixx>
            <ixy>-0.000185699</ixy>
            <ixz>-6.3147e-05</ixz>
            <iyy>0.01</iyy>
            <iyz>7.86e-07</iyz>
            <izz>0.01</izz>
          </inertia>
        </inertial>
        <collision name='l_lower_leg_collision'>
          <pose frame=''>0 0 0 -3.14159 -0 1.5708</pose>
          <geometry>
            <mesh>
              <scale>1 1 1</scale>
              <uri>model://icub/meshes/collision/icub_simple_collision_l_shank.dae</uri>
            </mesh>
          </geometry>
          <max_contacts>10</max_contacts>
          <surface>
            <contact>
              <ode/>
            </contact>
            <bounce/>
            <friction>
              <torsional>
                <ode/>
              </torsional>
              <ode/>
            </friction>
          </surface>
        </collision>
        <visual name='l_lower_leg_visual'>
          <pose frame=''>0 0 0 -3.14159 -0 1.5708</pose>
          <geometry>
            <mesh>
              <scale>1 1 1</scale>
              <uri>model://icub/meshes/visual/icub_l_shank.dae</uri>
            </mesh>
          </geometry>
        </visual>
        <self_collide>0</self_collide>
        <kinematic>0</kinematic>
      </link>
      <joint name='l_knee' type='revolute'>
        <child>l_lower_leg</child>
        <parent>l_upper_leg</parent>
        <axis>
          <xyz>5e-06 1 6e-06</xyz>
          <limit>
            <lower>-2.18166</lower>
            <upper>0.401426</upper>
            <effort>30</effort>
            <velocity>100</velocity>
          </limit>
          <dynamics>
            <damping>1</damping>
            <friction>0</friction>
            <spring_reference>0</spring_reference>
            <spring_stiffness>0</spring_stiffness>
          </dynamics>
          <use_parent_model_frame>1</use_parent_model_frame>
        </axis>
      </joint>
      <link name='l_ankle_1'>
        <pose frame=''>-4e-06 -0.068097 -0.5565 0.52118 -1.57078 -0.521189</pose>
        <inertial>
          <pose frame=''>-0.0054 0.00163 0.0172 0 -0 0</pose>
          <mass>0.746</mass>
          <inertia>
            <ixx>0.01</ixx>
            <ixy>-7.081e-06</ixy>
            <ixz>4.1421e-05</ixz>
            <iyy>0.01</iyy>
            <iyz>2.0817e-05</iyz>
            <izz>0.01</izz>
          </inertia>
        </inertial>
        <collision name='l_ankle_1_collision'>
          <pose frame=''>0 -0 0 1.5708 -0 0</pose>
          <geometry>
            <mesh>
              <scale>1 1 1</scale>
              <uri>model://icub/meshes/collision/icub_simple_collision_l_ankle_1.dae</uri>
            </mesh>
          </geometry>
          <max_contacts>10</max_contacts>
          <surface>
            <contact>
              <ode/>
            </contact>
            <bounce/>
            <friction>
              <torsional>
                <ode/>
              </torsional>
              <ode/>
            </friction>
          </surface>
        </collision>
        <visual name='l_ankle_1_visual'>
          <pose frame=''>0 -0 0 1.5708 -0 0</pose>
          <geometry>
            <mesh>
              <scale>1 1 1</scale>
              <uri>model://icub/meshes/visual/icub_l_ankle_1.dae</uri>
            </mesh>
          </geometry>
        </visual>
        <self_collide>0</self_collide>
        <kinematic>0</kinematic>
      </link>
      <joint name='l_ankle_pitch' type='revolute'>
        <child>l_ankle_1</child>
        <parent>l_lower_leg</parent>
        <axis>
          <xyz>-9e-06 -1 -6e-06</xyz>
          <limit>
            <lower>-0.733038</lower>
            <upper>0.366519</upper>
            <effort>24</effort>
            <velocity>100</velocity>
          </limit>
          <dynamics>
            <damping>1</damping>
            <friction>0</friction>
            <spring_reference>0</spring_reference>
            <spring_stiffness>0</spring_stiffness>
          </dynamics>
          <use_parent_model_frame>1</use_parent_model_frame>
        </axis>
      </joint>
      <link name='l_ankle_2'>
        <pose frame=''>-4e-06 -0.068097 -0.5565 3.14159 -7e-06 3.14158</pose>
        <inertial>
          <pose frame=''>0 0 0.037 0 -0 0</pose>
          <mass>0.2675</mass>
          <inertia>
            <ixx>0.01</ixx>
            <ixy>0</ixy>
            <ixz>0</ixz>
            <iyy>0.01</iyy>
            <iyz>0</iyz>
            <izz>0.01</izz>
          </inertia>
        </inertial>
        <self_collide>0</self_collide>
        <kinematic>0</kinematic>
      </link>
      <joint name='l_ankle_roll' type='revolute'>
        <child>l_ankle_2</child>
        <parent>l_ankle_1</parent>
        <axis>
          <xyz>-1 9e-06 7e-06</xyz>
          <limit>
            <lower>-0.418879</lower>
            <upper>0.418879</upper>
            <effort>11</effort>
            <velocity>100</velocity>
          </limit>
          <dynamics>
            <damping>1</damping>
            <friction>0</friction>
            <spring_reference>0</spring_reference>
            <spring_stiffness>0</spring_stiffness>
          </dynamics>
          <use_parent_model_frame>1</use_parent_model_frame>
        </axis>
      </joint>
      <link name='l_foot'>
        <pose frame=''>-4e-06 -0.068097 -0.5935 3.14159 -7e-06 3.14158</pose>
        <inertial>
          <pose frame=''>0.024069 -0.000614 -0.028415 0 -0 0</pose>
          <mass>0.5935</mass>
          <inertia>
            <ixx>0.01</ixx>
            <ixy>-4.51893e-06</ixy>
            <ixz>0.000567785</ixz>
            <iyy>0.01</iyy>
            <iyz>-6.62361e-07</iyz>
            <izz>0.01</izz>
          </inertia>
        </inertial>
        <collision name='l_foot_collision'>
          <pose frame=''>0.03 0 -0.01 0 -0 0</pose>
          <geometry>
            <box>
              <size>0.15 0.07 0.03</size>
            </box>
          </geometry>
          <max_contacts>4</max_contacts>
          <surface>
            <contact>
              <ode>
                <soft_erp>0.2</soft_erp>
                <soft_cfm>0</soft_cfm>
                <kp>1.8e+07</kp>
                <kd>100</kd>
                <max_vel>100</max_vel>
                <min_depth>0.0001</min_depth>
              </ode>
            </contact>
            <friction>
              <ode>
                <mu>1</mu>
                <mu2>1</mu2>
                <fdir1>0 0 0</fdir1>
                <slip1>0</slip1>
                <slip2>0</slip2>
              </ode>
              <torsional>
                <ode/>
              </torsional>
            </friction>
            <bounce>
              <restitution_coefficient>0</restitution_coefficient>
              <threshold>100000</threshold>
            </bounce>
          </surface>
        </collision>
        <visual name='l_foot_visual'>
          <pose frame=''>0 -0 -0.037 -0.785403 1.57079 -0.785403</pose>
          <geometry>
            <mesh>
              <scale>1 1 1</scale>
              <uri>model://icub/meshes/visual/icub_l_foot.dae</uri>
            </mesh>
          </geometry>
        </visual>
        <self_collide>0</self_collide>
        <kinematic>0</kinematic>
      </link>
      <joint name='l_foot_ft_sensor' type='revolute'>
        <child>l_foot</child>
        <parent>l_ankle_2</parent>
        <axis>
          <xyz>0 0 0</xyz>
          <limit>
            <lower>0</lower>
            <upper>0</upper>
            <effort>0</effort>
            <velocity>0</velocity>
          </limit>
          <dynamics>
            <spring_reference>0</spring_reference>
            <spring_stiffness>0</spring_stiffness>
          </dynamics>
          <use_parent_model_frame>1</use_parent_model_frame>
        </axis>
        <sensor name='left_foot_ft' type='force_torque'>
          <always_on>1</always_on>
          <update_rate>100</update_rate>
          <pose frame=''>0 0 0 0 -0 0</pose>
          <plugin name='left_foot_ft_plugin' filename='libgazebo_yarp_forcetorque.so'>
            <yarpConfigurationFile>model://icub/conf/FT/gazebo_icub_left_foot_ft.ini</yarpConfigurationFile>
          </plugin>
        </sensor>
      </joint>
      <link name='r_hip_1'>
        <pose frame=''>0 0.0681 -0.1199 3.14159 1.57079 -3.14159</pose>
        <inertial>
          <pose frame=''>0 -0.0782 0 0 -0 0</pose>
          <mass>0.754</mass>
          <inertia>
            <ixx>0.01</ixx>
            <ixy>0</ixy>
            <ixz>0</ixz>
            <iyy>0.01</iyy>
            <iyz>0</iyz>
            <izz>0.01</izz>
          </inertia>
        </inertial>
        <collision name='r_hip_1_collision'>
          <pose frame=''>0 0 0 1.76819 -1.57079 2.76109</pose>
          <geometry>
            <mesh>
              <scale>1 1 1</scale>
              <uri>model://icub/meshes/collision/icub_simple_collision_r_hip_1.dae</uri>
            </mesh>
          </geometry>
          <max_contacts>10</max_contacts>
          <surface>
            <contact>
              <ode/>
            </contact>
            <bounce/>
            <friction>
              <torsional>
                <ode/>
              </torsional>
              <ode/>
            </friction>
          </surface>
        </collision>
        <visual name='r_hip_1_visual'>
          <pose frame=''>0 0 0 1.76819 -1.57079 2.76109</pose>
          <geometry>
            <mesh>
              <scale>1 1 1</scale>
              <uri>model://icub/meshes/visual/icub_r_hip_1.dae</uri>
            </mesh>
          </geometry>
        </visual>
        <self_collide>0</self_collide>
        <kinematic>0</kinematic>
      </link>
      <joint name='r_hip_pitch' type='revolute'>
        <child>r_hip_1</child>
        <parent>root_link</parent>
        <axis>
          <xyz>0 1 0</xyz>
          <limit>
            <lower>-0.767945</lower>
            <upper>2.30383</upper>
            <effort>84</effort>
            <velocity>100</velocity>
          </limit>
          <dynamics>
            <damping>1</damping>
            <friction>0</friction>
            <spring_reference>0</spring_reference>
            <spring_stiffness>0</spring_stiffness>
          </dynamics>
          <use_parent_model_frame>1</use_parent_model_frame>
        </axis>
      </joint>
      <link name='r_hip_2'>
        <pose frame=''>0 0.0681 -0.1199 -3.14159 -7e-06 -3.14159</pose>
        <inertial>
          <pose frame=''>0 0 0.03045 0 -0 0</pose>
          <mass>0.526</mass>
          <inertia>
            <ixx>0.01</ixx>
            <ixy>0</ixy>
            <ixz>0</ixz>
            <iyy>0.01</iyy>
            <iyz>0</iyz>
            <izz>0.01</izz>
          </inertia>
        </inertial>
        <collision name='r_hip_2_collision'>
          <pose frame=''>0 0 0 -2.35627 -1.57079 2.35627</pose>
          <geometry>
            <mesh>
              <scale>1 1 1</scale>
              <uri>model://icub/meshes/collision/icub_simple_collision_r_hip_2.dae</uri>
            </mesh>
          </geometry>
          <max_contacts>10</max_contacts>
          <surface>
            <contact>
              <ode/>
            </contact>
            <bounce/>
            <friction>
              <torsional>
                <ode/>
              </torsional>
              <ode/>
            </friction>
          </surface>
        </collision>
        <visual name='r_hip_2_visual'>
          <pose frame=''>0 0 0 -2.35627 -1.57079 2.35627</pose>
          <geometry>
            <mesh>
              <scale>1 1 1</scale>
              <uri>model://icub/meshes/visual/icub_r_hip_2.dae</uri>
            </mesh>
          </geometry>
        </visual>
        <self_collide>0</self_collide>
        <kinematic>0</kinematic>
      </link>
      <joint name='r_hip_roll' type='revolute'>
        <child>r_hip_2</child>
        <parent>r_hip_1</parent>
        <axis>
          <xyz>1 0 -7e-06</xyz>
          <limit>
            <lower>-0.296706</lower>
            <upper>2.07694</upper>
            <effort>84</effort>
            <velocity>100</velocity>
          </limit>
          <dynamics>
            <damping>1</damping>
            <friction>0</friction>
            <spring_reference>0</spring_reference>
            <spring_stiffness>0</spring_stiffness>
          </dynamics>
          <use_parent_model_frame>1</use_parent_model_frame>
        </axis>
      </joint>
      <link name='r_hip_3'>
        <pose frame=''>-0 0.0681 -0.1864 -3.14159 -7e-06 -3.14159</pose>
        <inertial>
          <pose frame=''>0 0 0 0 -0 0</pose>
          <mass>0.1</mass>
          <inertia>
            <ixx>0.01</ixx>
            <ixy>0</ixy>
            <ixz>0</ixz>
            <iyy>0.01</iyy>
            <iyz>0</iyz>
            <izz>0.01</izz>
          </inertia>
        </inertial>
        <self_collide>0</self_collide>
        <kinematic>0</kinematic>
      </link>
      <joint name='r_leg_ft_sensor' type='revolute'>
        <child>r_hip_3</child>
        <parent>r_hip_2</parent>
        <axis>
          <xyz>0 0 0</xyz>
          <limit>
            <lower>0</lower>
            <upper>0</upper>
            <effort>0</effort>
            <velocity>0</velocity>
          </limit>
          <dynamics>
            <spring_reference>0</spring_reference>
            <spring_stiffness>0</spring_stiffness>
          </dynamics>
          <use_parent_model_frame>1</use_parent_model_frame>
        </axis>
        <sensor name='right_leg_ft' type='force_torque'>
          <always_on>1</always_on>
          <update_rate>100</update_rate>
          <pose frame=''>0 0 0 0 -0 0</pose>
          <plugin name='right_leg_ft_plugin' filename='libgazebo_yarp_forcetorque.so'>
            <yarpConfigurationFile>model://icub/conf/FT/gazebo_icub_right_leg_ft.ini</yarpConfigurationFile>
          </plugin>
        </sensor>
      </joint>
      <link name='r_upper_leg'>
        <pose frame=''>0 0.0681 -0.1199 1.57079 -7e-06 3.14159</pose>
        <inertial>
          <pose frame=''>0.00144 -0.15943 0.00039 0 -0 0</pose>
          <mass>2.175</mass>
          <inertia>
            <ixx>0.01</ixx>
            <ixy>0</ixy>
            <ixz>0</ixz>
            <iyy>0.01</iyy>
            <iyz>-2.71051e-20</iyz>
            <izz>0.01</izz>
          </inertia>
        </inertial>
        <collision name='r_upper_leg_collision'>
          <pose frame=''>0 0 0 1.57087 -1.57079 -7.3e-05</pose>
          <geometry>
            <mesh>
              <scale>1 1 1</scale>
              <uri>model://icub/meshes/collision/icub_simple_collision_r_thigh.dae</uri>
            </mesh>
          </geometry>
          <max_contacts>10</max_contacts>
          <surface>
            <contact>
              <ode/>
            </contact>
            <bounce/>
            <friction>
              <torsional>
                <ode/>
              </torsional>
              <ode/>
            </friction>
          </surface>
        </collision>
        <visual name='r_upper_leg_visual'>
          <pose frame=''>0 0 0 1.57087 -1.57079 -7.3e-05</pose>
          <geometry>
            <mesh>
              <scale>1 1 1</scale>
              <uri>model://icub/meshes/visual/icub_r_thigh.dae</uri>
            </mesh>
          </geometry>
        </visual>
        <self_collide>0</self_collide>
        <kinematic>0</kinematic>
      </link>
      <joint name='r_hip_yaw' type='revolute'>
        <child>r_upper_leg</child>
        <parent>r_hip_3</parent>
        <axis>
          <xyz>-7e-06 4e-06 -1</xyz>
          <limit>
            <lower>-1.37881</lower>
            <upper>1.37881</upper>
            <effort>40</effort>
            <velocity>100</velocity>
          </limit>
          <dynamics>
            <damping>1</damping>
            <friction>0</friction>
            <spring_reference>0</spring_reference>
            <spring_stiffness>0</spring_stiffness>
          </dynamics>
          <use_parent_model_frame>1</use_parent_model_frame>
        </axis>
      </joint>
      <link name='r_lower_leg'>
        <pose frame=''>-2e-06 0.068101 -0.3435 1.89254 -1.57078 -0.321751</pose>
        <inertial>
          <pose frame=''>-0.1071 0.00182 -0.00211 0 -0 0</pose>
          <mass>1.264</mass>
          <inertia>
            <ixx>0.01</ixx>
            <ixy>5.42101e-20</ixy>
            <ixz>-5.42101e-20</ixz>
            <iyy>0.01</iyy>
            <iyz>8.47033e-22</iyz>
            <izz>0.01</izz>
          </inertia>
        </inertial>
        <collision name='r_lower_leg_collision'>
          <pose frame=''>0 0 -0 3.14159 -0 1.5708</pose>
          <geometry>
            <mesh>
              <scale>1 1 1</scale>
              <uri>model://icub/meshes/collision/icub_simple_collision_r_shank.dae</uri>
            </mesh>
          </geometry>
          <max_contacts>10</max_contacts>
          <surface>
            <contact>
              <ode/>
            </contact>
            <bounce/>
            <friction>
              <torsional>
                <ode/>
              </torsional>
              <ode/>
            </friction>
          </surface>
        </collision>
        <visual name='r_lower_leg_visual'>
          <pose frame=''>0 0 -0 3.14159 -0 1.5708</pose>
          <geometry>
            <mesh>
              <scale>1 1 1</scale>
              <uri>model://icub/meshes/visual/icub_r_shank.dae</uri>
            </mesh>
          </geometry>
        </visual>
        <self_collide>0</self_collide>
        <kinematic>0</kinematic>
      </link>
      <joint name='r_knee' type='revolute'>
        <child>r_lower_leg</child>
        <parent>r_upper_leg</parent>
        <axis>
          <xyz>3e-06 1 4e-06</xyz>
          <limit>
            <lower>-2.18166</lower>
            <upper>0.401426</upper>
            <effort>30</effort>
            <velocity>100</velocity>
          </limit>
          <dynamics>
            <damping>1</damping>
            <friction>0</friction>
            <spring_reference>0</spring_reference>
            <spring_stiffness>0</spring_stiffness>
          </dynamics>
          <use_parent_model_frame>1</use_parent_model_frame>
        </axis>
      </joint>
      <link name='r_ankle_1'>
        <pose frame=''>-4e-06 0.068102 -0.5565 -2.81984 -1.57078 -0.321751</pose>
        <inertial>
          <pose frame=''>-0.0054 0.00163 -0.0172 0 -0 0</pose>
          <mass>0.746</mass>
          <inertia>
            <ixx>0.01</ixx>
            <ixy>-1.69407e-21</ixy>
            <ixz>1.35525e-20</ixz>
            <iyy>0.01</iyy>
            <iyz>3.38813e-21</iyz>
            <izz>0.01</izz>
          </inertia>
        </inertial>
        <collision name='r_ankle_1_collision'>
          <pose frame=''>0 -0 -0 -1.5708 -0 0</pose>
          <geometry>
            <mesh>
              <scale>1 1 1</scale>
              <uri>model://icub/meshes/collision/icub_simple_collision_r_ankle_1.dae</uri>
            </mesh>
          </geometry>
          <max_contacts>10</max_contacts>
          <surface>
            <contact>
              <ode/>
            </contact>
            <bounce/>
            <friction>
              <torsional>
                <ode/>
              </torsional>
              <ode/>
            </friction>
          </surface>
        </collision>
        <visual name='r_ankle_1_visual'>
          <pose frame=''>0 -0 -0 -1.5708 -0 0</pose>
          <geometry>
            <mesh>
              <scale>1 1 1</scale>
              <uri>model://icub/meshes/visual/icub_r_ankle_1.dae</uri>
            </mesh>
          </geometry>
        </visual>
        <self_collide>0</self_collide>
        <kinematic>0</kinematic>
      </link>
      <joint name='r_ankle_pitch' type='revolute'>
        <child>r_ankle_1</child>
        <parent>r_lower_leg</parent>
        <axis>
          <xyz>1e-06 -1 -4e-06</xyz>
          <limit>
            <lower>-0.733038</lower>
            <upper>0.366519</upper>
            <effort>24</effort>
            <velocity>100</velocity>
          </limit>
          <dynamics>
            <damping>1</damping>
            <friction>0</friction>
            <spring_reference>0</spring_reference>
            <spring_stiffness>0</spring_stiffness>
          </dynamics>
          <use_parent_model_frame>1</use_parent_model_frame>
        </axis>
      </joint>
      <link name='r_ankle_2'>
        <pose frame=''>-4e-06 0.068102 -0.5565 3.14159 -1.4e-05 -3.14159</pose>
        <inertial>
          <pose frame=''>0 0 0.037 0 -0 0</pose>
          <mass>0.2675</mass>
          <inertia>
            <ixx>0.01</ixx>
            <ixy>0</ixy>
            <ixz>0</ixz>
            <iyy>0.01</iyy>
            <iyz>0</iyz>
            <izz>0.01</izz>
          </inertia>
        </inertial>
        <self_collide>0</self_collide>
        <kinematic>0</kinematic>
      </link>
      <joint name='r_ankle_roll' type='revolute'>
        <child>r_ankle_2</child>
        <parent>r_ankle_1</parent>
        <axis>
          <xyz>1 3e-06 -1.4e-05</xyz>
          <limit>
            <lower>-0.418879</lower>
            <upper>0.418879</upper>
            <effort>11</effort>
            <velocity>100</velocity>
          </limit>
          <dynamics>
            <damping>1</damping>
            <friction>0</friction>
            <spring_reference>0</spring_reference>
            <spring_stiffness>0</spring_stiffness>
          </dynamics>
          <use_parent_model_frame>1</use_parent_model_frame>
        </axis>
      </joint>
      <link name='r_foot'>
        <pose frame=''>-5e-06 0.068102 -0.5935 3.14159 -1.4e-05 -3.14159</pose>
        <inertial>
          <pose frame=''>0.024069 0.000614 -0.028415 0 -0 0</pose>
          <mass>0.5935</mass>
          <inertia>
            <ixx>0.01</ixx>
            <ixy>4.51893e-06</ixy>
            <ixz>0.000567784</ixz>
            <iyy>0.01</iyy>
            <iyz>6.62535e-07</iyz>
            <izz>0.01</izz>
          </inertia>
        </inertial>
        <collision name='r_foot_collision'>
          <pose frame=''>0.03 0 -0.01 0 -0 0</pose>
          <geometry>
            <box>
              <size>0.15 0.07 0.03</size>
            </box>
          </geometry>
          <max_contacts>4</max_contacts>
          <surface>
            <contact>
              <ode>
                <soft_erp>0.2</soft_erp>
                <soft_cfm>0</soft_cfm>
                <kp>1.8e+07</kp>
                <kd>100</kd>
                <max_vel>100</max_vel>
                <min_depth>0.0001</min_depth>
              </ode>
            </contact>
            <friction>
              <ode>
                <mu>1</mu>
                <mu2>1</mu2>
                <fdir1>0 0 0</fdir1>
                <slip1>0</slip1>
                <slip2>0</slip2>
              </ode>
              <torsional>
                <ode/>
              </torsional>
            </friction>
            <bounce>
              <restitution_coefficient>0</restitution_coefficient>
              <threshold>100000</threshold>
            </bounce>
          </surface>
        </collision>
        <visual name='r_foot_visual'>
          <pose frame=''>0 0 -0.037 -2.81983 1.57079 0.321763</pose>
          <geometry>
            <mesh>
              <scale>1 1 1</scale>
              <uri>model://icub/meshes/visual/icub_r_foot.dae</uri>
            </mesh>
          </geometry>
        </visual>
        <self_collide>0</self_collide>
        <kinematic>0</kinematic>
      </link>
      <joint name='r_foot_ft_sensor' type='revolute'>
        <child>r_foot</child>
        <parent>r_ankle_2</parent>
        <axis>
          <xyz>0 0 0</xyz>
          <limit>
            <lower>0</lower>
            <upper>0</upper>
            <effort>0</effort>
            <velocity>0</velocity>
          </limit>
          <dynamics>
            <spring_reference>0</spring_reference>
            <spring_stiffness>0</spring_stiffness>
          </dynamics>
          <use_parent_model_frame>1</use_parent_model_frame>
        </axis>
        <sensor name='right_foot_ft' type='force_torque'>
          <always_on>1</always_on>
          <update_rate>100</update_rate>
          <pose frame=''>0 0 0 0 -0 0</pose>
          <plugin name='right_foot_ft_plugin' filename='libgazebo_yarp_forcetorque.so'>
            <yarpConfigurationFile>model://icub/conf/FT/gazebo_icub_right_foot_ft.ini</yarpConfigurationFile>
          </plugin>
        </sensor>
      </joint>
      <link name='torso_1'>
        <pose frame=''>0 0 0 3.14159 -1.57079 -3e-06</pose>
        <inertial>
          <pose frame=''>0 0 0 0 -0 0</pose>
          <mass>0.1</mass>
          <inertia>
            <ixx>0.01</ixx>
            <ixy>-4.263e-05</ixy>
            <ixz>-3.889e-08</ixz>
            <iyy>0.01</iyy>
            <iyz>0</iyz>
            <izz>0.01</izz>
          </inertia>
        </inertial>
        <collision name='torso_1_collision'>
          <pose frame=''>0 0 0 -1.5708 0 0</pose>
          <geometry>
            <mesh>
              <scale>1 1 1</scale>
              <uri>model://icub/meshes/collision/icub_simple_collision_lap_belt_1.dae</uri>
            </mesh>
          </geometry>
          <max_contacts>10</max_contacts>
          <surface>
            <contact>
              <ode/>
            </contact>
            <bounce/>
            <friction>
              <torsional>
                <ode/>
              </torsional>
              <ode/>
            </friction>
          </surface>
        </collision>
        <visual name='torso_1_visual'>
          <pose frame=''>0 0 0 -1.5708 0 0</pose>
          <geometry>
            <mesh>
              <scale>1 1 1</scale>
              <uri>model://icub/meshes/visual/icub_lap_belt_1.dae</uri>
            </mesh>
          </geometry>
        </visual>
        <self_collide>0</self_collide>
        <kinematic>0</kinematic>
      </link>
      <joint name='torso_pitch' type='revolute'>
        <child>torso_1</child>
        <parent>root_link</parent>
        <axis>
          <xyz>-3e-06 -1 0</xyz>
          <limit>
            <lower>-0.383972</lower>
            <upper>1.46608</upper>
            <effort>36</effort>
            <velocity>100</velocity>
          </limit>
          <dynamics>
            <damping>1</damping>
            <friction>0</friction>
            <spring_reference>0</spring_reference>
            <spring_stiffness>0</spring_stiffness>
          </dynamics>
          <use_parent_model_frame>1</use_parent_model_frame>
        </axis>
      </joint>
      <link name='torso_2'>
        <pose frame=''>0 -0 0.032 -3.14159 4e-06 1.57079</pose>
        <inertial>
          <pose frame=''>0 0 0 0 -0 0</pose>
          <mass>0.1</mass>
          <inertia>
            <ixx>0.01</ixx>
            <ixy>-1.923e-06</ixy>
            <ixz>5.095e-05</ixz>
            <iyy>0.01</iyy>
            <iyz>-3.849e-07</iyz>
            <izz>0.01</izz>
          </inertia>
        </inertial>
        <self_collide>0</self_collide>
        <kinematic>0</kinematic>
      </link>
      <joint name='torso_roll' type='revolute'>
        <child>torso_2</child>
        <parent>torso_1</parent>
        <axis>
          <xyz>1 -3e-06 -7e-06</xyz>
          <limit>
            <lower>-0.680678</lower>
            <upper>0.680678</upper>
            <effort>80</effort>
            <velocity>100</velocity>
          </limit>
          <dynamics>
            <damping>1</damping>
            <friction>0</friction>
            <spring_reference>0</spring_reference>
            <spring_stiffness>0</spring_stiffness>
          </dynamics>
          <use_parent_model_frame>1</use_parent_model_frame>
        </axis>
      </joint>
      <link name='chest'>
        <pose frame=''>-0.0055 0 0.032 1.5708 -7e-06 -3.14159</pose>
        <inertial>
          <pose frame=''>0.002229 0.075 -0 0 -0 0</pose>
          <mass>4.81</mass>
          <inertia>
            <ixx>0.07472</ixx>
            <ixy>-3.6e-06</ixy>
            <ixz>-4.705e-05</ixz>
            <iyy>0.08145</iyy>
            <iyz>0.004567</iyz>
            <izz>0.01306</izz>
          </inertia>
        </inertial>
        <collision name='chest_collision'>
          <pose frame=''>-0.0055 -0 -0 -1.10717 -1.57079 2.67798</pose>
          <geometry>
            <mesh>
              <scale>1 1 1</scale>
              <uri>model://icub/meshes/collision/icub_simple_collision_chest.dae</uri>
            </mesh>
          </geometry>
          <max_contacts>10</max_contacts>
          <surface>
            <contact>
              <ode/>
            </contact>
            <bounce/>
            <friction>
              <torsional>
                <ode/>
              </torsional>
              <ode/>
            </friction>
          </surface>
        </collision>
        <visual name='chest_visual'>
          <pose frame=''>-0.0055 -0 -0 -1.10717 -1.57079 2.67798</pose>
          <geometry>
            <mesh>
              <scale>1 1 1</scale>
              <uri>model://icub/meshes/visual/icub_chest.dae</uri>
            </mesh>
          </geometry>
        </visual>
        <self_collide>0</self_collide>
        <kinematic>0</kinematic>
      </link>
      <joint name='torso_yaw' type='revolute'>
        <child>chest</child>
        <parent>torso_2</parent>
        <axis>
          <xyz>-7e-06 0 -1</xyz>
          <limit>
            <lower>-1.02974</lower>
            <upper>1.02974</upper>
            <effort>80</effort>
            <velocity>100</velocity>
          </limit>
          <dynamics>
            <damping>1</damping>
            <friction>0</friction>
            <spring_reference>0</spring_reference>
            <spring_stiffness>0</spring_stiffness>
          </dynamics>
          <use_parent_model_frame>1</use_parent_model_frame>
        </axis>
      </joint>
      <link name='l_shoulder_1'>
        <pose frame=''>-0.010749 -0.11026 0.1753 -0.261794 -1.57079 -1e-06</pose>
        <inertial>
          <pose frame=''>-5e-06 0.0187 -0.00119 0 -0 0</pose>
          <mass>0.189</mass>
          <inertia>
            <ixx>0.01</ixx>
            <ixy>9e-09</ixy>
            <ixz>0</ixz>
            <iyy>0.01</iyy>
            <iyz>-1.7e-08</iyz>
            <izz>0.01</izz>
          </inertia>
        </inertial>
        <collision name='l_shoulder_1_collision'>
          <pose frame=''>0 0.109285 -0.005211 -0.301063 1.57079 -1.87186</pose>
          <geometry>
            <mesh>
              <scale>1 1 1</scale>
              <uri>model://icub/meshes/collision/icub_simple_collision_l_shoulder_1.dae</uri>
            </mesh>
          </geometry>
          <max_contacts>10</max_contacts>
          <surface>
            <contact>
              <ode/>
            </contact>
            <bounce/>
            <friction>
              <torsional>
                <ode/>
              </torsional>
              <ode/>
            </friction>
          </surface>
        </collision>
        <visual name='l_shoulder_1_visual'>
          <pose frame=''>0 0.109285 -0.005211 -0.301063 1.57079 -1.87186</pose>
          <geometry>
            <mesh>
              <scale>1 1 1</scale>
              <uri>model://icub/meshes/visual/icub_l_shoulder_1.dae</uri>
            </mesh>
          </geometry>
        </visual>
        <self_collide>0</self_collide>
        <kinematic>0</kinematic>
      </link>
      <joint name='l_shoulder_pitch' type='revolute'>
        <child>l_shoulder_1</child>
        <parent>chest</parent>
        <axis>
          <xyz>-0.258815 -0.965927 3e-06</xyz>
          <limit>
            <lower>-1.65806</lower>
            <upper>0.0872665</upper>
            <effort>84</effort>
            <velocity>100</velocity>
          </limit>
          <dynamics>
            <damping>1</damping>
            <friction>0</friction>
            <spring_reference>0</spring_reference>
            <spring_stiffness>0</spring_stiffness>
          </dynamics>
          <use_parent_model_frame>1</use_parent_model_frame>
        </axis>
      </joint>
      <link name='l_shoulder_2'>
        <pose frame=''>-0.010749 -0.11026 0.1753 3.14159 1e-06 -1.83259</pose>
        <inertial>
          <pose frame=''>9.4e-05 -0.00627 0.0166 0 -0 0</pose>
          <mass>0.179</mass>
          <inertia>
            <ixx>0.01</ixx>
            <ixy>4.66e-07</ixy>
            <ixz>3.65e-07</ixz>
            <iyy>0.01</iyy>
            <iyz>-2.0524e-05</iyz>
            <izz>0.01</izz>
          </inertia>
        </inertial>
        <collision name='l_shoulder_2_collision'>
          <pose frame=''>-0.001545 -0.005211 -0 -2.14033 1.57079 -0.569533</pose>
          <geometry>
            <mesh>
              <scale>1 1 1</scale>
              <uri>model://icub/meshes/collision/icub_simple_collision_l_shoulder_2.dae</uri>
            </mesh>
          </geometry>
          <max_contacts>10</max_contacts>
          <surface>
            <contact>
              <ode/>
            </contact>
            <bounce/>
            <friction>
              <torsional>
                <ode/>
              </torsional>
              <ode/>
            </friction>
          </surface>
        </collision>
        <visual name='l_shoulder_2_visual'>
          <pose frame=''>-0.001545 -0.005211 -0 -2.14033 1.57079 -0.569533</pose>
          <geometry>
            <mesh>
              <scale>1 1 1</scale>
              <uri>model://icub/meshes/visual/icub_l_shoulder_2.dae</uri>
            </mesh>
          </geometry>
        </visual>
        <self_collide>0</self_collide>
        <kinematic>0</kinematic>
      </link>
      <joint name='l_shoulder_roll' type='revolute'>
        <child>l_shoulder_2</child>
        <parent>l_shoulder_1</parent>
        <axis>
          <xyz>-0.965927 0.258815 7e-06</xyz>
          <limit>
            <lower>0</lower>
            <upper>2.80649</upper>
            <effort>84</effort>
            <velocity>100</velocity>
          </limit>
          <dynamics>
            <damping>1</damping>
            <friction>0</friction>
            <spring_reference>0</spring_reference>
            <spring_stiffness>0</spring_stiffness>
          </dynamics>
          <use_parent_model_frame>1</use_parent_model_frame>
        </axis>
      </joint>
      <link name='l_shoulder_3'>
        <pose frame=''>-0.010749 -0.11026 0.1753 3.14159 -7e-06 -3.14159</pose>
        <inertial>
          <pose frame=''>0.005594 9.8e-05 0.050135 0 -0 0</pose>
          <mass>0.156157</mass>
          <inertia>
            <ixx>0.01</ixx>
            <ixy>-5.662e-08</ixy>
            <ixz>-4.3618e-06</ixz>
            <iyy>0.01</iyy>
            <iyz>-7.42844e-07</iyz>
            <izz>0.01</izz>
          </inertia>
        </inertial>
        <self_collide>0</self_collide>
        <kinematic>0</kinematic>
      </link>
      <joint name='l_shoulder_yaw' type='revolute'>
        <child>l_shoulder_3</child>
        <parent>l_shoulder_2</parent>
        <axis>
          <xyz>-7e-06 3e-06 -1</xyz>
          <limit>
            <lower>-0.645772</lower>
            <upper>1.74533</upper>
            <effort>34</effort>
            <velocity>100</velocity>
          </limit>
          <dynamics>
            <damping>1</damping>
            <friction>0</friction>
            <spring_reference>0</spring_reference>
            <spring_stiffness>0</spring_stiffness>
          </dynamics>
          <use_parent_model_frame>1</use_parent_model_frame>
        </axis>
      </joint>
      <link name='l_upper_arm'>
        <pose frame=''>-0.025749 -0.11026 0.1073 3.14159 -7e-06 -3.14159</pose>
        <inertial>
          <pose frame=''>-0.000156 -9.9e-05 0.0298 0 -0 0</pose>
          <mass>0.727843</mass>
          <inertia>
            <ixx>0.01</ixx>
            <ixy>-1.08e-06</ixy>
            <ixz>-2.29e-06</ixz>
            <iyy>0.01</iyy>
            <iyz>3.57e-06</iyz>
            <izz>0.01</izz>
          </inertia>
        </inertial>
        <collision name='l_upper_arm_collision'>
          <pose frame=''>-0.020433 0.000144 -0.068 0 0 -1.309</pose>
          <geometry>
            <mesh>
              <scale>1 1 1</scale>
              <uri>model://icub/meshes/collision/icub_simple_collision_l_arm.dae</uri>
            </mesh>
          </geometry>
          <max_contacts>10</max_contacts>
          <surface>
            <contact>
              <ode/>
            </contact>
            <bounce/>
            <friction>
              <torsional>
                <ode/>
              </torsional>
              <ode/>
            </friction>
          </surface>
        </collision>
        <visual name='l_upper_arm_visual'>
          <pose frame=''>-0.020433 0.000144 -0.068 0 0 -1.309</pose>
          <geometry>
            <mesh>
              <scale>1 1 1</scale>
              <uri>model://icub/meshes/visual/icub_l_arm.dae</uri>
            </mesh>
          </geometry>
        </visual>
        <self_collide>0</self_collide>
        <kinematic>0</kinematic>
      </link>
      <joint name='l_arm_ft_sensor' type='revolute'>
        <child>l_upper_arm</child>
        <parent>l_shoulder_3</parent>
        <axis>
          <xyz>0 0 0</xyz>
          <limit>
            <lower>0</lower>
            <upper>0</upper>
            <effort>0</effort>
            <velocity>0</velocity>
          </limit>
          <dynamics>
            <spring_reference>0</spring_reference>
            <spring_stiffness>0</spring_stiffness>
          </dynamics>
          <use_parent_model_frame>1</use_parent_model_frame>
        </axis>
        <sensor name='left_arm_ft' type='force_torque'>
          <always_on>1</always_on>
          <update_rate>100</update_rate>
          <pose frame=''>0 0 0 0 -0 0</pose>
          <plugin name='left_arm_ft_plugin' filename='libgazebo_yarp_forcetorque.so'>
            <yarpConfigurationFile>model://icub/conf/FT/gazebo_icub_left_arm_ft.ini</yarpConfigurationFile>
          </plugin>
        </sensor>
      </joint>
      <link name='l_elbow_1'>
        <pose frame=''>-0.02575 -0.11026 0.02302 3.14159 -7e-06 -3.14159</pose>
        <inertial>
          <pose frame=''>-0.0013 0.00371 -0.00105 0 -0 0</pose>
          <mass>0.1</mass>
          <inertia>
            <ixx>0.01</ixx>
            <ixy>-5.15e-07</ixy>
            <ixz>-4.08e-07</ixz>
            <iyy>0.01</iyy>
            <iyz>-3.71e-07</iyz>
            <izz>0.01</izz>
          </inertia>
        </inertial>
        <self_collide>0</self_collide>
        <kinematic>0</kinematic>
      </link>
      <joint name='l_elbow' type='revolute'>
        <child>l_elbow_1</child>
        <parent>l_upper_arm</parent>
        <axis>
          <xyz>-1e-06 1 3e-06</xyz>
          <limit>
            <lower>0.0959931</lower>
            <upper>1.85005</upper>
            <effort>20</effort>
            <velocity>100</velocity>
          </limit>
          <dynamics>
            <damping>1</damping>
            <friction>0</friction>
            <spring_reference>0</spring_reference>
            <spring_stiffness>0</spring_stiffness>
          </dynamics>
          <use_parent_model_frame>1</use_parent_model_frame>
        </axis>
      </joint>
      <link name='l_forearm'>
        <pose frame=''>-0.01075 -0.11026 0.02302 -1.5708 3e-06 -1.57079</pose>
        <inertial>
          <pose frame=''>0.000347 0.066 0.00476 0 -0 0</pose>
          <mass>0.525</mass>
          <inertia>
            <ixx>0.01</ixx>
            <ixy>4.337e-06</ixy>
            <ixz>2.39e-07</ixz>
            <iyy>0.01</iyy>
            <iyz>1.9381e-05</iyz>
            <izz>0.01</izz>
          </inertia>
        </inertial>
        <collision name='l_forearm_collision'>
          <pose frame=''>-0.000144 -0 0.020433 -2.66395 1.57079 -1.09315</pose>
          <geometry>
            <mesh>
              <scale>1 1 1</scale>
              <uri>model://icub/meshes/collision/icub_simple_collision_l_forearm.dae</uri>
            </mesh>
          </geometry>
          <max_contacts>10</max_contacts>
          <surface>
            <contact>
              <ode/>
            </contact>
            <bounce/>
            <friction>
              <torsional>
                <ode/>
              </torsional>
              <ode/>
            </friction>
          </surface>
        </collision>
        <visual name='l_forearm_visual'>
          <pose frame=''>-0.000144 -0 0.020433 -2.66395 1.57079 -1.09315</pose>
          <geometry>
            <mesh>
              <scale>1 1 1</scale>
              <uri>model://icub/meshes/visual/icub_l_forearm.dae</uri>
            </mesh>
          </geometry>
        </visual>
        <self_collide>0</self_collide>
        <kinematic>0</kinematic>
      </link>
      <joint name='l_wrist_prosup' type='revolute'>
        <child>l_forearm</child>
        <parent>l_elbow_1</parent>
        <axis>
          <xyz>-3e-06 3e-06 -1</xyz>
          <limit>
            <lower>-0.872665</lower>
            <upper>0.872665</upper>
            <effort>0.45</effort>
            <velocity>100</velocity>
          </limit>
          <dynamics>
            <damping>1</damping>
            <friction>0</friction>
            <spring_reference>0</spring_reference>
            <spring_stiffness>0</spring_stiffness>
          </dynamics>
          <use_parent_model_frame>1</use_parent_model_frame>
        </axis>
      </joint>
      <link name='l_wrist_1'>
        <pose frame=''>-0.01075 -0.110259 -0.11428 -2.7153 1.57079 1.99709</pose>
        <inertial>
          <pose frame=''>0 0 0 0 -0 0</pose>
          <mass>0.1</mass>
          <inertia>
            <ixx>0.01</ixx>
            <ixy>0</ixy>
            <ixz>0</ixz>
            <iyy>0.01</iyy>
            <iyz>0</iyz>
            <izz>0.01</izz>
          </inertia>
        </inertial>
        <self_collide>0</self_collide>
        <kinematic>0</kinematic>
      </link>
      <joint name='l_wrist_pitch' type='revolute'>
        <child>l_wrist_1</child>
        <parent>l_forearm</parent>
        <axis>
          <xyz>1 1e-06 -3e-06</xyz>
          <limit>
            <lower>-1.13446</lower>
            <upper>0.174533</upper>
            <effort>0.65</effort>
            <velocity>100</velocity>
          </limit>
          <dynamics>
            <damping>1</damping>
            <friction>0</friction>
            <spring_reference>0</spring_reference>
            <spring_stiffness>0</spring_stiffness>
          </dynamics>
          <use_parent_model_frame>1</use_parent_model_frame>
        </axis>
      </joint>
      <link name='l_hand'>
        <pose frame=''>-0.01075 -0.110259 -0.11428 -2.7153 1.57079 1.99709</pose>
        <inertial>
          <pose frame=''>0.07023 -0.00805 -0.007 0 -0 0</pose>
          <mass>0.213</mass>
          <inertia>
            <ixx>0.01</ixx>
            <ixy>1.278e-05</ixy>
            <ixz>4.823e-06</ixz>
            <iyy>0.01</iyy>
            <iyz>-1.8188e-05</iyz>
            <izz>0.01</izz>
          </inertia>
        </inertial>
        <collision name='l_hand_collision'>
          <pose frame=''>-0 0.020433 -0.000144 0 -0 0</pose>
          <geometry>
            <mesh>
              <scale>1 1 1</scale>
              <uri>model://icub/meshes/collision/icub_simple_collision_l_hand.dae</uri>
            </mesh>
          </geometry>
          <max_contacts>10</max_contacts>
          <surface>
            <contact>
              <ode/>
            </contact>
            <bounce/>
            <friction>
              <torsional>
                <ode/>
              </torsional>
              <ode/>
            </friction>
          </surface>
        </collision>
        <visual name='l_hand_visual'>
          <pose frame=''>-0 0.020433 -0.000144 0 -0 0</pose>
          <geometry>
            <mesh>
              <scale>1 1 1</scale>
              <uri>model://icub/meshes/visual/icub_l_hand.dae</uri>
            </mesh>
          </geometry>
        </visual>
        <self_collide>0</self_collide>
        <kinematic>0</kinematic>
      </link>
      <joint name='l_wrist_yaw' type='revolute'>
        <child>l_hand</child>
        <parent>l_wrist_1</parent>
        <axis>
          <xyz>1e-06 -1 -6e-06</xyz>
          <limit>
            <lower>-0.436332</lower>
            <upper>0.436332</upper>
            <effort>0.65</effort>
            <velocity>100</velocity>
          </limit>
          <dynamics>
            <damping>1</damping>
            <friction>0</friction>
            <spring_reference>0</spring_reference>
            <spring_stiffness>0</spring_stiffness>
          </dynamics>
          <use_parent_model_frame>1</use_parent_model_frame>
        </axis>
      </joint>
      <link name='neck_1'>
        <pose frame=''>-0.007808 0 0.2253 6e-06 -1.57079 -1e-06</pose>
        <inertial>
          <pose frame=''>0 0 0 0 -0 0</pose>
          <mass>0.1</mass>
          <inertia>
            <ixx>0.01</ixx>
            <ixy>0</ixy>
            <ixz>0</ixz>
            <iyy>0.01</iyy>
            <iyz>0</iyz>
            <izz>0.01</izz>
          </inertia>
        </inertial>
        <collision name='neck_1_collision'>
          <pose frame=''>-0 0 -0.0055 3.14159 -1.57079 1.5708</pose>
          <geometry>
            <mesh>
              <scale>1 1 1</scale>
              <uri>model://icub/meshes/collision/icub_simple_collision_neck_1.dae</uri>
            </mesh>
          </geometry>
          <max_contacts>10</max_contacts>
          <surface>
            <contact>
              <ode/>
            </contact>
            <bounce/>
            <friction>
              <torsional>
                <ode/>
              </torsional>
              <ode/>
            </friction>
          </surface>
        </collision>
        <visual name='neck_1_visual'>
          <pose frame=''>-0 0 -0.0055 3.14159 -1.57079 1.5708</pose>
          <geometry>
            <mesh>
              <scale>1 1 1</scale>
              <uri>model://icub/meshes/visual/icub_neck_1.dae</uri>
            </mesh>
          </geometry>
        </visual>
        <self_collide>0</self_collide>
        <kinematic>0</kinematic>
      </link>
      <joint name='neck_pitch' type='revolute'>
        <child>neck_1</child>
        <parent>chest</parent>
        <axis>
          <xyz>-5e-06 1 0</xyz>
          <limit>
            <lower>-0.523599</lower>
            <upper>0.383972</upper>
            <effort>20</effort>
            <velocity>100</velocity>
          </limit>
          <dynamics>
            <damping>1</damping>
            <friction>0</friction>
            <spring_reference>0</spring_reference>
            <spring_stiffness>0</spring_stiffness>
          </dynamics>
          <use_parent_model_frame>1</use_parent_model_frame>
        </axis>
        <physics>
          <ode>
            <implicit_spring_damper>1</implicit_spring_damper>
            <cfm_damping>1</cfm_damping>
            <limit>
              <cfm>0</cfm>
              <erp>0.2</erp>
            </limit>
          </ode>
        </physics>
      </joint>
      <link name='neck_2'>
        <pose frame=''>-0.007808 0 0.2348 -1.5e-05 4e-06 -1.57079</pose>
        <inertial>
          <pose frame=''>0 0 0 0 -0 0</pose>
          <mass>0.1</mass>
          <inertia>
            <ixx>0.01</ixx>
            <ixy>0</ixy>
            <ixz>0</ixz>
            <iyy>0.01</iyy>
            <iyz>0</iyz>
            <izz>0.01</izz>
          </inertia>
        </inertial>
        <collision name='neck_2_collision'>
          <pose frame=''>-0 0.0055 0.0235 -3.14157 -1.57079 -1.57082</pose>
          <geometry>
            <mesh>
              <scale>1 1 1</scale>
              <uri>model://icub/meshes/collision/icub_simple_collision_neck_2.dae</uri>
            </mesh>
          </geometry>
          <max_contacts>10</max_contacts>
          <surface>
            <contact>
              <ode/>
            </contact>
            <bounce/>
            <friction>
              <torsional>
                <ode/>
              </torsional>
              <ode/>
            </friction>
          </surface>
        </collision>
        <visual name='neck_2_visual'>
          <pose frame=''>-0 0.0055 0.0235 -3.14157 -1.57079 -1.57082</pose>
          <geometry>
            <mesh>
              <scale>1 1 1</scale>
              <uri>model://icub/meshes/visual/icub_neck_2.dae</uri>
            </mesh>
          </geometry>
        </visual>
        <self_collide>0</self_collide>
        <kinematic>0</kinematic>
      </link>
      <joint name='neck_roll' type='revolute'>
        <child>neck_2</child>
        <parent>neck_1</parent>
        <axis>
          <xyz>-1 -5e-06 1.5e-05</xyz>
          <limit>
            <lower>-0.349066</lower>
            <upper>0.349066</upper>
            <effort>20</effort>
            <velocity>100</velocity>
          </limit>
          <dynamics>
            <damping>1</damping>
            <friction>0</friction>
            <spring_reference>0</spring_reference>
            <spring_stiffness>0</spring_stiffness>
          </dynamics>
          <use_parent_model_frame>1</use_parent_model_frame>
        </axis>
        <physics>
          <ode>
            <implicit_spring_damper>1</implicit_spring_damper>
            <cfm_damping>1</cfm_damping>
            <limit>
              <cfm>0</cfm>
              <erp>0.2</erp>
            </limit>
          </ode>
        </physics>
      </joint>
      <link name='head'>
        <pose frame=''>-0.007808 0 0.2348 -1.5708 1.5e-05 8e-06</pose>
        <inertial>
          <pose frame=''>0.0185 -0.1108 0 0 -0 0</pose>
          <mass>3</mass>
          <inertia>
            <ixx>0.01</ixx>
            <ixy>0</ixy>
            <ixz>0</ixz>
            <iyy>0.01</iyy>
            <iyz>0</iyz>
            <izz>0.01</izz>
          </inertia>
        </inertial>
        <collision name='head_collision'>
          <pose frame=''>0.0045 -0.0235 0 -1.32582 1.57079 -2.89662</pose>
          <geometry>
            <mesh>
              <scale>1 1 1</scale>
              <uri>model://icub/meshes/collision/icub_simple_collision_head.dae</uri>
            </mesh>
          </geometry>
          <max_contacts>10</max_contacts>
          <surface>
            <contact>
              <ode/>
            </contact>
            <bounce/>
            <friction>
              <torsional>
                <ode/>
              </torsional>
              <ode/>
            </friction>
          </surface>
        </collision>
        <visual name='head_visual'>
          <pose frame=''>0.0045 -0.0235 0 -2.89662 1.57079 -2.89662</pose>
          <geometry>
            <mesh>
              <scale>1 1 1</scale>
              <uri>model://icub/meshes/visual/icub_head_without_eyes.dae</uri>
            </mesh>
          </geometry>
        </visual>
        <sensor name='imu_sensor' type='imu'>
          <always_on>1</always_on>
          <update_rate>100</update_rate>
          <visualize>1</visualize>
          <imu>
            <angular_velocity/>
            <linear_acceleration/>
          </imu>
          <plugin name='iCub_yarp_gazebo_plugin_IMU' filename='libgazebo_yarp_imu.so'>
            <yarpConfigurationFile>model://icub/conf/gazebo_icub_inertial.ini</yarpConfigurationFile>
          </plugin>
          <pose frame=''>0.0185 -0.1108 0.0066 1.5708 -0 0</pose>
        </sensor>
        <self_collide>0</self_collide>
        <kinematic>0</kinematic>
      </link>
      <joint name='neck_yaw' type='revolute'>
        <child>head</child>
        <parent>neck_2</parent>
        <axis>
          <xyz>1.5e-05 0 1</xyz>
          <limit>
            <lower>-0.767945</lower>
            <upper>0.767945</upper>
            <effort>20</effort>
            <velocity>100</velocity>
          </limit>
          <dynamics>
            <damping>1</damping>
            <friction>0</friction>
            <spring_reference>0</spring_reference>
            <spring_stiffness>0</spring_stiffness>
          </dynamics>
          <use_parent_model_frame>1</use_parent_model_frame>
        </axis>
        <physics>
          <ode>
            <implicit_spring_damper>1</implicit_spring_damper>
            <cfm_damping>1</cfm_damping>
            <limit>
              <cfm>0</cfm>
              <erp>0.2</erp>
            </limit>
          </ode>
        </physics>
      </joint>
      <link name='eyes_tilt_link'>
        <pose frame=''>-0.06281 0 0.3408 1.57079 -0 0</pose>
        <inertial>
          <pose frame=''>0 0 0 0 -0 0</pose>
          <mass>0.01</mass>
          <inertia>
            <ixx>0.001</ixx>
            <ixy>0</ixy>
            <ixz>0</ixz>
            <iyy>0.001</iyy>
            <iyz>0</iyz>
            <izz>0.001</izz>
          </inertia>
        </inertial>
        <self_collide>0</self_collide>
        <kinematic>0</kinematic>
      </link>
      <link name='left_eye_link'>
        <pose frame=''>-0.06281 -0.034 0.3408 -3.14159 0 0</pose>
        <inertial>
          <pose frame=''>0 0 0 0 -0 0</pose>
          <mass>0.01</mass>
          <inertia>
            <ixx>0.001</ixx>
            <ixy>0</ixy>
            <ixz>0</ixz>
            <iyy>0.001</iyy>
            <iyz>0</iyz>
            <izz>0.001</izz>
          </inertia>
        </inertial>
        <visual name='left_eye_visual'>
          <pose frame=''>0.055 0.033 -0.14 0 -0 0</pose>
          <geometry>
            <mesh>
              <scale>1 1 1</scale>
              <uri>model://icub/meshes/visual/icub_eye.dae</uri>
            </mesh>
          </geometry>
        </visual>
        <self_collide>0</self_collide>
        <kinematic>0</kinematic>
      </link>
      <link name='right_eye_link'>
        <pose frame=''>-0.06281 0.034 0.3408 -3.14159 0 0</pose>
        <inertial>
          <pose frame=''>0 0 0 0 -0 0</pose>
          <mass>0.01</mass>
          <inertia>
            <ixx>0.001</ixx>
            <ixy>0</ixy>
            <ixz>0</ixz>
            <iyy>0.001</iyy>
            <iyz>0</iyz>
            <izz>0.001</izz>
          </inertia>
        </inertial>
        <visual name='right_eye_visual'>
          <pose frame=''>0.055 0.033 -0.14 0 -0 0</pose>
          <geometry>
            <mesh>
              <scale>1 1 1</scale>
              <uri>model://icub/meshes/visual/icub_eye.dae</uri>
            </mesh>
          </geometry>
        </visual>
        <self_collide>0</self_collide>
        <kinematic>0</kinematic>
      </link>
      <joint name='eyes_tilt' type='revolute'>
        <child>eyes_tilt_link</child>
        <parent>head</parent>
        <axis>
          <xyz>0 1 0</xyz>
          <limit>
            <lower>-1.5708</lower>
            <upper>1.5708</upper>
            <effort>84</effort>
            <velocity>100</velocity>
          </limit>
          <dynamics>
            <damping>1</damping>
            <friction>0</friction>
            <spring_reference>0</spring_reference>
            <spring_stiffness>0</spring_stiffness>
          </dynamics>
          <use_parent_model_frame>1</use_parent_model_frame>
        </axis>
        <physics>
          <ode>
            <implicit_spring_damper>1</implicit_spring_damper>
            <cfm_damping>1</cfm_damping>
            <limit>
              <cfm>0</cfm>
              <erp>0.2</erp>
            </limit>
          </ode>
        </physics>
      </joint>
      <joint name='left_eye' type='revolute'>
        <child>left_eye_link</child>
        <parent>eyes_tilt_link</parent>
        <axis>
          <xyz>0 0 1</xyz>
          <limit>
            <lower>-1.5708</lower>
            <upper>1.5708</upper>
            <effort>84</effort>
            <velocity>100</velocity>
          </limit>
          <dynamics>
            <damping>1</damping>
            <friction>0</friction>
            <spring_reference>0</spring_reference>
            <spring_stiffness>0</spring_stiffness>
          </dynamics>
          <use_parent_model_frame>1</use_parent_model_frame>
        </axis>
        <physics>
          <ode>
            <implicit_spring_damper>1</implicit_spring_damper>
            <cfm_damping>1</cfm_damping>
            <limit>
              <cfm>0</cfm>
              <erp>0.2</erp>
            </limit>
          </ode>
        </physics>
      </joint>
      <joint name='right_eye' type='revolute'>
        <child>right_eye_link</child>
        <parent>eyes_tilt_link</parent>
        <axis>
          <xyz>0 0 1</xyz>
          <limit>
            <lower>-1.5708</lower>
            <upper>1.5708</upper>
            <effort>84</effort>
            <velocity>100</velocity>
          </limit>
          <dynamics>
            <damping>1</damping>
            <friction>0</friction>
            <spring_reference>0</spring_reference>
            <spring_stiffness>0</spring_stiffness>
          </dynamics>
          <use_parent_model_frame>1</use_parent_model_frame>
        </axis>
        <physics>
          <ode>
            <implicit_spring_damper>1</implicit_spring_damper>
            <cfm_damping>1</cfm_damping>
            <limit>
              <cfm>0</cfm>
              <erp>0.2</erp>
            </limit>
          </ode>
        </physics>
      </joint>
      <link name='r_shoulder_1'>
        <pose frame=''>-0.010749 0.11026 0.1753 -2.87979 -1.57079 -1e-06</pose>
        <inertial>
          <pose frame=''>5e-06 0.0187 0.00119 0 -0 0</pose>
          <mass>0.189</mass>
          <inertia>
            <ixx>0.01</ixx>
            <ixy>2.1e-08</ixy>
            <ixz>-1e-09</ixz>
            <iyy>0.01</iyy>
            <iyz>4.22e-06</iyz>
            <izz>0.01</izz>
          </inertia>
        </inertial>
        <collision name='r_shoulder_1_collision'>
          <pose frame=''>-0 0.109285 0.005211 3.06003 1.57079 -1.65235</pose>
          <geometry>
            <mesh>
              <scale>1 1 1</scale>
              <uri>model://icub/meshes/collision/icub_simple_collision_r_shoulder_1.dae</uri>
            </mesh>
          </geometry>
          <max_contacts>10</max_contacts>
          <surface>
            <contact>
              <ode/>
            </contact>
            <bounce/>
            <friction>
              <torsional>
                <ode/>
              </torsional>
              <ode/>
            </friction>
          </surface>
        </collision>
        <visual name='r_shoulder_1_visual'>
          <pose frame=''>-0 0.109285 0.005211 3.06003 1.57079 -1.65235</pose>
          <geometry>
            <mesh>
              <scale>1 1 1</scale>
              <uri>model://icub/meshes/visual/icub_r_shoulder_1.dae</uri>
            </mesh>
          </geometry>
        </visual>
        <self_collide>0</self_collide>
        <kinematic>0</kinematic>
      </link>
      <joint name='r_shoulder_pitch' type='revolute'>
        <child>r_shoulder_1</child>
        <parent>chest</parent>
        <axis>
          <xyz>0.258817 -0.965926 -3e-06</xyz>
          <limit>
            <lower>-1.65806</lower>
            <upper>0.0872665</upper>
            <effort>84</effort>
            <velocity>100</velocity>
          </limit>
          <dynamics>
            <damping>1</damping>
            <friction>0</friction>
            <spring_reference>0</spring_reference>
            <spring_stiffness>0</spring_stiffness>
          </dynamics>
          <use_parent_model_frame>1</use_parent_model_frame>
        </axis>
      </joint>
      <link name='r_shoulder_2'>
        <pose frame=''>-0.010749 0.11026 0.1753 7e-06 1e-06 1.83259</pose>
        <inertial>
          <pose frame=''>-9.4e-05 -0.00627 -0.0166 0 -0 0</pose>
          <mass>0.179</mass>
          <inertia>
            <ixx>0.01</ixx>
            <ixy>-4.53e-07</ixy>
            <ixz>2.03e-07</ixz>
            <iyy>0.01</iyy>
            <iyz>2.07e-05</iyz>
            <izz>0.01</izz>
          </inertia>
        </inertial>
        <collision name='r_shoulder_2_collision'>
          <pose frame=''>-0.001545 -0.005211 -0 -1.00125 -1.57079 2.57205</pose>
          <geometry>
            <mesh>
              <scale>1 1 1</scale>
              <uri>model://icub/meshes/collision/icub_simple_collision_r_shoulder_2.dae</uri>
            </mesh>
          </geometry>
          <max_contacts>10</max_contacts>
          <surface>
            <contact>
              <ode/>
            </contact>
            <bounce/>
            <friction>
              <torsional>
                <ode/>
              </torsional>
              <ode/>
            </friction>
          </surface>
        </collision>
        <visual name='r_shoulder_2_visual'>
          <pose frame=''>-0.001545 -0.005211 -0 -1.00125 -1.57079 2.57205</pose>
          <geometry>
            <mesh>
              <scale>1 1 1</scale>
              <uri>model://icub/meshes/visual/icub_r_shoulder_2.dae</uri>
            </mesh>
          </geometry>
        </visual>
        <self_collide>0</self_collide>
        <kinematic>0</kinematic>
      </link>
      <joint name='r_shoulder_roll' type='revolute'>
        <child>r_shoulder_2</child>
        <parent>r_shoulder_1</parent>
        <axis>
          <xyz>0.965926 0.258817 -7e-06</xyz>
          <limit>
            <lower>0</lower>
            <upper>2.80649</upper>
            <effort>84</effort>
            <velocity>100</velocity>
          </limit>
          <dynamics>
            <damping>1</damping>
            <friction>0</friction>
            <spring_reference>0</spring_reference>
            <spring_stiffness>0</spring_stiffness>
          </dynamics>
          <use_parent_model_frame>1</use_parent_model_frame>
        </axis>
      </joint>
      <link name='r_shoulder_3'>
        <pose frame=''>-0.010749 0.11026 0.1753 3.14159 -7e-06 -3.14159</pose>
        <inertial>
          <pose frame=''>0.005539 -2.5e-05 0.04939 0 -0 0</pose>
          <mass>0.155</mass>
          <inertia>
            <ixx>0.01</ixx>
            <ixy>3.56977e-07</ixy>
            <ixz>-3.95372e-06</ixz>
            <iyy>0.01</iyy>
            <iyz>-6.5128e-06</iyz>
            <izz>0.01</izz>
          </inertia>
        </inertial>
        <self_collide>0</self_collide>
        <kinematic>0</kinematic>
      </link>
      <joint name='r_shoulder_yaw' type='revolute'>
        <child>r_shoulder_3</child>
        <parent>r_shoulder_2</parent>
        <axis>
          <xyz>7e-06 0 1</xyz>
          <limit>
            <lower>-0.645772</lower>
            <upper>1.74533</upper>
            <effort>34</effort>
            <velocity>100</velocity>
          </limit>
          <dynamics>
            <damping>1</damping>
            <friction>0</friction>
            <spring_reference>0</spring_reference>
            <spring_stiffness>0</spring_stiffness>
          </dynamics>
          <use_parent_model_frame>1</use_parent_model_frame>
        </axis>
      </joint>
      <link name='r_upper_arm'>
        <pose frame=''>-0.025749 0.11026 0.1073 3.14159 -7e-06 -3.14159</pose>
        <inertial>
          <pose frame=''>-0.000159 8.3e-05 0.029883 0 -0 0</pose>
          <mass>0.729</mass>
          <inertia>
            <ixx>0.01</ixx>
            <ixy>-1.08e-06</ixy>
            <ixz>-2.29e-06</ixz>
            <iyy>0.01</iyy>
            <iyz>3.57e-06</iyz>
            <izz>0.01</izz>
          </inertia>
        </inertial>
        <collision name='r_upper_arm_collision'>
          <pose frame=''>-0.020433 -0.000144 -0.068 -3.14159 -0 1.309</pose>
          <geometry>
            <mesh>
              <scale>1 1 1</scale>
              <uri>model://icub/meshes/collision/icub_simple_collision_r_arm.dae</uri>
            </mesh>
          </geometry>
          <max_contacts>10</max_contacts>
          <surface>
            <contact>
              <ode/>
            </contact>
            <bounce/>
            <friction>
              <torsional>
                <ode/>
              </torsional>
              <ode/>
            </friction>
          </surface>
        </collision>
        <visual name='r_upper_arm_visual'>
          <pose frame=''>-0.020433 -0.000144 -0.068 -3.14159 -0 1.309</pose>
          <geometry>
            <mesh>
              <scale>1 1 1</scale>
              <uri>model://icub/meshes/visual/icub_r_arm.dae</uri>
            </mesh>
          </geometry>
        </visual>
        <self_collide>0</self_collide>
        <kinematic>0</kinematic>
      </link>
      <joint name='r_arm_ft_sensor' type='revolute'>
        <child>r_upper_arm</child>
        <parent>r_shoulder_3</parent>
        <axis>
          <xyz>0 0 0</xyz>
          <limit>
            <lower>0</lower>
            <upper>0</upper>
            <effort>0</effort>
            <velocity>0</velocity>
          </limit>
          <dynamics>
            <spring_reference>0</spring_reference>
            <spring_stiffness>0</spring_stiffness>
          </dynamics>
          <use_parent_model_frame>1</use_parent_model_frame>
        </axis>
        <sensor name='right_arm_ft' type='force_torque'>
          <always_on>1</always_on>
          <update_rate>100</update_rate>
          <pose frame=''>0 0 0 0 -0 0</pose>
          <plugin name='right_arm_ft_plugin' filename='libgazebo_yarp_forcetorque.so'>
            <yarpConfigurationFile>model://icub/conf/FT/gazebo_icub_right_arm_ft.ini</yarpConfigurationFile>
          </plugin>
        </sensor>
      </joint>
      <link name='r_elbow_1'>
        <pose frame=''>-0.02575 0.11026 0.02302 -3e-06 7e-06 4e-06</pose>
        <inertial>
          <pose frame=''>0.0013 -0.00371 0.00105 0 -0 0</pose>
          <mass>0.1</mass>
          <inertia>
            <ixx>0.01</ixx>
            <ixy>-5.02e-07</ixy>
            <ixz>-3.99e-07</ixz>
            <iyy>0.01</iyy>
            <iyz>-3.71e-07</iyz>
            <izz>0.01</izz>
          </inertia>
        </inertial>
        <self_collide>0</self_collide>
        <kinematic>0</kinematic>
      </link>
      <joint name='r_elbow' type='revolute'>
        <child>r_elbow_1</child>
        <parent>r_upper_arm</parent>
        <axis>
          <xyz>-4e-06 1 -3e-06</xyz>
          <limit>
            <lower>0.0959931</lower>
            <upper>1.85005</upper>
            <effort>20</effort>
            <velocity>100</velocity>
          </limit>
          <dynamics>
            <damping>1</damping>
            <friction>0</friction>
            <spring_reference>0</spring_reference>
            <spring_stiffness>0</spring_stiffness>
          </dynamics>
          <use_parent_model_frame>1</use_parent_model_frame>
        </axis>
      </joint>
      <link name='r_forearm'>
        <pose frame=''>-0.01075 0.11026 0.02302 1.57079 -3e-06 -1.5708</pose>
        <inertial>
          <pose frame=''>-0.000347 -0.066 -0.00476 0 -0 0</pose>
          <mass>0.525</mass>
          <inertia>
            <ixx>0.01</ixx>
            <ixy>5.66e-06</ixy>
            <ixz>1.4e-06</ixz>
            <iyy>0.01</iyy>
            <iyz>1.82e-05</iyz>
            <izz>0.01</izz>
          </inertia>
        </inertial>
        <collision name='r_forearm_collision'>
          <pose frame=''>0.000144 -0 -0.020433 -1.74165 1.57079 -0.170863</pose>
          <geometry>
            <mesh>
              <scale>1 1 1</scale>
              <uri>model://icub/meshes/collision/icub_simple_collision_r_forearm.dae</uri>
            </mesh>
          </geometry>
          <max_contacts>10</max_contacts>
          <surface>
            <contact>
              <ode/>
            </contact>
            <bounce/>
            <friction>
              <torsional>
                <ode/>
              </torsional>
              <ode/>
            </friction>
          </surface>
        </collision>
        <visual name='r_forearm_visual'>
          <pose frame=''>0.000144 -0 -0.020433 -1.74165 1.57079 -0.170863</pose>
          <geometry>
            <mesh>
              <scale>1 1 1</scale>
              <uri>model://icub/meshes/visual/icub_r_forearm.dae</uri>
            </mesh>
          </geometry>
        </visual>
        <self_collide>0</self_collide>
        <kinematic>0</kinematic>
      </link>
      <joint name='r_wrist_prosup' type='revolute'>
        <child>r_forearm</child>
        <parent>r_elbow_1</parent>
        <axis>
          <xyz>3e-06 3e-06 1</xyz>
          <limit>
            <lower>-0.872665</lower>
            <upper>0.872665</upper>
            <effort>0.45</effort>
            <velocity>100</velocity>
          </limit>
          <dynamics>
            <damping>1</damping>
            <friction>0</friction>
            <spring_reference>0</spring_reference>
            <spring_stiffness>0</spring_stiffness>
          </dynamics>
          <use_parent_model_frame>1</use_parent_model_frame>
        </axis>
      </joint>
      <link name='r_wrist_1'>
        <pose frame=''>-0.01075 0.11026 -0.11428 0.426292 -1.57079 1.14451</pose>
        <inertial>
          <pose frame=''>0 0 0 0 -0 0</pose>
          <mass>0.1</mass>
          <inertia>
            <ixx>0.01</ixx>
            <ixy>0</ixy>
            <ixz>0</ixz>
            <iyy>0.01</iyy>
            <iyz>0</iyz>
            <izz>0.01</izz>
          </inertia>
        </inertial>
        <self_collide>0</self_collide>
        <kinematic>0</kinematic>
      </link>
      <joint name='r_wrist_pitch' type='revolute'>
        <child>r_wrist_1</child>
        <parent>r_forearm</parent>
        <axis>
          <xyz>-1 -4e-06 3e-06</xyz>
          <limit>
            <lower>-1.13446</lower>
            <upper>0.174533</upper>
            <effort>0.65</effort>
            <velocity>100</velocity>
          </limit>
          <dynamics>
            <damping>1</damping>
            <friction>0</friction>
            <spring_reference>0</spring_reference>
            <spring_stiffness>0</spring_stiffness>
          </dynamics>
          <use_parent_model_frame>1</use_parent_model_frame>
        </axis>
      </joint>
      <link name='r_hand'>
        <pose frame=''>-0.01075 0.11026 -0.11428 -0.720145 1.57079 -2.29094</pose>
        <inertial>
          <pose frame=''>0.07023 -0.00805 0.007 0 -0 0</pose>
          <mass>0.213</mass>
          <inertia>
            <ixx>0.01</ixx>
            <ixy>1.26e-05</ixy>
            <ixz>-6.08e-06</ixz>
            <iyy>0.01</iyy>
            <iyz>1.76e-05</iyz>
            <izz>0.01</izz>
          </inertia>
        </inertial>
        <collision name='r_hand_collision'>
          <pose frame=''>0 0.020433 0.000144 0 0 -3.14159</pose>
          <geometry>
            <mesh>
              <scale>1 1 1</scale>
              <uri>model://icub/meshes/collision/icub_simple_collision_r_hand.dae</uri>
            </mesh>
          </geometry>
          <max_contacts>10</max_contacts>
          <surface>
            <contact>
              <ode/>
            </contact>
            <bounce/>
            <friction>
              <torsional>
                <ode/>
              </torsional>
              <ode/>
            </friction>
          </surface>
        </collision>
        <visual name='r_hand_visual'>
          <pose frame=''>0 0.020433 0.000144 0 0 -3.14159</pose>
          <geometry>
            <mesh>
              <scale>1 1 1</scale>
              <uri>model://icub/meshes/visual/icub_r_hand.dae</uri>
            </mesh>
          </geometry>
        </visual>
        <self_collide>0</self_collide>
        <kinematic>0</kinematic>
      </link>
      <joint name='r_wrist_yaw' type='revolute'>
        <child>r_hand</child>
        <parent>r_wrist_1</parent>
        <axis>
          <xyz>4e-06 -1 6e-06</xyz>
          <limit>
            <lower>-0.436332</lower>
            <upper>0.436332</upper>
            <effort>0.65</effort>
            <velocity>100</velocity>
          </limit>
          <dynamics>
            <damping>1</damping>
            <friction>0</friction>
            <spring_reference>0</spring_reference>
            <spring_stiffness>0</spring_stiffness>
          </dynamics>
          <use_parent_model_frame>1</use_parent_model_frame>
        </axis>
      </joint>
      <plugin name='controlboard_torso' filename='libgazebo_yarp_controlboard.so'>
        <yarpConfigurationFile>model://icub/conf/gazebo_icub_torso.ini</yarpConfigurationFile>
      </plugin>
      <plugin name='controlboard_head' filename='libgazebo_yarp_controlboard.so'>
        <yarpConfigurationFile>model://icub/conf/gazebo_icub_head.ini</yarpConfigurationFile>
      </plugin>
      <plugin name='controlboard_left_arm_no_arm' filename='libgazebo_yarp_controlboard.so'>
        <yarpConfigurationFile>model://icub/conf/gazebo_icub_left_arm_no_hand_for_no_hand_model.ini</yarpConfigurationFile>
        <initialConfiguration>-0.52 0.52 0 0.785 0 0 0.698</initialConfiguration>
      </plugin>
      <plugin name='controlboard_right_arm_no_arm' filename='libgazebo_yarp_controlboard.so'>
        <yarpConfigurationFile>model://icub/conf/gazebo_icub_right_arm_no_hand_for_no_hand_model.ini</yarpConfigurationFile>
        <initialConfiguration>-0.52 0.52 0 0.785 0 0 0.698</initialConfiguration>
      </plugin>
      <plugin name='controlboard_left_leg' filename='libgazebo_yarp_controlboard.so'>
        <yarpConfigurationFile>model://icub/conf/gazebo_icub_left_leg.ini</yarpConfigurationFile>
      </plugin>
      <plugin name='controlboard_right_leg' filename='libgazebo_yarp_controlboard.so'>
        <yarpConfigurationFile>model://icub/conf/gazebo_icub_right_leg.ini</yarpConfigurationFile>
      </plugin>
      <plugin name='apply_external_wrench' filename='libgazebo_yarp_externalwrench.so'>
        <robotNamefromConfigFile>model://icub/conf/gazebo_icub_robotname.ini</robotNamefromConfigFile>
      </plugin>
      <pose frame=''>0 0 0.7 0 -0 0</pose>
    </model>
    <plugin name='ocra_gui_plugin' filename='libocra_gui_plugin.so'/>
    <gravity>0 0 -9.8</gravity>
    <magnetic_field>6e-06 2.3e-05 -4.2e-05</magnetic_field>
    <atmosphere type='adiabatic'/>
    <physics name='default_physics' default='0' type='ode'>
      <max_step_size>0.001</max_step_size>
      <real_time_factor>1</real_time_factor>
      <real_time_update_rate>1000</real_time_update_rate>
    </physics>
    <scene>
      <ambient>0.4 0.4 0.4 1</ambient>
      <background>0.7 0.7 0.7 1</background>
      <shadows>1</shadows>
    </scene>
    <spherical_coordinates>
      <surface_model>EARTH_WGS84</surface_model>
      <latitude_deg>0</latitude_deg>
      <longitude_deg>0</longitude_deg>
      <elevation>0</elevation>
      <heading_deg>0</heading_deg>
    </spherical_coordinates>
    <state world_name='default'>
      <sim_time>1699 0</sim_time>
      <real_time>24 21909699</real_time>
      <wall_time>1485274298 817115840</wall_time>
      <iterations>23798</iterations>
      <model name='RightHandTarget'>
        <pose frame=''>0 0 0 0 -0 0</pose>
        <scale>1 1 1</scale>
        <link name='link'>
          <pose frame=''>0 0 0 0 -0 0</pose>
          <velocity>0 0 0 0 -0 0</velocity>
          <acceleration>0 0 0 0 -0 0</acceleration>
          <wrench>0 0 0 0 -0 0</wrench>
        </link>
      </model>
      <model name='ground_plane'>
        <pose frame=''>0 0 0 0 -0 0</pose>
        <scale>1 1 1</scale>
        <link name='link'>
          <pose frame=''>0 0 0 0 -0 0</pose>
          <velocity>0 0 0 0 -0 0</velocity>
          <acceleration>0 0 0 0 -0 0</acceleration>
          <wrench>0 0 0 0 -0 0</wrench>
        </link>
      </model>
      <model name='iCub'>
        <pose frame=''>-0.017277 0.030764 0.594278 0.000886 -0.083781 -3.10555</pose>
        <scale>1 1 1</scale>
        <link name='chest'>
          <pose frame=''>-0.010678 0.031029 0.626 1.56993 0.03478 0.036103</pose>
          <velocity>-3.7e-05 -5e-06 5e-06 1.6e-05 -0.000473 -2.8e-05</velocity>
          <acceleration>-0.00037 -0.001947 0.000545 2.4499 1.33199 -1.05625</acceleration>
          <wrench>-0.001781 -0.009366 0.002622 0 -0 0</wrench>
        </link>
        <link name='eyes_tilt_link'>
          <pose frame=''>0.055824 0.033707 0.933348 1.57172 -0.021969 -3.10549</pose>
          <velocity>-0.000186 -1.3e-05 3.8e-05 2e-05 -0.000532 -3.6e-05</velocity>
          <acceleration>-0.00016 0.000519 0.000793 0.008284 0.019832 0.007323</acceleration>
          <wrench>-2e-06 5e-06 8e-06 0 -0 0</wrench>
        </link>
        <link name='head'>
          <pose frame=''>-0.001453 0.03154 0.828583 -1.56987 -0.021963 -3.10548</pose>
          <velocity>-0.000133 -9e-06 9e-06 1.9e-05 -0.000504 -3.6e-05</velocity>
          <acceleration>-0.000109 -7.3e-05 0.001141 0.008851 0.005381 0.00734</acceleration>
          <wrench>-0.000326 -0.000218 0.003423 0 -0 0</wrench>
        </link>
        <link name='l_ankle_1'>
          <pose frame=''>-0.012728 0.136444 0.041885 -1.57058 -1.48499 -1.52292</pose>
          <velocity>5e-06 -7.1e-05 1.5e-05 -0.000345 2.3e-05 -1.5e-05</velocity>
          <acceleration>0.007029 -0.14473 0.000244 -0.986113 0.066921 -0.182206</acceleration>
          <wrench>0.005244 -0.107969 0.000182 0 -0 0</wrench>
        </link>
        <link name='l_ankle_2'>
          <pose frame=''>-0.012728 0.136442 0.041897 -3.14159 -1.2e-05 0.048093</pose>
          <velocity>5e-06 -7.1e-05 1.8e-05 0.001976 0.000136 -1.4e-05</velocity>
          <acceleration>-0.000109 0.002819 -0.001592 -2.3996 0.185927 -0.008638</acceleration>
          <wrench>-2.9e-05 0.000754 -0.000426 0 -0 0</wrench>
        </link>
        <link name='l_elbow_1'>
          <pose frame=''>0.084643 0.201083 0.659593 -2.04401 -1.23316 -0.806366</pose>
          <velocity>-2.9e-05 9e-06 7.8e-05 8.4e-05 -0.000775 2.6e-05</velocity>
          <acceleration>-0.000295 0.000657 -8.6e-05 -0.093529 -0.012816 -0.03381</acceleration>
          <wrench>-2.9e-05 6.6e-05 -9e-06 0 -0 0</wrench>
        </link>
        <link name='l_foot'>
          <pose frame=''>-0.012727 0.136442 0.004899 -3.14159 -2e-06 0.048098</pose>
          <velocity>0 2e-06 1.9e-05 -0.000345 2.5e-05 -8e-06</velocity>
          <acceleration>-0.001165 0.017885 -0.001899 -0.538715 -0.034571 -0.061091</acceleration>
          <wrench>-0.000692 0.010615 -0.001127 0 -0 0</wrench>
        </link>
        <link name='l_forearm'>
          <pose frame=''>0.081204 0.204669 0.64544 -2.98293 -0.299326 1.83804</pose>
          <velocity>-1.9e-05 1e-05 7.5e-05 0.000126 -0.000761 1.9e-05</velocity>
          <acceleration>0.000765 -0.002753 -0.001609 0.015815 0.028328 -0.048504</acceleration>
          <wrench>0.000402 -0.001445 -0.000845 0 -0 0</wrench>
        </link>
        <link name='l_hand'>
          <pose frame=''>0.210278 0.24664 0.624711 -1.21411 0.56523 0.464124</pose>
          <velocity>-4e-06 1.5e-05 0.000179 0.000137 -0.000772 6.5e-05</velocity>
          <acceleration>0.001173 -0.004185 -0.002391 0.032855 0.060697 0.205024</acceleration>
          <wrench>0.00025 -0.000891 -0.000509 0 -0 0</wrench>
        </link>
        <link name='l_hip_1'>
          <pose frame=''>-0.029759 0.098348 0.474743 -0.006634 1.44181 0.029535</pose>
          <velocity>-1.8e-05 2.3e-05 1.8e-05 0.000171 -5.6e-05 -4e-06</velocity>
          <acceleration>0.000826 0.048243 -0.00469 0.302605 0.026327 -0.122599</acceleration>
          <wrench>0.000623 0.036375 -0.003537 0 -0 0</wrench>
        </link>
        <link name='l_hip_2'>
          <pose frame=''>-0.029759 0.098348 0.474748 -3.05497 -0.128988 0.036227</pose>
          <velocity>-1.8e-05 2.2e-05 1.8e-05 0.000512 -4.4e-05 4e-05</velocity>
          <acceleration>-0.002339 0.075844 0.021682 0.915597 0.039868 0.261393</acceleration>
          <wrench>-0.00123 0.039894 0.011405 0 -0 0</wrench>
        </link>
        <link name='l_hip_3'>
          <pose frame=''>-0.021453 0.104404 0.409077 -3.05497 -0.128992 0.036227</pose>
          <velocity>-1.5e-05 5.5e-05 2.4e-05 -0.000336 -7.7e-05 -7e-05</velocity>
          <acceleration>-0.003953 0.1071 0.020611 -0.667562 -0.011029 -0.107744</acceleration>
          <wrench>-0.000395 0.01071 0.002061 0 -0 0</wrench>
        </link>
        <link name='l_lower_leg'>
          <pose frame=''>-0.001825 0.118714 0.253861 -0.501203 -1.47292 -1.01947</pose>
          <velocity>-2e-06 2e-06 2.1e-05 -0.000342 -3.1e-05 -2e-05</velocity>
          <acceleration>0.003103 -0.069514 0.004525 -2.55765 0.025969 0.61883</acceleration>
          <wrench>0.003922 -0.087866 0.005719 0 -0 0</wrench>
        </link>
        <link name='l_shoulder_1'>
          <pose frame=''>-0.004442 0.141712 0.76893 0.021125 -1.08594 2.89739</pose>
          <velocity>-0.000102 -8e-06 1e-05 -2.3e-05 -0.000643 -2.6e-05</velocity>
          <acceleration>-0.000813 -0.000547 -0.00158 -0.017821 0.024574 0.000697</acceleration>
          <wrench>-0.000154 -0.000103 -0.000299 0 -0 0</wrench>
        </link>
        <link name='l_shoulder_2'>
          <pose frame=''>-0.004442 0.141712 0.768928 2.59925 -0.444531 1.60404</pose>
          <velocity>-0.000102 -8e-06 1e-05 0.000155 -0.000683 7e-05</velocity>
          <acceleration>-0.001346 0.001259 -0.001141 -0.081701 -0.007086 0.231745</acceleration>
          <wrench>-0.000241 0.000225 -0.000204 0 -0 0</wrench>
        </link>
        <link name='l_shoulder_3'>
          <pose frame=''>-0.004442 0.141713 0.768925 -2.7773 -0.596034 0.056373</pose>
          <velocity>-0.000102 -8e-06 1e-05 0.000136 -0.000697 9.9e-05</velocity>
          <acceleration>-0.002184 0.00528 0.000309 0.111233 -0.013137 0.087849</acceleration>
          <wrench>-0.000341 0.000824 4.8e-05 0 -0 0</wrench>
        </link>
        <link name='l_upper_arm'>
          <pose frame=''>0.042198 0.168611 0.724765 -2.7773 -0.596034 0.056374</pose>
          <velocity>-7.3e-05 3e-06 4.6e-05 6.4e-05 -0.000701 5e-05</velocity>
          <acceleration>-0.001803 0.005244 0.000628 -0.075654 -0.045323 -0.035776</acceleration>
          <wrench>-0.001313 0.003817 0.000457 0 -0 0</wrench>
        </link>
        <link name='l_upper_leg'>
          <pose frame=''>-0.029761 0.098345 0.47477 1.65733 -0.129053 0.036941</pose>
          <velocity>-2.1e-05 7.8e-05 2.5e-05 -0.00034 -8.1e-05 -2.5e-05</velocity>
          <acceleration>-0.002083 0.045456 0.015885 -1.17273 -0.004475 0.491572</acceleration>
          <wrench>-0.004531 0.098867 0.034549 0 -0 0</wrench>
        </link>
        <link name='l_wrist_1'>
          <pose frame=''>0.210278 0.24664 0.624711 -1.2679 0.151584 0.314285</pose>
          <velocity>-4e-06 1.5e-05 0.000179 0.000137 -0.000772 6.5e-05</velocity>
          <acceleration>0.001518 -0.005674 -0.002609 0.023164 0.003738 0.011864</acceleration>
          <wrench>0.000152 -0.000567 -0.000261 0 -0 0</wrench>
        </link>
        <link name='left_eye_link'>
          <pose frame=''>0.054597 0.067684 0.933316 -3.14066 -0.021969 -3.10548</pose>
          <velocity>-0.000185 -1.3e-05 3.8e-05 2e-05 -0.000532 -5.1e-05</velocity>
          <acceleration>-0.000411 0.000511 0.001092 0.008333 0.01984 0.008866</acceleration>
          <wrench>-4e-06 5e-06 1.1e-05 0 -0 0</wrench>
        </link>
        <link name='neck_1'>
          <pose frame=''>-0.001661 0.031524 0.819089 3.10194 -1.54881 0.075778</pose>
          <velocity>-0.000128 -9e-06 9e-06 1.8e-05 -0.000504 -2.8e-05</velocity>
          <acceleration>-0.000762 0.000813 0.000932 -0.024407 0.004156 0.001088</acceleration>
          <wrench>-7.6e-05 8.1e-05 9.3e-05 0 -0 0</wrench>
        </link>
        <link name='neck_2'>
          <pose frame=''>-0.001453 0.03154 0.828579 0.021962 0.000929 1.60694</pose>
          <velocity>-0.000133 -9e-06 9e-06 2e-05 -0.000504 -2.8e-05</velocity>
          <acceleration>-0.000699 0.001018 0.001164 0.008714 0.005413 0.000376</acceleration>
          <wrench>-7e-05 0.000102 0.000116 0 -0 0</wrench>
        </link>
        <link name='r_ankle_1'>
          <pose frame=''>-0.001149 -0.071816 0.041882 -1.57101 -1.49101 1.59498</pose>
          <velocity>5e-06 -7.8e-05 1.7e-05 -0.000109 6.6e-05 2e-06</velocity>
          <acceleration>0.004625 -0.145537 -0.002236 -0.196818 0.030603 -0.008597</acceleration>
          <wrench>0.00345 -0.10857 -0.001668 0 -0 0</wrench>
        </link>
        <link name='r_ankle_2'>
          <pose frame=''>-0.001149 -0.071815 0.041896 3.14158 -1.6e-05 0.023966</pose>
          <velocity>5e-06 -8e-05 2.3e-05 0.002215 0.000122 2e-06</velocity>
          <acceleration>-9.4e-05 0.006488 0.001531 -2.08853 0.134557 -0.009528</acceleration>
          <wrench>-2.5e-05 0.001735 0.00041 0 -0 0</wrench>
        </link>
        <link name='r_elbow_1'>
          <pose frame=''>0.096669 -0.131639 0.659885 1.10107 1.23188 -2.2597</pose>
          <velocity>-3.6e-05 -1.7e-05 7.5e-05 -8.4e-05 -0.00089 2.5e-05</velocity>
          <acceleration>0.001988 0.000272 0.005037 0.013302 -0.005536 -0.005945</acceleration>
          <wrench>0.000199 2.7e-05 0.000504 0 -0 0</wrench>
        </link>
        <link name='r_foot'>
          <pose frame=''>-0.001148 -0.071814 0.004898 3.14158 -4e-06 0.023962</pose>
          <velocity>0 1e-06 2.4e-05 -0.000189 6.5e-05 6e-06</velocity>
          <acceleration>0.000243 0.027309 0.001931 -0.822543 0.006426 -0.093152</acceleration>
          <wrench>0.000144 0.016208 0.001146 0 -0 0</wrench>
        </link>
        <link name='r_forearm'>
          <pose frame=''>0.093499 -0.135489 0.645736 0.158237 0.301124 1.37569</pose>
          <velocity>-2.4e-05 -1.8e-05 7.2e-05 -9.2e-05 -0.000888 2.6e-05</velocity>
          <acceleration>0.002072 0.000142 0.005115 -0.003499 -0.00787 -0.004486</acceleration>
          <wrench>0.001088 7.5e-05 0.002685 0 -0 0</wrench>
        </link>
        <link name='r_hand'>
          <pose frame=''>0.225267 -0.168072 0.625072 -1.92949 0.564443 -0.393057</pose>
          <velocity>-4e-06 -1.7e-05 0.000192 -0.000218 -0.001539 0.000249</velocity>
          <acceleration>-0.004142 -0.002769 -0.00486 -0.152585 0.17391 -0.230491</acceleration>
          <wrench>-0.000882 -0.00059 -0.001035 0 -0 0</wrench>
        </link>
        <link name='r_hip_1'>
          <pose frame=''>-0.024841 -0.037758 0.474866 3.1346 1.43532 0.029201</pose>
          <velocity>-1.9e-05 2.4e-05 -4e-06 0.000163 -6.7e-05 -5e-06</velocity>
          <acceleration>0.000152 0.050318 0.00275 0.322545 0.022783 0.018731</acceleration>
          <wrench>0.000115 0.03794 0.002074 0 -0 0</wrench>
        </link>
        <link name='r_hip_2'>
          <pose frame=''>-0.024841 -0.037757 0.474871 3.06089 -0.135471 0.036253</pose>
          <velocity>-1.9e-05 2.5e-05 -3e-06 -0.001015 -0.00011 -0.000165</velocity>
          <acceleration>0.002556 -0.007089 -0.017215 -1.91402 -0.058685 -0.286292</acceleration>
          <wrench>0.001344 -0.003729 -0.009055 0 -0 0</wrench>
        </link>
        <link name='r_hip_3'>
          <pose frame=''>-0.015703 -0.042787 0.40923 3.06089 -0.135476 0.036253</pose>
          <velocity>-1.3e-05 -3.9e-05 1.2e-05 -8.7e-05 -7.6e-05 -3.9e-05</velocity>
          <acceleration>0.003102 -0.069356 -0.007066 -0.168189 0.006951 -0.048402</acceleration>
          <wrench>0.00031 -0.006936 -0.000707 0 -0 0</wrench>
        </link>
        <link name='r_lower_leg'>
          <pose frame=''>0.005892 -0.054678 0.25407 -2.72928 -1.4837 1.18104</pose>
          <velocity>-2e-06 -5.5e-05 1.3e-05 -0.000107 -2.8e-05 9e-06</velocity>
          <acceleration>0.003183 -0.122358 -0.003589 -0.196318 -0.014803 -0.006071</acceleration>
          <wrench>0.004023 -0.15466 -0.004536 0 -0 0</wrench>
        </link>
        <link name='r_shoulder_1'>
          <pose frame=''>0.003524 -0.078664 0.769127 3.12408 -1.08642 -2.82831</pose>
          <velocity>-0.000108 -8e-06 1e-05 7.5e-05 -0.000663 -3e-05</velocity>
          <acceleration>-0.000524 -0.000314 0.002737 0.063594 -0.087216 0.092431</acceleration>
          <wrench>-9.9e-05 -5.9e-05 0.000517 0 -0 0</wrench>
        </link>
        <link name='r_shoulder_2'>
          <pose frame=''>0.003524 -0.078664 0.769124 0.542339 -0.446274 -1.53177</pose>
          <velocity>-0.000108 -8e-06 1e-05 -1.6e-05 -0.000691 -8e-05</velocity>
          <acceleration>-0.000135 -0.000377 0.003356 0.198247 -0.018862 -0.129316</acceleration>
          <wrench>-2.4e-05 -6.8e-05 0.000601 0 -0 0</wrench>
        </link>
        <link name='r_shoulder_3'>
          <pose frame=''>0.003524 -0.078665 0.769122 2.77521 -0.596082 0.017036</pose>
          <velocity>-0.000108 -8e-06 1e-05 -4.1e-05 -0.000675 -4.4e-05</velocity>
          <acceleration>0.000319 -0.000242 0.003893 -0.002344 -0.019691 -0.011107</acceleration>
          <wrench>4.9e-05 -3.8e-05 0.000603 0 -0 0</wrench>
        </link>
        <link name='r_upper_arm'>
          <pose frame=''>0.051986 -0.102203 0.725001 2.77521 -0.596082 0.017036</pose>
          <velocity>-7.9e-05 -1.2e-05 4.3e-05 -4.1e-05 -0.000675 -4.4e-05</velocity>
          <acceleration>0.001072 -0.000112 0.004535 0.003829 -0.001029 0.002582</acceleration>
          <wrench>0.000782 -8.2e-05 0.003306 0 -0 0</wrench>
        </link>
        <link name='r_upper_leg'>
          <pose frame=''>-0.024844 -0.037754 0.474897 1.49027 -0.135587 0.034867</pose>
          <velocity>-1.8e-05 -3.3e-05 8e-06 -0.000104 -7.3e-05 1.3e-05</velocity>
          <acceleration>0.002281 -0.089223 -0.006988 -0.192165 0.009399 -0.007087</acceleration>
          <wrench>0.004962 -0.19406 -0.0152 0 -0 0</wrench>
        </link>
        <link name='r_wrist_1'>
          <pose frame=''>0.225267 -0.168071 0.625073 1.87551 -0.151061 2.89918</pose>
          <velocity>-4e-06 -1.7e-05 0.000192 -8.8e-05 -0.000884 4.1e-05</velocity>
          <acceleration>0.002037 -0.000152 0.00533 0.002886 -0.005445 -0.010091</acceleration>
          <wrench>0.000204 -1.5e-05 0.000533 0 -0 0</wrench>
        </link>
        <link name='right_eye_link'>
          <pose frame=''>0.057052 -0.000271 0.93338 -3.14066 -0.021969 -3.10551</pose>
          <velocity>-0.000187 -1.3e-05 3.8e-05 2e-05 -0.000532 -5.1e-05</velocity>
          <acceleration>8.7e-05 0.000531 0.000459 0.008361 0.01985 0.008866</acceleration>
          <wrench>1e-06 5e-06 5e-06 0 -0 0</wrench>
        </link>
        <link name='root_link'>
          <pose frame=''>-0.017277 0.030764 0.594278 0.000886 -0.083781 -3.10555</pose>
          <velocity>-2.2e-05 3e-06 6e-06 0.000168 -3.2e-05 -4e-06</velocity>
          <acceleration>-0.000609 0.009985 -0.000886 0.318606 -0.009676 0.02008</acceleration>
          <wrench>-0.002873 0.047131 -0.00418 0 -0 0</wrench>
        </link>
        <link name='torso_1'>
          <pose frame=''>-0.017276 0.030764 0.594291 -0.025365 -1.53601 0.061465</pose>
          <velocity>-2.2e-05 3e-06 7e-06 0.000184 -0.000467 -3e-06</velocity>
          <acceleration>-0.000655 0.010636 -0.001189 -1.98485 0.113025 2.40564</acceleration>
          <wrench>-6.6e-05 0.001064 -0.000119 0 -0 0</wrench>
        </link>
        <link name='torso_2'>
          <pose frame=''>-0.016167 0.030832 0.626238 3.10681 -0.00087 -1.53468</pose>
          <velocity>-3.7e-05 -4e-06 5e-06 1.8e-05 -0.000473 2e-06</velocity>
          <acceleration>-0.00026 -0.001369 -0.000494 -0.02426 -0.001913 0.02587</acceleration>
          <wrench>-2.6e-05 -0.000137 -4.9e-05 0 -0 0</wrench>
        </link>
      </model>
      <light name='sun'>
        <pose frame=''>0 0 10 0 -0 0</pose>
      </light>
    </state>
    <gui fullscreen='0'>
      <camera name='user_camera'>
        <pose frame=''>1.33511 -0.859083 0.940133 0 0.255643 2.44419</pose>
        <view_controller>orbit</view_controller>
        <projection_type>perspective</projection_type>
      </camera>
    </gui>
    <plugin name='ocra_gui_plugin' filename='libocra_gui_plugin.so'/>
    <model name='RightHandTarget'>
      <static>1</static>
      <link name='link'>
        <visual name='visual'>
          <pose frame=''>0 0 0 0 -0 0</pose>
          <geometry>
            <sphere>
              <radius>0.03</radius>
            </sphere>
          </geometry>
          <material>
            <ambient>1 0 0 0.6</ambient>
            <diffuse>1 0 0 0.6</diffuse>
          </material>
          <transparency>0.2</transparency>
        </visual>
        <self_collide>0</self_collide>
        <kinematic>0</kinematic>
      </link>
      <plugin name='yarp_model_move' filename='libyarp_model_move.so'/>
      <plugin name='task_optimization_change_color' filename='libtask_optimization_change_color.so'/>
      <pose frame=''>0.00963 -0.003675 0 0 -0 0</pose>
    </model>
  </world>
</sdf>
