<sdf version='1.6'>
  <world name='default'>
    <light name='sun' type='directional'>
      <cast_shadows>1</cast_shadows>
      <pose frame=''>0 0 10 0 -0 0</pose>
      <diffuse>0.8 0.8 0.8 1</diffuse>
      <specular>0.1 0.1 0.1 1</specular>
      <attenuation>
        <range>1000</range>
        <constant>0.9</constant>
        <linear>0.01</linear>
        <quadratic>0.001</quadratic>
      </attenuation>
      <direction>-0.5 0.5 -1</direction>
    </light>
    <model name='ground_plane'>
      <static>1</static>
      <link name='link'>
        <collision name='collision'>
          <geometry>
            <plane>
              <normal>0 0 1</normal>
              <size>100 100</size>
            </plane>
          </geometry>
          <surface>
            <friction>
              <ode>
                <mu>100</mu>
                <mu2>50</mu2>
              </ode>
              <torsional>
                <ode/>
              </torsional>
            </friction>
            <contact>
              <ode/>
            </contact>
            <bounce/>
          </surface>
          <max_contacts>10</max_contacts>
        </collision>
        <visual name='visual'>
          <cast_shadows>0</cast_shadows>
          <geometry>
            <plane>
              <normal>0 0 1</normal>
              <size>100 100</size>
            </plane>
          </geometry>
          <material>
            <script>
              <uri>file://media/materials/scripts/gazebo.material</uri>
              <name>Gazebo/White</name>
            </script>
          </material>
        </visual>
        <self_collide>0</self_collide>
        <kinematic>0</kinematic>
      </link>
    </model>
    <model name='iCub'>
      <pose frame=''>0 0 0.6 0 -0 3.14</pose>
      <link name='root_link'>
        <pose frame=''>0 0 0 0 -0 0</pose>
        <inertial>
          <pose frame=''>0 0 0 0 -0 0</pose>
          <mass>4.72</mass>
          <inertia>
            <ixx>0.01</ixx>
            <ixy>0</ixy>
            <ixz>0</ixz>
            <iyy>0.01</iyy>
            <iyz>0</iyz>
            <izz>0.01</izz>
          </inertia>
        </inertial>
        <collision name='root_link_collision'>
          <pose frame=''>0 0 0 0 -0 0</pose>
          <geometry>
            <mesh>
              <scale>1 1 1</scale>
              <uri>model://icub/meshes/collision/icub_simple_collision_root_link.dae</uri>
            </mesh>
          </geometry>
          <max_contacts>10</max_contacts>
          <surface>
            <contact>
              <ode/>
            </contact>
            <bounce/>
            <friction>
              <torsional>
                <ode/>
              </torsional>
              <ode/>
            </friction>
          </surface>
        </collision>
        <visual name='root_link_visual'>
          <pose frame=''>0 0 0 0 -0 0</pose>
          <geometry>
            <mesh>
              <scale>1 1 1</scale>
              <uri>model://icub/meshes/visual/icub_root_link.dae</uri>
            </mesh>
          </geometry>
        </visual>
        <self_collide>0</self_collide>
        <kinematic>0</kinematic>
      </link>
      <link name='l_hip_1'>
        <pose frame=''>0 -0.0681 -0.1199 3e-06 1.57079 3.14159</pose>
        <inertial>
          <pose frame=''>0 -0.0782 0 0 -0 0</pose>
          <mass>0.754</mass>
          <inertia>
            <ixx>0.01</ixx>
            <ixy>2.059e-06</ixy>
            <ixz>1.451e-06</ixz>
            <iyy>0.01</iyy>
            <iyz>1.545e-06</iyz>
            <izz>0.01</izz>
          </inertia>
        </inertial>
        <collision name='l_hip_1_collision'>
          <pose frame=''>0 0 0 -0.785403 1.57079 -2.35619</pose>
          <geometry>
            <mesh>
              <scale>1 1 1</scale>
              <uri>model://icub/meshes/collision/icub_simple_collision_l_hip_1.dae</uri>
            </mesh>
          </geometry>
          <max_contacts>10</max_contacts>
          <surface>
            <contact>
              <ode/>
            </contact>
            <bounce/>
            <friction>
              <torsional>
                <ode/>
              </torsional>
              <ode/>
            </friction>
          </surface>
        </collision>
        <visual name='l_hip_1_visual'>
          <pose frame=''>0 0 0 -0.785403 1.57079 -2.35619</pose>
          <geometry>
            <mesh>
              <scale>1 1 1</scale>
              <uri>model://icub/meshes/visual/icub_l_hip_1.dae</uri>
            </mesh>
          </geometry>
        </visual>
        <self_collide>0</self_collide>
        <kinematic>0</kinematic>
      </link>
      <joint name='l_hip_pitch' type='revolute'>
        <child>l_hip_1</child>
        <parent>root_link</parent>
        <axis>
          <xyz>3e-06 1 0</xyz>
          <limit>
            <lower>-0.767945</lower>
            <upper>2.30383</upper>
            <effort>84</effort>
            <velocity>100</velocity>
          </limit>
          <dynamics>
            <damping>1</damping>
            <friction>0</friction>
            <spring_reference>0</spring_reference>
            <spring_stiffness>0</spring_stiffness>
          </dynamics>
          <use_parent_model_frame>1</use_parent_model_frame>
        </axis>
      </joint>
      <link name='l_hip_2'>
        <pose frame=''>0 -0.0681 -0.1199 3.14159 -7e-06 3.14159</pose>
        <inertial>
          <pose frame=''>0 0 0.03045 0 -0 0</pose>
          <mass>0.526</mass>
          <inertia>
            <ixx>0.01</ixx>
            <ixy>-7.4e-08</ixy>
            <ixz>1.0835e-05</ixz>
            <iyy>0.01</iyy>
            <iyz>-6.2e-08</iyz>
            <izz>0.01</izz>
          </inertia>
        </inertial>
        <collision name='l_hip_2_collision'>
          <pose frame=''>0 0 0 0.785363 -1.57079 2.35623</pose>
          <geometry>
            <mesh>
              <scale>1 1 1</scale>
              <uri>model://icub/meshes/collision/icub_simple_collision_l_hip_2.dae</uri>
            </mesh>
          </geometry>
          <max_contacts>10</max_contacts>
          <surface>
            <contact>
              <ode/>
            </contact>
            <bounce/>
            <friction>
              <torsional>
                <ode/>
              </torsional>
              <ode/>
            </friction>
          </surface>
        </collision>
        <visual name='l_hip_2_visual'>
          <pose frame=''>0 0 0 0.785363 -1.57079 2.35623</pose>
          <geometry>
            <mesh>
              <scale>1 1 1</scale>
              <uri>model://icub/meshes/visual/icub_l_hip_2.dae</uri>
            </mesh>
          </geometry>
        </visual>
        <self_collide>0</self_collide>
        <kinematic>0</kinematic>
      </link>
      <joint name='l_hip_roll' type='revolute'>
        <child>l_hip_2</child>
        <parent>l_hip_1</parent>
        <axis>
          <xyz>-1 3e-06 7e-06</xyz>
          <limit>
            <lower>-0.296706</lower>
            <upper>2.07694</upper>
            <effort>84</effort>
            <velocity>100</velocity>
          </limit>
          <dynamics>
            <damping>1</damping>
            <friction>0</friction>
            <spring_reference>0</spring_reference>
            <spring_stiffness>0</spring_stiffness>
          </dynamics>
          <use_parent_model_frame>1</use_parent_model_frame>
        </axis>
      </joint>
      <link name='l_hip_3'>
        <pose frame=''>-0 -0.0681 -0.1864 3.14159 -7e-06 3.14159</pose>
        <inertial>
          <pose frame=''>0 0 0 0 -0 0</pose>
          <mass>0.1</mass>
          <inertia>
            <ixx>0.01</ixx>
            <ixy>0</ixy>
            <ixz>0</ixz>
            <iyy>0.01</iyy>
            <iyz>0</iyz>
            <izz>0.01</izz>
          </inertia>
        </inertial>
        <self_collide>0</self_collide>
        <kinematic>0</kinematic>
      </link>
      <joint name='l_leg_ft_sensor' type='revolute'>
        <child>l_hip_3</child>
        <parent>l_hip_2</parent>
        <axis>
          <xyz>0 0 0</xyz>
          <limit>
            <lower>0</lower>
            <upper>0</upper>
            <effort>0</effort>
            <velocity>0</velocity>
          </limit>
          <dynamics>
            <spring_reference>0</spring_reference>
            <spring_stiffness>0</spring_stiffness>
          </dynamics>
          <use_parent_model_frame>1</use_parent_model_frame>
        </axis>
        <sensor name='left_leg_ft' type='force_torque'>
          <always_on>1</always_on>
          <update_rate>100</update_rate>
          <pose frame=''>0 0 0 0 -0 0</pose>
          <plugin name='left_leg_ft_plugin' filename='libgazebo_yarp_forcetorque.so'>
            <yarpConfigurationFile>model://icub/conf/FT/gazebo_icub_left_leg_ft.ini</yarpConfigurationFile>
          </plugin>
        </sensor>
      </joint>
      <link name='l_upper_leg'>
        <pose frame=''>0 -0.0681 -0.1199 1.57079 -7e-06 3.14159</pose>
        <inertial>
          <pose frame=''>0.00144 -0.15943 -0.00039 0 -0 0</pose>
          <mass>2.175</mass>
          <inertia>
            <ixx>0.01</ixx>
            <ixy>-6.726e-05</ixy>
            <ixz>2.267e-06</ixz>
            <iyy>0.01</iyy>
            <iyz>3.63726e-05</iyz>
            <izz>0.01</izz>
          </inertia>
        </inertial>
        <collision name='l_upper_leg_collision'>
          <pose frame=''>0 0 0 -2.67797 1.57079 -1.10716</pose>
          <geometry>
            <mesh>
              <scale>1 1 1</scale>
              <uri>model://icub/meshes/collision/icub_simple_collision_l_thigh.dae</uri>
            </mesh>
          </geometry>
          <max_contacts>10</max_contacts>
          <surface>
            <contact>
              <ode/>
            </contact>
            <bounce/>
            <friction>
              <torsional>
                <ode/>
              </torsional>
              <ode/>
            </friction>
          </surface>
        </collision>
        <visual name='l_upper_leg_visual'>
          <pose frame=''>0 0 0 -2.67797 1.57079 -1.10716</pose>
          <geometry>
            <mesh>
              <scale>1 1 1</scale>
              <uri>model://icub/meshes/visual/icub_l_thigh.dae</uri>
            </mesh>
          </geometry>
        </visual>
        <self_collide>0</self_collide>
        <kinematic>0</kinematic>
      </link>
      <joint name='l_hip_yaw' type='revolute'>
        <child>l_upper_leg</child>
        <parent>l_hip_3</parent>
        <axis>
          <xyz>7e-06 -6e-06 1</xyz>
          <limit>
            <lower>-1.37881</lower>
            <upper>1.37881</upper>
            <effort>40</effort>
            <velocity>100</velocity>
          </limit>
          <dynamics>
            <damping>1</damping>
            <friction>0</friction>
            <spring_reference>0</spring_reference>
            <spring_stiffness>0</spring_stiffness>
          </dynamics>
          <use_parent_model_frame>1</use_parent_model_frame>
        </axis>
      </joint>
      <link name='l_lower_leg'>
        <pose frame=''>-2e-06 -0.068099 -0.3435 2.09198 -1.57078 -0.521189</pose>
        <inertial>
          <pose frame=''>-0.1071 0.00182 0.00211 0 -0 0</pose>
          <mass>1.264</mass>
          <inertia>
            <ixx>0.01</ixx>
            <ixy>-0.000185699</ixy>
            <ixz>-6.3147e-05</ixz>
            <iyy>0.01</iyy>
            <iyz>7.86e-07</iyz>
            <izz>0.01</izz>
          </inertia>
        </inertial>
        <collision name='l_lower_leg_collision'>
          <pose frame=''>0 0 0 -3.14159 -0 1.5708</pose>
          <geometry>
            <mesh>
              <scale>1 1 1</scale>
              <uri>model://icub/meshes/collision/icub_simple_collision_l_shank.dae</uri>
            </mesh>
          </geometry>
          <max_contacts>10</max_contacts>
          <surface>
            <contact>
              <ode/>
            </contact>
            <bounce/>
            <friction>
              <torsional>
                <ode/>
              </torsional>
              <ode/>
            </friction>
          </surface>
        </collision>
        <visual name='l_lower_leg_visual'>
          <pose frame=''>0 0 0 -3.14159 -0 1.5708</pose>
          <geometry>
            <mesh>
              <scale>1 1 1</scale>
              <uri>model://icub/meshes/visual/icub_l_shank.dae</uri>
            </mesh>
          </geometry>
        </visual>
        <self_collide>0</self_collide>
        <kinematic>0</kinematic>
      </link>
      <joint name='l_knee' type='revolute'>
        <child>l_lower_leg</child>
        <parent>l_upper_leg</parent>
        <axis>
          <xyz>5e-06 1 6e-06</xyz>
          <limit>
            <lower>-2.18166</lower>
            <upper>0.401426</upper>
            <effort>30</effort>
            <velocity>100</velocity>
          </limit>
          <dynamics>
            <damping>1</damping>
            <friction>0</friction>
            <spring_reference>0</spring_reference>
            <spring_stiffness>0</spring_stiffness>
          </dynamics>
          <use_parent_model_frame>1</use_parent_model_frame>
        </axis>
      </joint>
      <link name='l_ankle_1'>
        <pose frame=''>-4e-06 -0.068097 -0.5565 0.52118 -1.57078 -0.521189</pose>
        <inertial>
          <pose frame=''>-0.0054 0.00163 0.0172 0 -0 0</pose>
          <mass>0.746</mass>
          <inertia>
            <ixx>0.01</ixx>
            <ixy>-7.081e-06</ixy>
            <ixz>4.1421e-05</ixz>
            <iyy>0.01</iyy>
            <iyz>2.0817e-05</iyz>
            <izz>0.01</izz>
          </inertia>
        </inertial>
        <collision name='l_ankle_1_collision'>
          <pose frame=''>0 -0 0 1.5708 -0 0</pose>
          <geometry>
            <mesh>
              <scale>1 1 1</scale>
              <uri>model://icub/meshes/collision/icub_simple_collision_l_ankle_1.dae</uri>
            </mesh>
          </geometry>
          <max_contacts>10</max_contacts>
          <surface>
            <contact>
              <ode/>
            </contact>
            <bounce/>
            <friction>
              <torsional>
                <ode/>
              </torsional>
              <ode/>
            </friction>
          </surface>
        </collision>
        <visual name='l_ankle_1_visual'>
          <pose frame=''>0 -0 0 1.5708 -0 0</pose>
          <geometry>
            <mesh>
              <scale>1 1 1</scale>
              <uri>model://icub/meshes/visual/icub_l_ankle_1.dae</uri>
            </mesh>
          </geometry>
        </visual>
        <self_collide>0</self_collide>
        <kinematic>0</kinematic>
      </link>
      <joint name='l_ankle_pitch' type='revolute'>
        <child>l_ankle_1</child>
        <parent>l_lower_leg</parent>
        <axis>
          <xyz>-9e-06 -1 -6e-06</xyz>
          <limit>
            <lower>-0.733038</lower>
            <upper>0.366519</upper>
            <effort>24</effort>
            <velocity>100</velocity>
          </limit>
          <dynamics>
            <damping>1</damping>
            <friction>0</friction>
            <spring_reference>0</spring_reference>
            <spring_stiffness>0</spring_stiffness>
          </dynamics>
          <use_parent_model_frame>1</use_parent_model_frame>
        </axis>
      </joint>
      <link name='l_ankle_2'>
        <pose frame=''>-4e-06 -0.068097 -0.5565 3.14159 -7e-06 3.14158</pose>
        <inertial>
          <pose frame=''>0 0 0.037 0 -0 0</pose>
          <mass>0.2675</mass>
          <inertia>
            <ixx>0.01</ixx>
            <ixy>0</ixy>
            <ixz>0</ixz>
            <iyy>0.01</iyy>
            <iyz>0</iyz>
            <izz>0.01</izz>
          </inertia>
        </inertial>
        <self_collide>0</self_collide>
        <kinematic>0</kinematic>
      </link>
      <joint name='l_ankle_roll' type='revolute'>
        <child>l_ankle_2</child>
        <parent>l_ankle_1</parent>
        <axis>
          <xyz>-1 9e-06 7e-06</xyz>
          <limit>
            <lower>-0.418879</lower>
            <upper>0.418879</upper>
            <effort>11</effort>
            <velocity>100</velocity>
          </limit>
          <dynamics>
            <damping>1</damping>
            <friction>0</friction>
            <spring_reference>0</spring_reference>
            <spring_stiffness>0</spring_stiffness>
          </dynamics>
          <use_parent_model_frame>1</use_parent_model_frame>
        </axis>
      </joint>
      <link name='l_foot'>
        <pose frame=''>-4e-06 -0.068097 -0.5935 3.14159 -7e-06 3.14158</pose>
        <inertial>
          <pose frame=''>0.024069 -0.000614 -0.028415 0 -0 0</pose>
          <mass>0.5935</mass>
          <inertia>
            <ixx>0.01</ixx>
            <ixy>-4.51893e-06</ixy>
            <ixz>0.000567785</ixz>
            <iyy>0.01</iyy>
            <iyz>-6.62361e-07</iyz>
            <izz>0.01</izz>
          </inertia>
        </inertial>
        <collision name='l_foot_collision'>
          <pose frame=''>0.03 0 -0.01 0 -0 0</pose>
          <geometry>
            <box>
              <size>0.15 0.07 0.03</size>
            </box>
          </geometry>
          <max_contacts>4</max_contacts>
          <surface>
            <contact>
              <ode>
                <soft_erp>0.2</soft_erp>
                <soft_cfm>0</soft_cfm>
                <kp>1.8e+07</kp>
                <kd>100</kd>
                <max_vel>100</max_vel>
                <min_depth>0.0001</min_depth>
              </ode>
            </contact>
            <friction>
              <ode>
                <mu>1</mu>
                <mu2>1</mu2>
                <fdir1>0 0 0</fdir1>
                <slip1>0</slip1>
                <slip2>0</slip2>
              </ode>
              <torsional>
                <ode/>
              </torsional>
            </friction>
            <bounce>
              <restitution_coefficient>0</restitution_coefficient>
              <threshold>100000</threshold>
            </bounce>
          </surface>
        </collision>
        <visual name='l_foot_visual'>
          <pose frame=''>0 -0 -0.037 -0.785403 1.57079 -0.785403</pose>
          <geometry>
            <mesh>
              <scale>1 1 1</scale>
              <uri>model://icub/meshes/visual/icub_l_foot.dae</uri>
            </mesh>
          </geometry>
        </visual>
        <self_collide>0</self_collide>
        <kinematic>0</kinematic>
      </link>
      <joint name='l_foot_ft_sensor' type='revolute'>
        <child>l_foot</child>
        <parent>l_ankle_2</parent>
        <axis>
          <xyz>0 0 0</xyz>
          <limit>
            <lower>0</lower>
            <upper>0</upper>
            <effort>0</effort>
            <velocity>0</velocity>
          </limit>
          <dynamics>
            <spring_reference>0</spring_reference>
            <spring_stiffness>0</spring_stiffness>
          </dynamics>
          <use_parent_model_frame>1</use_parent_model_frame>
        </axis>
        <sensor name='left_foot_ft' type='force_torque'>
          <always_on>1</always_on>
          <update_rate>100</update_rate>
          <pose frame=''>0 0 0 0 -0 0</pose>
          <plugin name='left_foot_ft_plugin' filename='libgazebo_yarp_forcetorque.so'>
            <yarpConfigurationFile>model://icub/conf/FT/gazebo_icub_left_foot_ft.ini</yarpConfigurationFile>
          </plugin>
        </sensor>
      </joint>
      <link name='r_hip_1'>
        <pose frame=''>0 0.0681 -0.1199 3.14159 1.57079 -3.14159</pose>
        <inertial>
          <pose frame=''>0 -0.0782 0 0 -0 0</pose>
          <mass>0.754</mass>
          <inertia>
            <ixx>0.01</ixx>
            <ixy>0</ixy>
            <ixz>0</ixz>
            <iyy>0.01</iyy>
            <iyz>0</iyz>
            <izz>0.01</izz>
          </inertia>
        </inertial>
        <collision name='r_hip_1_collision'>
          <pose frame=''>0 0 0 1.76819 -1.57079 2.76109</pose>
          <geometry>
            <mesh>
              <scale>1 1 1</scale>
              <uri>model://icub/meshes/collision/icub_simple_collision_r_hip_1.dae</uri>
            </mesh>
          </geometry>
          <max_contacts>10</max_contacts>
          <surface>
            <contact>
              <ode/>
            </contact>
            <bounce/>
            <friction>
              <torsional>
                <ode/>
              </torsional>
              <ode/>
            </friction>
          </surface>
        </collision>
        <visual name='r_hip_1_visual'>
          <pose frame=''>0 0 0 1.76819 -1.57079 2.76109</pose>
          <geometry>
            <mesh>
              <scale>1 1 1</scale>
              <uri>model://icub/meshes/visual/icub_r_hip_1.dae</uri>
            </mesh>
          </geometry>
        </visual>
        <self_collide>0</self_collide>
        <kinematic>0</kinematic>
      </link>
      <joint name='r_hip_pitch' type='revolute'>
        <child>r_hip_1</child>
        <parent>root_link</parent>
        <axis>
          <xyz>0 1 0</xyz>
          <limit>
            <lower>-0.767945</lower>
            <upper>2.30383</upper>
            <effort>84</effort>
            <velocity>100</velocity>
          </limit>
          <dynamics>
            <damping>1</damping>
            <friction>0</friction>
            <spring_reference>0</spring_reference>
            <spring_stiffness>0</spring_stiffness>
          </dynamics>
          <use_parent_model_frame>1</use_parent_model_frame>
        </axis>
      </joint>
      <link name='r_hip_2'>
        <pose frame=''>0 0.0681 -0.1199 -3.14159 -7e-06 -3.14159</pose>
        <inertial>
          <pose frame=''>0 0 0.03045 0 -0 0</pose>
          <mass>0.526</mass>
          <inertia>
            <ixx>0.01</ixx>
            <ixy>0</ixy>
            <ixz>0</ixz>
            <iyy>0.01</iyy>
            <iyz>0</iyz>
            <izz>0.01</izz>
          </inertia>
        </inertial>
        <collision name='r_hip_2_collision'>
          <pose frame=''>0 0 0 -2.35627 -1.57079 2.35627</pose>
          <geometry>
            <mesh>
              <scale>1 1 1</scale>
              <uri>model://icub/meshes/collision/icub_simple_collision_r_hip_2.dae</uri>
            </mesh>
          </geometry>
          <max_contacts>10</max_contacts>
          <surface>
            <contact>
              <ode/>
            </contact>
            <bounce/>
            <friction>
              <torsional>
                <ode/>
              </torsional>
              <ode/>
            </friction>
          </surface>
        </collision>
        <visual name='r_hip_2_visual'>
          <pose frame=''>0 0 0 -2.35627 -1.57079 2.35627</pose>
          <geometry>
            <mesh>
              <scale>1 1 1</scale>
              <uri>model://icub/meshes/visual/icub_r_hip_2.dae</uri>
            </mesh>
          </geometry>
        </visual>
        <self_collide>0</self_collide>
        <kinematic>0</kinematic>
      </link>
      <joint name='r_hip_roll' type='revolute'>
        <child>r_hip_2</child>
        <parent>r_hip_1</parent>
        <axis>
          <xyz>1 0 -7e-06</xyz>
          <limit>
            <lower>-0.296706</lower>
            <upper>2.07694</upper>
            <effort>84</effort>
            <velocity>100</velocity>
          </limit>
          <dynamics>
            <damping>1</damping>
            <friction>0</friction>
            <spring_reference>0</spring_reference>
            <spring_stiffness>0</spring_stiffness>
          </dynamics>
          <use_parent_model_frame>1</use_parent_model_frame>
        </axis>
      </joint>
      <link name='r_hip_3'>
        <pose frame=''>-0 0.0681 -0.1864 -3.14159 -7e-06 -3.14159</pose>
        <inertial>
          <pose frame=''>0 0 0 0 -0 0</pose>
          <mass>0.1</mass>
          <inertia>
            <ixx>0.01</ixx>
            <ixy>0</ixy>
            <ixz>0</ixz>
            <iyy>0.01</iyy>
            <iyz>0</iyz>
            <izz>0.01</izz>
          </inertia>
        </inertial>
        <self_collide>0</self_collide>
        <kinematic>0</kinematic>
      </link>
      <joint name='r_leg_ft_sensor' type='revolute'>
        <child>r_hip_3</child>
        <parent>r_hip_2</parent>
        <axis>
          <xyz>0 0 0</xyz>
          <limit>
            <lower>0</lower>
            <upper>0</upper>
            <effort>0</effort>
            <velocity>0</velocity>
          </limit>
          <dynamics>
            <spring_reference>0</spring_reference>
            <spring_stiffness>0</spring_stiffness>
          </dynamics>
          <use_parent_model_frame>1</use_parent_model_frame>
        </axis>
        <sensor name='right_leg_ft' type='force_torque'>
          <always_on>1</always_on>
          <update_rate>100</update_rate>
          <pose frame=''>0 0 0 0 -0 0</pose>
          <plugin name='right_leg_ft_plugin' filename='libgazebo_yarp_forcetorque.so'>
            <yarpConfigurationFile>model://icub/conf/FT/gazebo_icub_right_leg_ft.ini</yarpConfigurationFile>
          </plugin>
        </sensor>
      </joint>
      <link name='r_upper_leg'>
        <pose frame=''>0 0.0681 -0.1199 1.57079 -7e-06 3.14159</pose>
        <inertial>
          <pose frame=''>0.00144 -0.15943 0.00039 0 -0 0</pose>
          <mass>2.175</mass>
          <inertia>
            <ixx>0.01</ixx>
            <ixy>0</ixy>
            <ixz>0</ixz>
            <iyy>0.01</iyy>
            <iyz>-2.71051e-20</iyz>
            <izz>0.01</izz>
          </inertia>
        </inertial>
        <collision name='r_upper_leg_collision'>
          <pose frame=''>0 0 0 1.57087 -1.57079 -7.3e-05</pose>
          <geometry>
            <mesh>
              <scale>1 1 1</scale>
              <uri>model://icub/meshes/collision/icub_simple_collision_r_thigh.dae</uri>
            </mesh>
          </geometry>
          <max_contacts>10</max_contacts>
          <surface>
            <contact>
              <ode/>
            </contact>
            <bounce/>
            <friction>
              <torsional>
                <ode/>
              </torsional>
              <ode/>
            </friction>
          </surface>
        </collision>
        <visual name='r_upper_leg_visual'>
          <pose frame=''>0 0 0 1.57087 -1.57079 -7.3e-05</pose>
          <geometry>
            <mesh>
              <scale>1 1 1</scale>
              <uri>model://icub/meshes/visual/icub_r_thigh.dae</uri>
            </mesh>
          </geometry>
        </visual>
        <self_collide>0</self_collide>
        <kinematic>0</kinematic>
      </link>
      <joint name='r_hip_yaw' type='revolute'>
        <child>r_upper_leg</child>
        <parent>r_hip_3</parent>
        <axis>
          <xyz>-7e-06 4e-06 -1</xyz>
          <limit>
            <lower>-1.37881</lower>
            <upper>1.37881</upper>
            <effort>40</effort>
            <velocity>100</velocity>
          </limit>
          <dynamics>
            <damping>1</damping>
            <friction>0</friction>
            <spring_reference>0</spring_reference>
            <spring_stiffness>0</spring_stiffness>
          </dynamics>
          <use_parent_model_frame>1</use_parent_model_frame>
        </axis>
      </joint>
      <link name='r_lower_leg'>
        <pose frame=''>-2e-06 0.068101 -0.3435 1.89254 -1.57078 -0.321751</pose>
        <inertial>
          <pose frame=''>-0.1071 0.00182 -0.00211 0 -0 0</pose>
          <mass>1.264</mass>
          <inertia>
            <ixx>0.01</ixx>
            <ixy>5.42101e-20</ixy>
            <ixz>-5.42101e-20</ixz>
            <iyy>0.01</iyy>
            <iyz>8.47033e-22</iyz>
            <izz>0.01</izz>
          </inertia>
        </inertial>
        <collision name='r_lower_leg_collision'>
          <pose frame=''>0 0 -0 3.14159 -0 1.5708</pose>
          <geometry>
            <mesh>
              <scale>1 1 1</scale>
              <uri>model://icub/meshes/collision/icub_simple_collision_r_shank.dae</uri>
            </mesh>
          </geometry>
          <max_contacts>10</max_contacts>
          <surface>
            <contact>
              <ode/>
            </contact>
            <bounce/>
            <friction>
              <torsional>
                <ode/>
              </torsional>
              <ode/>
            </friction>
          </surface>
        </collision>
        <visual name='r_lower_leg_visual'>
          <pose frame=''>0 0 -0 3.14159 -0 1.5708</pose>
          <geometry>
            <mesh>
              <scale>1 1 1</scale>
              <uri>model://icub/meshes/visual/icub_r_shank.dae</uri>
            </mesh>
          </geometry>
        </visual>
        <self_collide>0</self_collide>
        <kinematic>0</kinematic>
      </link>
      <joint name='r_knee' type='revolute'>
        <child>r_lower_leg</child>
        <parent>r_upper_leg</parent>
        <axis>
          <xyz>3e-06 1 4e-06</xyz>
          <limit>
            <lower>-2.18166</lower>
            <upper>0.401426</upper>
            <effort>30</effort>
            <velocity>100</velocity>
          </limit>
          <dynamics>
            <damping>1</damping>
            <friction>0</friction>
            <spring_reference>0</spring_reference>
            <spring_stiffness>0</spring_stiffness>
          </dynamics>
          <use_parent_model_frame>1</use_parent_model_frame>
        </axis>
      </joint>
      <link name='r_ankle_1'>
        <pose frame=''>-4e-06 0.068102 -0.5565 -2.81984 -1.57078 -0.321751</pose>
        <inertial>
          <pose frame=''>-0.0054 0.00163 -0.0172 0 -0 0</pose>
          <mass>0.746</mass>
          <inertia>
            <ixx>0.01</ixx>
            <ixy>-1.69407e-21</ixy>
            <ixz>1.35525e-20</ixz>
            <iyy>0.01</iyy>
            <iyz>3.38813e-21</iyz>
            <izz>0.01</izz>
          </inertia>
        </inertial>
        <collision name='r_ankle_1_collision'>
          <pose frame=''>0 -0 -0 -1.5708 -0 0</pose>
          <geometry>
            <mesh>
              <scale>1 1 1</scale>
              <uri>model://icub/meshes/collision/icub_simple_collision_r_ankle_1.dae</uri>
            </mesh>
          </geometry>
          <max_contacts>10</max_contacts>
          <surface>
            <contact>
              <ode/>
            </contact>
            <bounce/>
            <friction>
              <torsional>
                <ode/>
              </torsional>
              <ode/>
            </friction>
          </surface>
        </collision>
        <visual name='r_ankle_1_visual'>
          <pose frame=''>0 -0 -0 -1.5708 -0 0</pose>
          <geometry>
            <mesh>
              <scale>1 1 1</scale>
              <uri>model://icub/meshes/visual/icub_r_ankle_1.dae</uri>
            </mesh>
          </geometry>
        </visual>
        <self_collide>0</self_collide>
        <kinematic>0</kinematic>
      </link>
      <joint name='r_ankle_pitch' type='revolute'>
        <child>r_ankle_1</child>
        <parent>r_lower_leg</parent>
        <axis>
          <xyz>1e-06 -1 -4e-06</xyz>
          <limit>
            <lower>-0.733038</lower>
            <upper>0.366519</upper>
            <effort>24</effort>
            <velocity>100</velocity>
          </limit>
          <dynamics>
            <damping>1</damping>
            <friction>0</friction>
            <spring_reference>0</spring_reference>
            <spring_stiffness>0</spring_stiffness>
          </dynamics>
          <use_parent_model_frame>1</use_parent_model_frame>
        </axis>
      </joint>
      <link name='r_ankle_2'>
        <pose frame=''>-4e-06 0.068102 -0.5565 3.14159 -1.4e-05 -3.14159</pose>
        <inertial>
          <pose frame=''>0 0 0.037 0 -0 0</pose>
          <mass>0.2675</mass>
          <inertia>
            <ixx>0.01</ixx>
            <ixy>0</ixy>
            <ixz>0</ixz>
            <iyy>0.01</iyy>
            <iyz>0</iyz>
            <izz>0.01</izz>
          </inertia>
        </inertial>
        <self_collide>0</self_collide>
        <kinematic>0</kinematic>
      </link>
      <joint name='r_ankle_roll' type='revolute'>
        <child>r_ankle_2</child>
        <parent>r_ankle_1</parent>
        <axis>
          <xyz>1 3e-06 -1.4e-05</xyz>
          <limit>
            <lower>-0.418879</lower>
            <upper>0.418879</upper>
            <effort>11</effort>
            <velocity>100</velocity>
          </limit>
          <dynamics>
            <damping>1</damping>
            <friction>0</friction>
            <spring_reference>0</spring_reference>
            <spring_stiffness>0</spring_stiffness>
          </dynamics>
          <use_parent_model_frame>1</use_parent_model_frame>
        </axis>
      </joint>
      <link name='r_foot'>
        <pose frame=''>-5e-06 0.068102 -0.5935 3.14159 -1.4e-05 -3.14159</pose>
        <inertial>
          <pose frame=''>0.024069 0.000614 -0.028415 0 -0 0</pose>
          <mass>0.5935</mass>
          <inertia>
            <ixx>0.01</ixx>
            <ixy>4.51893e-06</ixy>
            <ixz>0.000567784</ixz>
            <iyy>0.01</iyy>
            <iyz>6.62535e-07</iyz>
            <izz>0.01</izz>
          </inertia>
        </inertial>
        <collision name='r_foot_collision'>
          <pose frame=''>0.03 0 -0.01 0 -0 0</pose>
          <geometry>
            <box>
              <size>0.15 0.07 0.03</size>
            </box>
          </geometry>
          <max_contacts>4</max_contacts>
          <surface>
            <contact>
              <ode>
                <soft_erp>0.2</soft_erp>
                <soft_cfm>0</soft_cfm>
                <kp>1.8e+07</kp>
                <kd>100</kd>
                <max_vel>100</max_vel>
                <min_depth>0.0001</min_depth>
              </ode>
            </contact>
            <friction>
              <ode>
                <mu>1</mu>
                <mu2>1</mu2>
                <fdir1>0 0 0</fdir1>
                <slip1>0</slip1>
                <slip2>0</slip2>
              </ode>
              <torsional>
                <ode/>
              </torsional>
            </friction>
            <bounce>
              <restitution_coefficient>0</restitution_coefficient>
              <threshold>100000</threshold>
            </bounce>
          </surface>
        </collision>
        <visual name='r_foot_visual'>
          <pose frame=''>0 0 -0.037 -2.81983 1.57079 0.321763</pose>
          <geometry>
            <mesh>
              <scale>1 1 1</scale>
              <uri>model://icub/meshes/visual/icub_r_foot.dae</uri>
            </mesh>
          </geometry>
        </visual>
        <self_collide>0</self_collide>
        <kinematic>0</kinematic>
      </link>
      <joint name='r_foot_ft_sensor' type='revolute'>
        <child>r_foot</child>
        <parent>r_ankle_2</parent>
        <axis>
          <xyz>0 0 0</xyz>
          <limit>
            <lower>0</lower>
            <upper>0</upper>
            <effort>0</effort>
            <velocity>0</velocity>
          </limit>
          <dynamics>
            <spring_reference>0</spring_reference>
            <spring_stiffness>0</spring_stiffness>
          </dynamics>
          <use_parent_model_frame>1</use_parent_model_frame>
        </axis>
        <sensor name='right_foot_ft' type='force_torque'>
          <always_on>1</always_on>
          <update_rate>100</update_rate>
          <pose frame=''>0 0 0 0 -0 0</pose>
          <plugin name='right_foot_ft_plugin' filename='libgazebo_yarp_forcetorque.so'>
            <yarpConfigurationFile>model://icub/conf/FT/gazebo_icub_right_foot_ft.ini</yarpConfigurationFile>
          </plugin>
        </sensor>
      </joint>
      <link name='torso_1'>
        <pose frame=''>0 0 0 3.14159 -1.57079 -3e-06</pose>
        <inertial>
          <pose frame=''>0 0 0 0 -0 0</pose>
          <mass>0.1</mass>
          <inertia>
            <ixx>0.01</ixx>
            <ixy>-4.263e-05</ixy>
            <ixz>-3.889e-08</ixz>
            <iyy>0.01</iyy>
            <iyz>0</iyz>
            <izz>0.01</izz>
          </inertia>
        </inertial>
        <collision name='torso_1_collision'>
          <pose frame=''>0 0 0 -1.5708 0 0</pose>
          <geometry>
            <mesh>
              <scale>1 1 1</scale>
              <uri>model://icub/meshes/collision/icub_simple_collision_lap_belt_1.dae</uri>
            </mesh>
          </geometry>
          <max_contacts>10</max_contacts>
          <surface>
            <contact>
              <ode/>
            </contact>
            <bounce/>
            <friction>
              <torsional>
                <ode/>
              </torsional>
              <ode/>
            </friction>
          </surface>
        </collision>
        <visual name='torso_1_visual'>
          <pose frame=''>0 0 0 -1.5708 0 0</pose>
          <geometry>
            <mesh>
              <scale>1 1 1</scale>
              <uri>model://icub/meshes/visual/icub_lap_belt_1.dae</uri>
            </mesh>
          </geometry>
        </visual>
        <self_collide>0</self_collide>
        <kinematic>0</kinematic>
      </link>
      <joint name='torso_pitch' type='revolute'>
        <child>torso_1</child>
        <parent>root_link</parent>
        <axis>
          <xyz>-3e-06 -1 0</xyz>
          <limit>
            <lower>-0.383972</lower>
            <upper>1.46608</upper>
            <effort>36</effort>
            <velocity>100</velocity>
          </limit>
          <dynamics>
            <damping>1</damping>
            <friction>0</friction>
            <spring_reference>0</spring_reference>
            <spring_stiffness>0</spring_stiffness>
          </dynamics>
          <use_parent_model_frame>1</use_parent_model_frame>
        </axis>
      </joint>
      <link name='torso_2'>
        <pose frame=''>0 -0 0.032 -3.14159 4e-06 1.57079</pose>
        <inertial>
          <pose frame=''>0 0 0 0 -0 0</pose>
          <mass>0.1</mass>
          <inertia>
            <ixx>0.01</ixx>
            <ixy>-1.923e-06</ixy>
            <ixz>5.095e-05</ixz>
            <iyy>0.01</iyy>
            <iyz>-3.849e-07</iyz>
            <izz>0.01</izz>
          </inertia>
        </inertial>
        <self_collide>0</self_collide>
        <kinematic>0</kinematic>
      </link>
      <joint name='torso_roll' type='revolute'>
        <child>torso_2</child>
        <parent>torso_1</parent>
        <axis>
          <xyz>1 -3e-06 -7e-06</xyz>
          <limit>
            <lower>-0.680678</lower>
            <upper>0.680678</upper>
            <effort>80</effort>
            <velocity>100</velocity>
          </limit>
          <dynamics>
            <damping>1</damping>
            <friction>0</friction>
            <spring_reference>0</spring_reference>
            <spring_stiffness>0</spring_stiffness>
          </dynamics>
          <use_parent_model_frame>1</use_parent_model_frame>
        </axis>
      </joint>
      <link name='chest'>
        <pose frame=''>-0.0055 0 0.032 1.5708 -7e-06 -3.14159</pose>
        <inertial>
          <pose frame=''>0.002229 0.075 -0 0 -0 0</pose>
          <mass>4.81</mass>
          <inertia>
            <ixx>0.07472</ixx>
            <ixy>-3.6e-06</ixy>
            <ixz>-4.705e-05</ixz>
            <iyy>0.08145</iyy>
            <iyz>0.004567</iyz>
            <izz>0.01306</izz>
          </inertia>
        </inertial>
        <collision name='chest_collision'>
          <pose frame=''>-0.0055 -0 -0 -1.10717 -1.57079 2.67798</pose>
          <geometry>
            <mesh>
              <scale>1 1 1</scale>
              <uri>model://icub/meshes/collision/icub_simple_collision_chest.dae</uri>
            </mesh>
          </geometry>
          <max_contacts>10</max_contacts>
          <surface>
            <contact>
              <ode/>
            </contact>
            <bounce/>
            <friction>
              <torsional>
                <ode/>
              </torsional>
              <ode/>
            </friction>
          </surface>
        </collision>
        <visual name='chest_visual'>
          <pose frame=''>-0.0055 -0 -0 -1.10717 -1.57079 2.67798</pose>
          <geometry>
            <mesh>
              <scale>1 1 1</scale>
              <uri>model://icub/meshes/visual/icub_chest.dae</uri>
            </mesh>
          </geometry>
        </visual>
        <self_collide>0</self_collide>
        <kinematic>0</kinematic>
      </link>
      <joint name='torso_yaw' type='revolute'>
        <child>chest</child>
        <parent>torso_2</parent>
        <axis>
          <xyz>-7e-06 0 -1</xyz>
          <limit>
            <lower>-1.02974</lower>
            <upper>1.02974</upper>
            <effort>80</effort>
            <velocity>100</velocity>
          </limit>
          <dynamics>
            <damping>1</damping>
            <friction>0</friction>
            <spring_reference>0</spring_reference>
            <spring_stiffness>0</spring_stiffness>
          </dynamics>
          <use_parent_model_frame>1</use_parent_model_frame>
        </axis>
      </joint>
      <link name='l_shoulder_1'>
        <pose frame=''>-0.010749 -0.11026 0.1753 -0.261794 -1.57079 -1e-06</pose>
        <inertial>
          <pose frame=''>-5e-06 0.0187 -0.00119 0 -0 0</pose>
          <mass>0.189</mass>
          <inertia>
            <ixx>0.01</ixx>
            <ixy>9e-09</ixy>
            <ixz>0</ixz>
            <iyy>0.01</iyy>
            <iyz>-1.7e-08</iyz>
            <izz>0.01</izz>
          </inertia>
        </inertial>
        <collision name='l_shoulder_1_collision'>
          <pose frame=''>0 0.109285 -0.005211 -0.301063 1.57079 -1.87186</pose>
          <geometry>
            <mesh>
              <scale>1 1 1</scale>
              <uri>model://icub/meshes/collision/icub_simple_collision_l_shoulder_1.dae</uri>
            </mesh>
          </geometry>
          <max_contacts>10</max_contacts>
          <surface>
            <contact>
              <ode/>
            </contact>
            <bounce/>
            <friction>
              <torsional>
                <ode/>
              </torsional>
              <ode/>
            </friction>
          </surface>
        </collision>
        <visual name='l_shoulder_1_visual'>
          <pose frame=''>0 0.109285 -0.005211 -0.301063 1.57079 -1.87186</pose>
          <geometry>
            <mesh>
              <scale>1 1 1</scale>
              <uri>model://icub/meshes/visual/icub_l_shoulder_1.dae</uri>
            </mesh>
          </geometry>
        </visual>
        <self_collide>0</self_collide>
        <kinematic>0</kinematic>
      </link>
      <joint name='l_shoulder_pitch' type='revolute'>
        <child>l_shoulder_1</child>
        <parent>chest</parent>
        <axis>
          <xyz>-0.258815 -0.965927 3e-06</xyz>
          <limit>
            <lower>-1.65806</lower>
            <upper>0.0872665</upper>
            <effort>84</effort>
            <velocity>100</velocity>
          </limit>
          <dynamics>
            <damping>1</damping>
            <friction>0</friction>
            <spring_reference>0</spring_reference>
            <spring_stiffness>0</spring_stiffness>
          </dynamics>
          <use_parent_model_frame>1</use_parent_model_frame>
        </axis>
      </joint>
      <link name='l_shoulder_2'>
        <pose frame=''>-0.010749 -0.11026 0.1753 3.14159 1e-06 -1.83259</pose>
        <inertial>
          <pose frame=''>9.4e-05 -0.00627 0.0166 0 -0 0</pose>
          <mass>0.179</mass>
          <inertia>
            <ixx>0.01</ixx>
            <ixy>4.66e-07</ixy>
            <ixz>3.65e-07</ixz>
            <iyy>0.01</iyy>
            <iyz>-2.0524e-05</iyz>
            <izz>0.01</izz>
          </inertia>
        </inertial>
        <collision name='l_shoulder_2_collision'>
          <pose frame=''>-0.001545 -0.005211 -0 -2.14033 1.57079 -0.569533</pose>
          <geometry>
            <mesh>
              <scale>1 1 1</scale>
              <uri>model://icub/meshes/collision/icub_simple_collision_l_shoulder_2.dae</uri>
            </mesh>
          </geometry>
          <max_contacts>10</max_contacts>
          <surface>
            <contact>
              <ode/>
            </contact>
            <bounce/>
            <friction>
              <torsional>
                <ode/>
              </torsional>
              <ode/>
            </friction>
          </surface>
        </collision>
        <visual name='l_shoulder_2_visual'>
          <pose frame=''>-0.001545 -0.005211 -0 -2.14033 1.57079 -0.569533</pose>
          <geometry>
            <mesh>
              <scale>1 1 1</scale>
              <uri>model://icub/meshes/visual/icub_l_shoulder_2.dae</uri>
            </mesh>
          </geometry>
        </visual>
        <self_collide>0</self_collide>
        <kinematic>0</kinematic>
      </link>
      <joint name='l_shoulder_roll' type='revolute'>
        <child>l_shoulder_2</child>
        <parent>l_shoulder_1</parent>
        <axis>
          <xyz>-0.965927 0.258815 7e-06</xyz>
          <limit>
            <lower>0</lower>
            <upper>2.80649</upper>
            <effort>84</effort>
            <velocity>100</velocity>
          </limit>
          <dynamics>
            <damping>1</damping>
            <friction>0</friction>
            <spring_reference>0</spring_reference>
            <spring_stiffness>0</spring_stiffness>
          </dynamics>
          <use_parent_model_frame>1</use_parent_model_frame>
        </axis>
      </joint>
      <link name='l_shoulder_3'>
        <pose frame=''>-0.010749 -0.11026 0.1753 3.14159 -7e-06 -3.14159</pose>
        <inertial>
          <pose frame=''>0.005594 9.8e-05 0.050135 0 -0 0</pose>
          <mass>0.156157</mass>
          <inertia>
            <ixx>0.01</ixx>
            <ixy>-5.662e-08</ixy>
            <ixz>-4.3618e-06</ixz>
            <iyy>0.01</iyy>
            <iyz>-7.42844e-07</iyz>
            <izz>0.01</izz>
          </inertia>
        </inertial>
        <self_collide>0</self_collide>
        <kinematic>0</kinematic>
      </link>
      <joint name='l_shoulder_yaw' type='revolute'>
        <child>l_shoulder_3</child>
        <parent>l_shoulder_2</parent>
        <axis>
          <xyz>-7e-06 3e-06 -1</xyz>
          <limit>
            <lower>-0.645772</lower>
            <upper>1.74533</upper>
            <effort>34</effort>
            <velocity>100</velocity>
          </limit>
          <dynamics>
            <damping>1</damping>
            <friction>0</friction>
            <spring_reference>0</spring_reference>
            <spring_stiffness>0</spring_stiffness>
          </dynamics>
          <use_parent_model_frame>1</use_parent_model_frame>
        </axis>
      </joint>
      <link name='l_upper_arm'>
        <pose frame=''>-0.025749 -0.11026 0.1073 3.14159 -7e-06 -3.14159</pose>
        <inertial>
          <pose frame=''>-0.000156 -9.9e-05 0.0298 0 -0 0</pose>
          <mass>0.727843</mass>
          <inertia>
            <ixx>0.01</ixx>
            <ixy>-1.08e-06</ixy>
            <ixz>-2.29e-06</ixz>
            <iyy>0.01</iyy>
            <iyz>3.57e-06</iyz>
            <izz>0.01</izz>
          </inertia>
        </inertial>
        <collision name='l_upper_arm_collision'>
          <pose frame=''>-0.020433 0.000144 -0.068 0 0 -1.309</pose>
          <geometry>
            <mesh>
              <scale>1 1 1</scale>
              <uri>model://icub/meshes/collision/icub_simple_collision_l_arm.dae</uri>
            </mesh>
          </geometry>
          <max_contacts>10</max_contacts>
          <surface>
            <contact>
              <ode/>
            </contact>
            <bounce/>
            <friction>
              <torsional>
                <ode/>
              </torsional>
              <ode/>
            </friction>
          </surface>
        </collision>
        <visual name='l_upper_arm_visual'>
          <pose frame=''>-0.020433 0.000144 -0.068 0 0 -1.309</pose>
          <geometry>
            <mesh>
              <scale>1 1 1</scale>
              <uri>model://icub/meshes/visual/icub_l_arm.dae</uri>
            </mesh>
          </geometry>
        </visual>
        <self_collide>0</self_collide>
        <kinematic>0</kinematic>
      </link>
      <joint name='l_arm_ft_sensor' type='revolute'>
        <child>l_upper_arm</child>
        <parent>l_shoulder_3</parent>
        <axis>
          <xyz>0 0 0</xyz>
          <limit>
            <lower>0</lower>
            <upper>0</upper>
            <effort>0</effort>
            <velocity>0</velocity>
          </limit>
          <dynamics>
            <spring_reference>0</spring_reference>
            <spring_stiffness>0</spring_stiffness>
          </dynamics>
          <use_parent_model_frame>1</use_parent_model_frame>
        </axis>
        <sensor name='left_arm_ft' type='force_torque'>
          <always_on>1</always_on>
          <update_rate>100</update_rate>
          <pose frame=''>0 0 0 0 -0 0</pose>
          <plugin name='left_arm_ft_plugin' filename='libgazebo_yarp_forcetorque.so'>
            <yarpConfigurationFile>model://icub/conf/FT/gazebo_icub_left_arm_ft.ini</yarpConfigurationFile>
          </plugin>
        </sensor>
      </joint>
      <link name='l_elbow_1'>
        <pose frame=''>-0.02575 -0.11026 0.02302 3.14159 -7e-06 -3.14159</pose>
        <inertial>
          <pose frame=''>-0.0013 0.00371 -0.00105 0 -0 0</pose>
          <mass>0.1</mass>
          <inertia>
            <ixx>0.01</ixx>
            <ixy>-5.15e-07</ixy>
            <ixz>-4.08e-07</ixz>
            <iyy>0.01</iyy>
            <iyz>-3.71e-07</iyz>
            <izz>0.01</izz>
          </inertia>
        </inertial>
        <self_collide>0</self_collide>
        <kinematic>0</kinematic>
      </link>
      <joint name='l_elbow' type='revolute'>
        <child>l_elbow_1</child>
        <parent>l_upper_arm</parent>
        <axis>
          <xyz>-1e-06 1 3e-06</xyz>
          <limit>
            <lower>0.0959931</lower>
            <upper>1.85005</upper>
            <effort>20</effort>
            <velocity>100</velocity>
          </limit>
          <dynamics>
            <damping>1</damping>
            <friction>0</friction>
            <spring_reference>0</spring_reference>
            <spring_stiffness>0</spring_stiffness>
          </dynamics>
          <use_parent_model_frame>1</use_parent_model_frame>
        </axis>
      </joint>
      <link name='l_forearm'>
        <pose frame=''>-0.01075 -0.11026 0.02302 -1.5708 3e-06 -1.57079</pose>
        <inertial>
          <pose frame=''>0.000347 0.066 0.00476 0 -0 0</pose>
          <mass>0.525</mass>
          <inertia>
            <ixx>0.01</ixx>
            <ixy>4.337e-06</ixy>
            <ixz>2.39e-07</ixz>
            <iyy>0.01</iyy>
            <iyz>1.9381e-05</iyz>
            <izz>0.01</izz>
          </inertia>
        </inertial>
        <collision name='l_forearm_collision'>
          <pose frame=''>-0.000144 -0 0.020433 -2.66395 1.57079 -1.09315</pose>
          <geometry>
            <mesh>
              <scale>1 1 1</scale>
              <uri>model://icub/meshes/collision/icub_simple_collision_l_forearm.dae</uri>
            </mesh>
          </geometry>
          <max_contacts>10</max_contacts>
          <surface>
            <contact>
              <ode/>
            </contact>
            <bounce/>
            <friction>
              <torsional>
                <ode/>
              </torsional>
              <ode/>
            </friction>
          </surface>
        </collision>
        <visual name='l_forearm_visual'>
          <pose frame=''>-0.000144 -0 0.020433 -2.66395 1.57079 -1.09315</pose>
          <geometry>
            <mesh>
              <scale>1 1 1</scale>
              <uri>model://icub/meshes/visual/icub_l_forearm.dae</uri>
            </mesh>
          </geometry>
        </visual>
        <self_collide>0</self_collide>
        <kinematic>0</kinematic>
      </link>
      <joint name='l_wrist_prosup' type='revolute'>
        <child>l_forearm</child>
        <parent>l_elbow_1</parent>
        <axis>
          <xyz>-3e-06 3e-06 -1</xyz>
          <limit>
            <lower>-0.872665</lower>
            <upper>0.872665</upper>
            <effort>0.45</effort>
            <velocity>100</velocity>
          </limit>
          <dynamics>
            <damping>1</damping>
            <friction>0</friction>
            <spring_reference>0</spring_reference>
            <spring_stiffness>0</spring_stiffness>
          </dynamics>
          <use_parent_model_frame>1</use_parent_model_frame>
        </axis>
      </joint>
      <link name='l_wrist_1'>
        <pose frame=''>-0.01075 -0.110259 -0.11428 -2.7153 1.57079 1.99709</pose>
        <inertial>
          <pose frame=''>0 0 0 0 -0 0</pose>
          <mass>0.1</mass>
          <inertia>
            <ixx>0.01</ixx>
            <ixy>0</ixy>
            <ixz>0</ixz>
            <iyy>0.01</iyy>
            <iyz>0</iyz>
            <izz>0.01</izz>
          </inertia>
        </inertial>
        <self_collide>0</self_collide>
        <kinematic>0</kinematic>
      </link>
      <joint name='l_wrist_pitch' type='revolute'>
        <child>l_wrist_1</child>
        <parent>l_forearm</parent>
        <axis>
          <xyz>1 1e-06 -3e-06</xyz>
          <limit>
            <lower>-1.13446</lower>
            <upper>0.174533</upper>
            <effort>0.65</effort>
            <velocity>100</velocity>
          </limit>
          <dynamics>
            <damping>1</damping>
            <friction>0</friction>
            <spring_reference>0</spring_reference>
            <spring_stiffness>0</spring_stiffness>
          </dynamics>
          <use_parent_model_frame>1</use_parent_model_frame>
        </axis>
      </joint>
      <link name='l_hand'>
        <pose frame=''>-0.01075 -0.110259 -0.11428 -2.7153 1.57079 1.99709</pose>
        <inertial>
          <pose frame=''>0.07023 -0.00805 -0.007 0 -0 0</pose>
          <mass>0.213</mass>
          <inertia>
            <ixx>0.01</ixx>
            <ixy>1.278e-05</ixy>
            <ixz>4.823e-06</ixz>
            <iyy>0.01</iyy>
            <iyz>-1.8188e-05</iyz>
            <izz>0.01</izz>
          </inertia>
        </inertial>
        <collision name='l_hand_collision'>
          <pose frame=''>-0 0.020433 -0.000144 0 -0 0</pose>
          <geometry>
            <mesh>
              <scale>1 1 1</scale>
              <uri>model://icub/meshes/collision/icub_simple_collision_l_hand.dae</uri>
            </mesh>
          </geometry>
          <max_contacts>10</max_contacts>
          <surface>
            <contact>
              <ode/>
            </contact>
            <bounce/>
            <friction>
              <torsional>
                <ode/>
              </torsional>
              <ode/>
            </friction>
          </surface>
        </collision>
        <visual name='l_hand_visual'>
          <pose frame=''>-0 0.020433 -0.000144 0 -0 0</pose>
          <geometry>
            <mesh>
              <scale>1 1 1</scale>
              <uri>model://icub/meshes/visual/icub_l_hand.dae</uri>
            </mesh>
          </geometry>
        </visual>
        <self_collide>0</self_collide>
        <kinematic>0</kinematic>
      </link>
      <joint name='l_wrist_yaw' type='revolute'>
        <child>l_hand</child>
        <parent>l_wrist_1</parent>
        <axis>
          <xyz>1e-06 -1 -6e-06</xyz>
          <limit>
            <lower>-0.436332</lower>
            <upper>0.436332</upper>
            <effort>0.65</effort>
            <velocity>100</velocity>
          </limit>
          <dynamics>
            <damping>1</damping>
            <friction>0</friction>
            <spring_reference>0</spring_reference>
            <spring_stiffness>0</spring_stiffness>
          </dynamics>
          <use_parent_model_frame>1</use_parent_model_frame>
        </axis>
      </joint>
      <link name='neck_1'>
        <pose frame=''>-0.007808 0 0.2253 6e-06 -1.57079 -1e-06</pose>
        <inertial>
          <pose frame=''>0 0 0 0 -0 0</pose>
          <mass>0.1</mass>
          <inertia>
            <ixx>0.01</ixx>
            <ixy>0</ixy>
            <ixz>0</ixz>
            <iyy>0.01</iyy>
            <iyz>0</iyz>
            <izz>0.01</izz>
          </inertia>
        </inertial>
        <collision name='neck_1_collision'>
          <pose frame=''>-0 0 -0.0055 3.14159 -1.57079 1.5708</pose>
          <geometry>
            <mesh>
              <scale>1 1 1</scale>
              <uri>model://icub/meshes/collision/icub_simple_collision_neck_1.dae</uri>
            </mesh>
          </geometry>
          <max_contacts>10</max_contacts>
          <surface>
            <contact>
              <ode/>
            </contact>
            <bounce/>
            <friction>
              <torsional>
                <ode/>
              </torsional>
              <ode/>
            </friction>
          </surface>
        </collision>
        <visual name='neck_1_visual'>
          <pose frame=''>-0 0 -0.0055 3.14159 -1.57079 1.5708</pose>
          <geometry>
            <mesh>
              <scale>1 1 1</scale>
              <uri>model://icub/meshes/visual/icub_neck_1.dae</uri>
            </mesh>
          </geometry>
        </visual>
        <self_collide>0</self_collide>
        <kinematic>0</kinematic>
      </link>
      <joint name='neck_pitch' type='revolute'>
        <child>neck_1</child>
        <parent>chest</parent>
        <axis>
          <xyz>-5e-06 1 0</xyz>
          <limit>
            <lower>-0.523599</lower>
            <upper>0.383972</upper>
            <effort>20</effort>
            <velocity>100</velocity>
          </limit>
          <dynamics>
            <damping>1</damping>
            <friction>0</friction>
            <spring_reference>0</spring_reference>
            <spring_stiffness>0</spring_stiffness>
          </dynamics>
          <use_parent_model_frame>1</use_parent_model_frame>
        </axis>
        <physics>
          <ode>
            <implicit_spring_damper>1</implicit_spring_damper>
            <cfm_damping>1</cfm_damping>
            <limit>
              <cfm>0</cfm>
              <erp>0.2</erp>
            </limit>
          </ode>
        </physics>
      </joint>
      <link name='neck_2'>
        <pose frame=''>-0.007808 0 0.2348 -1.5e-05 4e-06 -1.57079</pose>
        <inertial>
          <pose frame=''>0 0 0 0 -0 0</pose>
          <mass>0.1</mass>
          <inertia>
            <ixx>0.01</ixx>
            <ixy>0</ixy>
            <ixz>0</ixz>
            <iyy>0.01</iyy>
            <iyz>0</iyz>
            <izz>0.01</izz>
          </inertia>
        </inertial>
        <collision name='neck_2_collision'>
          <pose frame=''>-0 0.0055 0.0235 -3.14157 -1.57079 -1.57082</pose>
          <geometry>
            <mesh>
              <scale>1 1 1</scale>
              <uri>model://icub/meshes/collision/icub_simple_collision_neck_2.dae</uri>
            </mesh>
          </geometry>
          <max_contacts>10</max_contacts>
          <surface>
            <contact>
              <ode/>
            </contact>
            <bounce/>
            <friction>
              <torsional>
                <ode/>
              </torsional>
              <ode/>
            </friction>
          </surface>
        </collision>
        <visual name='neck_2_visual'>
          <pose frame=''>-0 0.0055 0.0235 -3.14157 -1.57079 -1.57082</pose>
          <geometry>
            <mesh>
              <scale>1 1 1</scale>
              <uri>model://icub/meshes/visual/icub_neck_2.dae</uri>
            </mesh>
          </geometry>
        </visual>
        <self_collide>0</self_collide>
        <kinematic>0</kinematic>
      </link>
      <joint name='neck_roll' type='revolute'>
        <child>neck_2</child>
        <parent>neck_1</parent>
        <axis>
          <xyz>-1 -5e-06 1.5e-05</xyz>
          <limit>
            <lower>-0.349066</lower>
            <upper>0.349066</upper>
            <effort>20</effort>
            <velocity>100</velocity>
          </limit>
          <dynamics>
            <damping>1</damping>
            <friction>0</friction>
            <spring_reference>0</spring_reference>
            <spring_stiffness>0</spring_stiffness>
          </dynamics>
          <use_parent_model_frame>1</use_parent_model_frame>
        </axis>
        <physics>
          <ode>
            <implicit_spring_damper>1</implicit_spring_damper>
            <cfm_damping>1</cfm_damping>
            <limit>
              <cfm>0</cfm>
              <erp>0.2</erp>
            </limit>
          </ode>
        </physics>
      </joint>
      <link name='head'>
        <pose frame=''>-0.007808 0 0.2348 -1.5708 1.5e-05 8e-06</pose>
        <inertial>
          <pose frame=''>0.0185 -0.1108 0 0 -0 0</pose>
          <mass>3</mass>
          <inertia>
            <ixx>0.01</ixx>
            <ixy>0</ixy>
            <ixz>0</ixz>
            <iyy>0.01</iyy>
            <iyz>0</iyz>
            <izz>0.01</izz>
          </inertia>
        </inertial>
        <collision name='head_collision'>
          <pose frame=''>0.0045 -0.0235 0 -1.32582 1.57079 -2.89662</pose>
          <geometry>
            <mesh>
              <scale>1 1 1</scale>
              <uri>model://icub/meshes/collision/icub_simple_collision_head.dae</uri>
            </mesh>
          </geometry>
          <max_contacts>10</max_contacts>
          <surface>
            <contact>
              <ode/>
            </contact>
            <bounce/>
            <friction>
              <torsional>
                <ode/>
              </torsional>
              <ode/>
            </friction>
          </surface>
        </collision>
        <visual name='head_visual'>
          <pose frame=''>0.0045 -0.0235 0 -2.89662 1.57079 -2.89662</pose>
          <geometry>
            <mesh>
              <scale>1 1 1</scale>
              <uri>model://icub/meshes/visual/icub_head_without_eyes.dae</uri>
            </mesh>
          </geometry>
        </visual>
        <sensor name='imu_sensor' type='imu'>
          <always_on>1</always_on>
          <update_rate>100</update_rate>
          <visualize>1</visualize>
          <imu>
            <angular_velocity/>
            <linear_acceleration/>
          </imu>
          <plugin name='iCub_yarp_gazebo_plugin_IMU' filename='libgazebo_yarp_imu.so'>
            <yarpConfigurationFile>model://icub/conf/gazebo_icub_inertial.ini</yarpConfigurationFile>
          </plugin>
          <pose frame=''>0.0185 -0.1108 0.0066 1.5708 -0 0</pose>
        </sensor>
        <self_collide>0</self_collide>
        <kinematic>0</kinematic>
      </link>
      <joint name='neck_yaw' type='revolute'>
        <child>head</child>
        <parent>neck_2</parent>
        <axis>
          <xyz>1.5e-05 0 1</xyz>
          <limit>
            <lower>-0.767945</lower>
            <upper>0.767945</upper>
            <effort>20</effort>
            <velocity>100</velocity>
          </limit>
          <dynamics>
            <damping>1</damping>
            <friction>0</friction>
            <spring_reference>0</spring_reference>
            <spring_stiffness>0</spring_stiffness>
          </dynamics>
          <use_parent_model_frame>1</use_parent_model_frame>
        </axis>
        <physics>
          <ode>
            <implicit_spring_damper>1</implicit_spring_damper>
            <cfm_damping>1</cfm_damping>
            <limit>
              <cfm>0</cfm>
              <erp>0.2</erp>
            </limit>
          </ode>
        </physics>
      </joint>
      <link name='eyes_tilt_link'>
        <pose frame=''>-0.06281 0 0.3408 1.57079 -0 0</pose>
        <inertial>
          <pose frame=''>0 0 0 0 -0 0</pose>
          <mass>0.01</mass>
          <inertia>
            <ixx>0.001</ixx>
            <ixy>0</ixy>
            <ixz>0</ixz>
            <iyy>0.001</iyy>
            <iyz>0</iyz>
            <izz>0.001</izz>
          </inertia>
        </inertial>
        <self_collide>0</self_collide>
        <kinematic>0</kinematic>
      </link>
      <link name='left_eye_link'>
        <pose frame=''>-0.06281 -0.034 0.3408 -3.14159 0 0</pose>
        <inertial>
          <pose frame=''>0 0 0 0 -0 0</pose>
          <mass>0.01</mass>
          <inertia>
            <ixx>0.001</ixx>
            <ixy>0</ixy>
            <ixz>0</ixz>
            <iyy>0.001</iyy>
            <iyz>0</iyz>
            <izz>0.001</izz>
          </inertia>
        </inertial>
        <visual name='left_eye_visual'>
          <pose frame=''>0.055 0.033 -0.14 0 -0 0</pose>
          <geometry>
            <mesh>
              <scale>1 1 1</scale>
              <uri>model://icub/meshes/visual/icub_eye.dae</uri>
            </mesh>
          </geometry>
        </visual>
        <self_collide>0</self_collide>
        <kinematic>0</kinematic>
      </link>
      <link name='right_eye_link'>
        <pose frame=''>-0.06281 0.034 0.3408 -3.14159 0 0</pose>
        <inertial>
          <pose frame=''>0 0 0 0 -0 0</pose>
          <mass>0.01</mass>
          <inertia>
            <ixx>0.001</ixx>
            <ixy>0</ixy>
            <ixz>0</ixz>
            <iyy>0.001</iyy>
            <iyz>0</iyz>
            <izz>0.001</izz>
          </inertia>
        </inertial>
        <visual name='right_eye_visual'>
          <pose frame=''>0.055 0.033 -0.14 0 -0 0</pose>
          <geometry>
            <mesh>
              <scale>1 1 1</scale>
              <uri>model://icub/meshes/visual/icub_eye.dae</uri>
            </mesh>
          </geometry>
        </visual>
        <self_collide>0</self_collide>
        <kinematic>0</kinematic>
      </link>
      <joint name='eyes_tilt' type='revolute'>
        <child>eyes_tilt_link</child>
        <parent>head</parent>
        <axis>
          <xyz>0 1 0</xyz>
          <limit>
            <lower>-1.5708</lower>
            <upper>1.5708</upper>
            <effort>84</effort>
            <velocity>100</velocity>
          </limit>
          <dynamics>
            <damping>1</damping>
            <friction>0</friction>
            <spring_reference>0</spring_reference>
            <spring_stiffness>0</spring_stiffness>
          </dynamics>
          <use_parent_model_frame>1</use_parent_model_frame>
        </axis>
        <physics>
          <ode>
            <implicit_spring_damper>1</implicit_spring_damper>
            <cfm_damping>1</cfm_damping>
            <limit>
              <cfm>0</cfm>
              <erp>0.2</erp>
            </limit>
          </ode>
        </physics>
      </joint>
      <joint name='left_eye' type='revolute'>
        <child>left_eye_link</child>
        <parent>eyes_tilt_link</parent>
        <axis>
          <xyz>0 0 1</xyz>
          <limit>
            <lower>-1.5708</lower>
            <upper>1.5708</upper>
            <effort>84</effort>
            <velocity>100</velocity>
          </limit>
          <dynamics>
            <damping>1</damping>
            <friction>0</friction>
            <spring_reference>0</spring_reference>
            <spring_stiffness>0</spring_stiffness>
          </dynamics>
          <use_parent_model_frame>1</use_parent_model_frame>
        </axis>
        <physics>
          <ode>
            <implicit_spring_damper>1</implicit_spring_damper>
            <cfm_damping>1</cfm_damping>
            <limit>
              <cfm>0</cfm>
              <erp>0.2</erp>
            </limit>
          </ode>
        </physics>
      </joint>
      <joint name='right_eye' type='revolute'>
        <child>right_eye_link</child>
        <parent>eyes_tilt_link</parent>
        <axis>
          <xyz>0 0 1</xyz>
          <limit>
            <lower>-1.5708</lower>
            <upper>1.5708</upper>
            <effort>84</effort>
            <velocity>100</velocity>
          </limit>
          <dynamics>
            <damping>1</damping>
            <friction>0</friction>
            <spring_reference>0</spring_reference>
            <spring_stiffness>0</spring_stiffness>
          </dynamics>
          <use_parent_model_frame>1</use_parent_model_frame>
        </axis>
        <physics>
          <ode>
            <implicit_spring_damper>1</implicit_spring_damper>
            <cfm_damping>1</cfm_damping>
            <limit>
              <cfm>0</cfm>
              <erp>0.2</erp>
            </limit>
          </ode>
        </physics>
      </joint>
      <link name='r_shoulder_1'>
        <pose frame=''>-0.010749 0.11026 0.1753 -2.87979 -1.57079 -1e-06</pose>
        <inertial>
          <pose frame=''>5e-06 0.0187 0.00119 0 -0 0</pose>
          <mass>0.189</mass>
          <inertia>
            <ixx>0.01</ixx>
            <ixy>2.1e-08</ixy>
            <ixz>-1e-09</ixz>
            <iyy>0.01</iyy>
            <iyz>4.22e-06</iyz>
            <izz>0.01</izz>
          </inertia>
        </inertial>
        <collision name='r_shoulder_1_collision'>
          <pose frame=''>-0 0.109285 0.005211 3.06003 1.57079 -1.65235</pose>
          <geometry>
            <mesh>
              <scale>1 1 1</scale>
              <uri>model://icub/meshes/collision/icub_simple_collision_r_shoulder_1.dae</uri>
            </mesh>
          </geometry>
          <max_contacts>10</max_contacts>
          <surface>
            <contact>
              <ode/>
            </contact>
            <bounce/>
            <friction>
              <torsional>
                <ode/>
              </torsional>
              <ode/>
            </friction>
          </surface>
        </collision>
        <visual name='r_shoulder_1_visual'>
          <pose frame=''>-0 0.109285 0.005211 3.06003 1.57079 -1.65235</pose>
          <geometry>
            <mesh>
              <scale>1 1 1</scale>
              <uri>model://icub/meshes/visual/icub_r_shoulder_1.dae</uri>
            </mesh>
          </geometry>
        </visual>
        <self_collide>0</self_collide>
        <kinematic>0</kinematic>
      </link>
      <joint name='r_shoulder_pitch' type='revolute'>
        <child>r_shoulder_1</child>
        <parent>chest</parent>
        <axis>
          <xyz>0.258817 -0.965926 -3e-06</xyz>
          <limit>
            <lower>-1.65806</lower>
            <upper>0.0872665</upper>
            <effort>84</effort>
            <velocity>100</velocity>
          </limit>
          <dynamics>
            <damping>1</damping>
            <friction>0</friction>
            <spring_reference>0</spring_reference>
            <spring_stiffness>0</spring_stiffness>
          </dynamics>
          <use_parent_model_frame>1</use_parent_model_frame>
        </axis>
      </joint>
      <link name='r_shoulder_2'>
        <pose frame=''>-0.010749 0.11026 0.1753 7e-06 1e-06 1.83259</pose>
        <inertial>
          <pose frame=''>-9.4e-05 -0.00627 -0.0166 0 -0 0</pose>
          <mass>0.179</mass>
          <inertia>
            <ixx>0.01</ixx>
            <ixy>-4.53e-07</ixy>
            <ixz>2.03e-07</ixz>
            <iyy>0.01</iyy>
            <iyz>2.07e-05</iyz>
            <izz>0.01</izz>
          </inertia>
        </inertial>
        <collision name='r_shoulder_2_collision'>
          <pose frame=''>-0.001545 -0.005211 -0 -1.00125 -1.57079 2.57205</pose>
          <geometry>
            <mesh>
              <scale>1 1 1</scale>
              <uri>model://icub/meshes/collision/icub_simple_collision_r_shoulder_2.dae</uri>
            </mesh>
          </geometry>
          <max_contacts>10</max_contacts>
          <surface>
            <contact>
              <ode/>
            </contact>
            <bounce/>
            <friction>
              <torsional>
                <ode/>
              </torsional>
              <ode/>
            </friction>
          </surface>
        </collision>
        <visual name='r_shoulder_2_visual'>
          <pose frame=''>-0.001545 -0.005211 -0 -1.00125 -1.57079 2.57205</pose>
          <geometry>
            <mesh>
              <scale>1 1 1</scale>
              <uri>model://icub/meshes/visual/icub_r_shoulder_2.dae</uri>
            </mesh>
          </geometry>
        </visual>
        <self_collide>0</self_collide>
        <kinematic>0</kinematic>
      </link>
      <joint name='r_shoulder_roll' type='revolute'>
        <child>r_shoulder_2</child>
        <parent>r_shoulder_1</parent>
        <axis>
          <xyz>0.965926 0.258817 -7e-06</xyz>
          <limit>
            <lower>0</lower>
            <upper>2.80649</upper>
            <effort>84</effort>
            <velocity>100</velocity>
          </limit>
          <dynamics>
            <damping>1</damping>
            <friction>0</friction>
            <spring_reference>0</spring_reference>
            <spring_stiffness>0</spring_stiffness>
          </dynamics>
          <use_parent_model_frame>1</use_parent_model_frame>
        </axis>
      </joint>
      <link name='r_shoulder_3'>
        <pose frame=''>-0.010749 0.11026 0.1753 3.14159 -7e-06 -3.14159</pose>
        <inertial>
          <pose frame=''>0.005539 -2.5e-05 0.04939 0 -0 0</pose>
          <mass>0.155</mass>
          <inertia>
            <ixx>0.01</ixx>
            <ixy>3.56977e-07</ixy>
            <ixz>-3.95372e-06</ixz>
            <iyy>0.01</iyy>
            <iyz>-6.5128e-06</iyz>
            <izz>0.01</izz>
          </inertia>
        </inertial>
        <self_collide>0</self_collide>
        <kinematic>0</kinematic>
      </link>
      <joint name='r_shoulder_yaw' type='revolute'>
        <child>r_shoulder_3</child>
        <parent>r_shoulder_2</parent>
        <axis>
          <xyz>7e-06 0 1</xyz>
          <limit>
            <lower>-0.645772</lower>
            <upper>1.74533</upper>
            <effort>34</effort>
            <velocity>100</velocity>
          </limit>
          <dynamics>
            <damping>1</damping>
            <friction>0</friction>
            <spring_reference>0</spring_reference>
            <spring_stiffness>0</spring_stiffness>
          </dynamics>
          <use_parent_model_frame>1</use_parent_model_frame>
        </axis>
      </joint>
      <link name='r_upper_arm'>
        <pose frame=''>-0.025749 0.11026 0.1073 3.14159 -7e-06 -3.14159</pose>
        <inertial>
          <pose frame=''>-0.000159 8.3e-05 0.029883 0 -0 0</pose>
          <mass>0.729</mass>
          <inertia>
            <ixx>0.01</ixx>
            <ixy>-1.08e-06</ixy>
            <ixz>-2.29e-06</ixz>
            <iyy>0.01</iyy>
            <iyz>3.57e-06</iyz>
            <izz>0.01</izz>
          </inertia>
        </inertial>
        <collision name='r_upper_arm_collision'>
          <pose frame=''>-0.020433 -0.000144 -0.068 -3.14159 -0 1.309</pose>
          <geometry>
            <mesh>
              <scale>1 1 1</scale>
              <uri>model://icub/meshes/collision/icub_simple_collision_r_arm.dae</uri>
            </mesh>
          </geometry>
          <max_contacts>10</max_contacts>
          <surface>
            <contact>
              <ode/>
            </contact>
            <bounce/>
            <friction>
              <torsional>
                <ode/>
              </torsional>
              <ode/>
            </friction>
          </surface>
        </collision>
        <visual name='r_upper_arm_visual'>
          <pose frame=''>-0.020433 -0.000144 -0.068 -3.14159 -0 1.309</pose>
          <geometry>
            <mesh>
              <scale>1 1 1</scale>
              <uri>model://icub/meshes/visual/icub_r_arm.dae</uri>
            </mesh>
          </geometry>
        </visual>
        <self_collide>0</self_collide>
        <kinematic>0</kinematic>
      </link>
      <joint name='r_arm_ft_sensor' type='revolute'>
        <child>r_upper_arm</child>
        <parent>r_shoulder_3</parent>
        <axis>
          <xyz>0 0 0</xyz>
          <limit>
            <lower>0</lower>
            <upper>0</upper>
            <effort>0</effort>
            <velocity>0</velocity>
          </limit>
          <dynamics>
            <spring_reference>0</spring_reference>
            <spring_stiffness>0</spring_stiffness>
          </dynamics>
          <use_parent_model_frame>1</use_parent_model_frame>
        </axis>
        <sensor name='right_arm_ft' type='force_torque'>
          <always_on>1</always_on>
          <update_rate>100</update_rate>
          <pose frame=''>0 0 0 0 -0 0</pose>
          <plugin name='right_arm_ft_plugin' filename='libgazebo_yarp_forcetorque.so'>
            <yarpConfigurationFile>model://icub/conf/FT/gazebo_icub_right_arm_ft.ini</yarpConfigurationFile>
          </plugin>
        </sensor>
      </joint>
      <link name='r_elbow_1'>
        <pose frame=''>-0.02575 0.11026 0.02302 -3e-06 7e-06 4e-06</pose>
        <inertial>
          <pose frame=''>0.0013 -0.00371 0.00105 0 -0 0</pose>
          <mass>0.1</mass>
          <inertia>
            <ixx>0.01</ixx>
            <ixy>-5.02e-07</ixy>
            <ixz>-3.99e-07</ixz>
            <iyy>0.01</iyy>
            <iyz>-3.71e-07</iyz>
            <izz>0.01</izz>
          </inertia>
        </inertial>
        <self_collide>0</self_collide>
        <kinematic>0</kinematic>
      </link>
      <joint name='r_elbow' type='revolute'>
        <child>r_elbow_1</child>
        <parent>r_upper_arm</parent>
        <axis>
          <xyz>-4e-06 1 -3e-06</xyz>
          <limit>
            <lower>0.0959931</lower>
            <upper>1.85005</upper>
            <effort>20</effort>
            <velocity>100</velocity>
          </limit>
          <dynamics>
            <damping>1</damping>
            <friction>0</friction>
            <spring_reference>0</spring_reference>
            <spring_stiffness>0</spring_stiffness>
          </dynamics>
          <use_parent_model_frame>1</use_parent_model_frame>
        </axis>
      </joint>
      <link name='r_forearm'>
        <pose frame=''>-0.01075 0.11026 0.02302 1.57079 -3e-06 -1.5708</pose>
        <inertial>
          <pose frame=''>-0.000347 -0.066 -0.00476 0 -0 0</pose>
          <mass>0.525</mass>
          <inertia>
            <ixx>0.01</ixx>
            <ixy>5.66e-06</ixy>
            <ixz>1.4e-06</ixz>
            <iyy>0.01</iyy>
            <iyz>1.82e-05</iyz>
            <izz>0.01</izz>
          </inertia>
        </inertial>
        <collision name='r_forearm_collision'>
          <pose frame=''>0.000144 -0 -0.020433 -1.74165 1.57079 -0.170863</pose>
          <geometry>
            <mesh>
              <scale>1 1 1</scale>
              <uri>model://icub/meshes/collision/icub_simple_collision_r_forearm.dae</uri>
            </mesh>
          </geometry>
          <max_contacts>10</max_contacts>
          <surface>
            <contact>
              <ode/>
            </contact>
            <bounce/>
            <friction>
              <torsional>
                <ode/>
              </torsional>
              <ode/>
            </friction>
          </surface>
        </collision>
        <visual name='r_forearm_visual'>
          <pose frame=''>0.000144 -0 -0.020433 -1.74165 1.57079 -0.170863</pose>
          <geometry>
            <mesh>
              <scale>1 1 1</scale>
              <uri>model://icub/meshes/visual/icub_r_forearm.dae</uri>
            </mesh>
          </geometry>
        </visual>
        <self_collide>0</self_collide>
        <kinematic>0</kinematic>
      </link>
      <joint name='r_wrist_prosup' type='revolute'>
        <child>r_forearm</child>
        <parent>r_elbow_1</parent>
        <axis>
          <xyz>3e-06 3e-06 1</xyz>
          <limit>
            <lower>-0.872665</lower>
            <upper>0.872665</upper>
            <effort>0.45</effort>
            <velocity>100</velocity>
          </limit>
          <dynamics>
            <damping>1</damping>
            <friction>0</friction>
            <spring_reference>0</spring_reference>
            <spring_stiffness>0</spring_stiffness>
          </dynamics>
          <use_parent_model_frame>1</use_parent_model_frame>
        </axis>
      </joint>
      <link name='r_wrist_1'>
        <pose frame=''>-0.01075 0.11026 -0.11428 0.426292 -1.57079 1.14451</pose>
        <inertial>
          <pose frame=''>0 0 0 0 -0 0</pose>
          <mass>0.1</mass>
          <inertia>
            <ixx>0.01</ixx>
            <ixy>0</ixy>
            <ixz>0</ixz>
            <iyy>0.01</iyy>
            <iyz>0</iyz>
            <izz>0.01</izz>
          </inertia>
        </inertial>
        <self_collide>0</self_collide>
        <kinematic>0</kinematic>
      </link>
      <joint name='r_wrist_pitch' type='revolute'>
        <child>r_wrist_1</child>
        <parent>r_forearm</parent>
        <axis>
          <xyz>-1 -4e-06 3e-06</xyz>
          <limit>
            <lower>-1.13446</lower>
            <upper>0.174533</upper>
            <effort>0.65</effort>
            <velocity>100</velocity>
          </limit>
          <dynamics>
            <damping>1</damping>
            <friction>0</friction>
            <spring_reference>0</spring_reference>
            <spring_stiffness>0</spring_stiffness>
          </dynamics>
          <use_parent_model_frame>1</use_parent_model_frame>
        </axis>
      </joint>
      <link name='r_hand'>
        <pose frame=''>-0.01075 0.11026 -0.11428 -0.720145 1.57079 -2.29094</pose>
        <inertial>
          <pose frame=''>0.07023 -0.00805 0.007 0 -0 0</pose>
          <mass>0.213</mass>
          <inertia>
            <ixx>0.01</ixx>
            <ixy>1.26e-05</ixy>
            <ixz>-6.08e-06</ixz>
            <iyy>0.01</iyy>
            <iyz>1.76e-05</iyz>
            <izz>0.01</izz>
          </inertia>
        </inertial>
        <collision name='r_hand_collision'>
          <pose frame=''>0 0.020433 0.000144 0 0 -3.14159</pose>
          <geometry>
            <mesh>
              <scale>1 1 1</scale>
              <uri>model://icub/meshes/collision/icub_simple_collision_r_hand.dae</uri>
            </mesh>
          </geometry>
          <max_contacts>10</max_contacts>
          <surface>
            <contact>
              <ode/>
            </contact>
            <bounce/>
            <friction>
              <torsional>
                <ode/>
              </torsional>
              <ode/>
            </friction>
          </surface>
        </collision>
        <visual name='r_hand_visual'>
          <pose frame=''>0 0.020433 0.000144 0 0 -3.14159</pose>
          <geometry>
            <mesh>
              <scale>1 1 1</scale>
              <uri>model://icub/meshes/visual/icub_r_hand.dae</uri>
            </mesh>
          </geometry>
        </visual>
        <self_collide>0</self_collide>
        <kinematic>0</kinematic>
      </link>
      <joint name='r_wrist_yaw' type='revolute'>
        <child>r_hand</child>
        <parent>r_wrist_1</parent>
        <axis>
          <xyz>4e-06 -1 6e-06</xyz>
          <limit>
            <lower>-0.436332</lower>
            <upper>0.436332</upper>
            <effort>0.65</effort>
            <velocity>100</velocity>
          </limit>
          <dynamics>
            <damping>1</damping>
            <friction>0</friction>
            <spring_reference>0</spring_reference>
            <spring_stiffness>0</spring_stiffness>
          </dynamics>
          <use_parent_model_frame>1</use_parent_model_frame>
        </axis>
      </joint>
      <plugin name='controlboard_torso' filename='libgazebo_yarp_controlboard.so'>
        <yarpConfigurationFile>model://icub/conf/gazebo_icub_torso.ini</yarpConfigurationFile>
      </plugin>
      <plugin name='controlboard_head' filename='libgazebo_yarp_controlboard.so'>
        <yarpConfigurationFile>model://icub/conf/gazebo_icub_head.ini</yarpConfigurationFile>
      </plugin>
      <plugin name='controlboard_left_arm_no_arm' filename='libgazebo_yarp_controlboard.so'>
        <yarpConfigurationFile>model://icub/conf/gazebo_icub_left_arm_no_hand_for_no_hand_model.ini</yarpConfigurationFile>
        <initialConfiguration>-0.52 0.52 0 0.785 0 0 0.698</initialConfiguration>
      </plugin>
      <plugin name='controlboard_right_arm_no_arm' filename='libgazebo_yarp_controlboard.so'>
        <yarpConfigurationFile>model://icub/conf/gazebo_icub_right_arm_no_hand_for_no_hand_model.ini</yarpConfigurationFile>
        <initialConfiguration>-0.52 0.52 0 0.785 0 0 0.698</initialConfiguration>
      </plugin>
      <plugin name='controlboard_left_leg' filename='libgazebo_yarp_controlboard.so'>
        <yarpConfigurationFile>model://icub/conf/gazebo_icub_left_leg.ini</yarpConfigurationFile>
      </plugin>
      <plugin name='controlboard_right_leg' filename='libgazebo_yarp_controlboard.so'>
        <yarpConfigurationFile>model://icub/conf/gazebo_icub_right_leg.ini</yarpConfigurationFile>
      </plugin>
      <plugin name='apply_external_wrench' filename='libgazebo_yarp_externalwrench.so'>
        <robotNamefromConfigFile>model://icub/conf/gazebo_icub_robotname.ini</robotNamefromConfigFile>
      </plugin>
      <pose frame=''>0 0 0.7 0 -0 0</pose>
    </model>
    <plugin name='ocra_gui_plugin' filename='libocra_gui_plugin.so'/>
    <gravity>0 0 -9.8</gravity>
    <magnetic_field>6e-06 2.3e-05 -4.2e-05</magnetic_field>
    <atmosphere type='adiabatic'/>
    <physics name='default_physics' default='0' type='ode'>
      <max_step_size>0.001</max_step_size>
      <real_time_factor>1</real_time_factor>
      <real_time_update_rate>1000</real_time_update_rate>
    </physics>
    <scene>
      <ambient>1 1 1 1</ambient>
      <background>1 1 1 1</background>
      <shadows>1</shadows>
    </scene>
    <spherical_coordinates>
      <surface_model>EARTH_WGS84</surface_model>
      <latitude_deg>0</latitude_deg>
      <longitude_deg>0</longitude_deg>
      <elevation>0</elevation>
      <heading_deg>0</heading_deg>
    </spherical_coordinates>
    <state world_name='default'>
      <sim_time>2483 455000000</sim_time>
      <real_time>563 543962439</real_time>
      <wall_time>1484845023 450277179</wall_time>
      <iterations>554468</iterations>
      <model name='ground_plane'>
        <pose frame=''>0 0 0 0 -0 0</pose>
        <scale>1 1 1</scale>
        <link name='link'>
          <pose frame=''>0 0 0 0 -0 0</pose>
          <velocity>0 0 0 0 -0 0</velocity>
          <acceleration>0 0 0 0 -0 0</acceleration>
          <wrench>0 0 0 0 -0 0</wrench>
        </link>
      </model>
      <model name='iCub'>
        <pose frame=''>-0.018778 0.031237 0.594341 0.000933 -0.078521 -3.10939</pose>
        <scale>1 1 1</scale>
        <link name='chest'>
          <pose frame=''>-0.012455 0.031469 0.626119 1.5699 0.026044 0.032266</pose>
          <velocity>0 6e-06 -6e-06 5.2e-05 7.1e-05 -5.8e-05</velocity>
          <acceleration>-0.001352 0.003447 -0.014866 -1.43763 -0.398254 -1.32359</acceleration>
          <wrench>-0.006501 0.016578 -0.071506 0 -0 0</wrench>
        </link>
        <link name='eyes_tilt_link'>
          <pose frame=''>0.051359 0.033813 0.934043 1.57175 -0.013131 -3.10934</pose>
          <velocity>1e-06 1e-06 6e-06 -8.5e-05 -8e-05 -6e-06</velocity>
          <acceleration>0.002537 -0.008949 0.000146 -0.011558 -0.040952 -0.081093</acceleration>
          <wrench>2.5e-05 -8.9e-05 1e-06 0 -0 0</wrench>
        </link>
        <link name='head'>
          <pose frame=''>-0.004998 0.031892 0.828775 -1.56984 -0.013127 -3.10933</pose>
          <velocity>1.3e-05 -7e-06 -1e-06 -8.3e-05 -0.000116 -6e-06</velocity>
          <acceleration>0.002445 -0.002746 0.001267 -0.011461 0.024119 -0.080942</acceleration>
          <wrench>0.007336 -0.008238 0.003802 0 -0 0</wrench>
        </link>
        <link name='l_ankle_1'>
          <pose frame=''>-0.012728 0.136512 0.041886 -1.57056 -1.48594 -1.5272</pose>
          <velocity>-0.000138 8e-05 5.2e-05 0.000462 -0.002836 8.2e-05</velocity>
          <acceleration>-0.242611 0.156313 0.172415 0.355766 0.915557 -0.105846</acceleration>
          <wrench>-0.180988 0.11661 0.128621 0 -0 0</wrench>
        </link>
        <link name='l_ankle_2'>
          <pose frame=''>-0.012728 0.136511 0.041897 -3.14158 -1.2e-05 0.043826</pose>
          <velocity>-0.000125 6.4e-05 7.5e-05 -0.001631 -0.002852 8.8e-05</velocity>
          <acceleration>-0.039228 0.005598 0.115539 -3.05137 0.588318 0.181832</acceleration>
          <wrench>-0.010493 0.001497 0.030907 0 -0 0</wrench>
        </link>
        <link name='l_elbow_1'>
          <pose frame=''>0.083406 0.201284 0.660822 -2.01578 -1.24024 -0.83637</pose>
          <velocity>1.5e-05 -1.4e-05 -4e-06 -0.000273 -0.000105 0.000175</velocity>
          <acceleration>0.006515 -0.025803 -0.006352 -0.444435 -0.174077 0.156453</acceleration>
          <wrench>0.000651 -0.00258 -0.000635 0 -0 0</wrench>
        </link>
        <link name='l_foot'>
          <pose frame=''>-0.012727 0.136511 0.004899 -3.14158 -3e-06 0.043826</pose>
          <velocity>-1.3e-05 -1e-06 7.7e-05 0.00018 -0.00268 1e-06</velocity>
          <acceleration>-0.178792 -0.027113 0.249362 0.821106 0.933218 0.081875</acceleration>
          <wrench>-0.106113 -0.016091 0.147996 0 -0 0</wrench>
        </link>
        <link name='l_forearm'>
          <pose frame=''>0.080143 0.204898 0.646635 -2.99495 -0.297323 1.83824</pose>
          <velocity>1.6e-05 -1.8e-05 -5e-06 0.000245 6.1e-05 9.8e-05</velocity>
          <acceleration>0.005272 -0.022777 -0.007452 0.524494 0.144442 0.013374</acceleration>
          <wrench>0.002768 -0.011958 -0.003912 0 -0 0</wrench>
        </link>
        <link name='l_hand'>
          <pose frame=''>0.209588 0.246461 0.627452 -1.21903 0.554314 0.458286</pose>
          <velocity>1.1e-05 0 -3e-06 0.000236 7.2e-05 5.7e-05</velocity>
          <acceleration>0.00063 -0.008637 -0.006335 0.500786 0.220415 0.093874</acceleration>
          <wrench>0.000134 -0.00184 -0.001349 0 -0 0</wrench>
        </link>
        <link name='l_hip_1'>
          <pose frame=''>-0.030372 0.098884 0.474752 -0.00694 1.44049 0.025386</pose>
          <velocity>1.1e-05 -1.4e-05 -3.2e-05 -0.000199 -0.000205 -4.6e-05</velocity>
          <acceleration>0.01404 -0.015417 -0.055119 -0.296179 -0.355073 -0.218443</acceleration>
          <wrench>0.010586 -0.011624 -0.04156 0 -0 0</wrench>
        </link>
        <link name='l_hip_2'>
          <pose frame=''>-0.030372 0.098884 0.474756 -3.05596 -0.130308 0.032388</pose>
          <velocity>1e-05 -1.4e-05 -2.4e-05 -0.000247 -0.000212 -5.2e-05</velocity>
          <acceleration>0.033968 -0.035671 -0.064983 -0.663942 -0.383437 0.088885</acceleration>
          <wrench>0.017867 -0.018763 -0.034181 0 -0 0</wrench>
        </link>
        <link name='l_hip_3'>
          <pose frame=''>-0.021953 0.104844 0.409089 -3.05596 -0.130312 0.032387</pose>
          <velocity>2.2e-05 -3.2e-05 2.4e-05 0.000415 -0.000196 3.4e-05</velocity>
          <acceleration>0.042391 -0.062223 0.025031 0.801137 -0.33156 0.02128</acceleration>
          <wrench>0.004239 -0.006222 0.002503 0 -0 0</wrench>
        </link>
        <link name='l_lower_leg'>
          <pose frame=''>-0.002058 0.118931 0.253887 -0.499621 -1.47409 -1.02537</pose>
          <velocity>5.2e-05 2.6e-05 2.8e-05 0.000299 0.000884 0.000393</velocity>
          <acceleration>-0.097017 0.106033 0.043183 -0.397021 1.34526 -0.953976</acceleration>
          <wrench>-0.122629 0.134025 0.054584 0 -0 0</wrench>
        </link>
        <link name='l_shoulder_1'>
          <pose frame=''>-0.007043 0.14209 0.76913 0.016027 -1.07567 2.89806</pose>
          <velocity>1.7e-05 -4e-06 0 4.6e-05 5.2e-05 -5.8e-05</velocity>
          <acceleration>0.000101 -0.001889 -0.007926 0.032966 -0.013191 -0.01413</acceleration>
          <wrench>1.9e-05 -0.000357 -0.001498 0 -0 0</wrench>
        </link>
        <link name='l_shoulder_2'>
          <pose frame=''>-0.007043 0.142091 0.769128 2.58726 -0.445155 1.60601</pose>
          <velocity>1.7e-05 -4e-06 1e-06 3e-06 6.1e-05 -8.2e-05</velocity>
          <acceleration>0.000627 -0.004093 -0.005805 -0.224929 0.000611 0.108761</acceleration>
          <wrench>0.000112 -0.000733 -0.001039 0 -0 0</wrench>
        </link>
        <link name='l_shoulder_3'>
          <pose frame=''>-0.007043 0.142091 0.769126 -2.7769 -0.606922 0.053054</pose>
          <velocity>1.7e-05 -5e-06 2e-06 -0.000203 -9.4e-05 0.000227</velocity>
          <acceleration>0.000502 -0.00546 -0.003641 -0.241452 -0.16781 0.283943</acceleration>
          <wrench>7.8e-05 -0.000853 -0.000569 0 -0 0</wrench>
        </link>
        <link name='l_upper_arm'>
          <pose frame=''>0.040156 0.168885 0.725499 -2.7769 -0.606922 0.053054</pose>
          <velocity>1.5e-05 -3e-06 0 -0.000275 -9.8e-05 0.000177</velocity>
          <acceleration>0.001939 -0.009811 -0.0056 -0.42862 -0.199952 0.156786</acceleration>
          <wrench>0.001411 -0.007141 -0.004076 0 -0 0</wrench>
        </link>
        <link name='l_upper_leg'>
          <pose frame=''>-0.030373 0.098881 0.474777 1.65638 -0.130337 0.032689</pose>
          <velocity>9e-06 -6e-05 9e-06 0.000361 -0.000221 0.000297</velocity>
          <acceleration>0.072962 0.004526 0.014321 -0.222093 -0.875998 1.03407</acceleration>
          <wrench>0.158693 0.009843 0.031149 0 -0 0</wrench>
        </link>
        <link name='l_wrist_1'>
          <pose frame=''>0.209588 0.246461 0.627451 -1.27043 0.140171 0.310691</pose>
          <velocity>1.1e-05 0 -3e-06 0.000236 7.2e-05 5.7e-05</velocity>
          <acceleration>0.003988 -0.018729 -0.005714 0.491074 0.163857 -0.100588</acceleration>
          <wrench>0.000399 -0.001873 -0.000571 0 -0 0</wrench>
        </link>
        <link name='left_eye_link'>
          <pose frame=''>0.050262 0.067795 0.93401 -3.14063 -0.013131 -3.10935</pose>
          <velocity>1e-06 1e-06 3e-06 -8.3e-05 -8e-05 6.8e-05</velocity>
          <acceleration>0.005264 -0.008786 -0.000448 -0.01046 -0.040788 -0.059994</acceleration>
          <wrench>5.3e-05 -8.8e-05 -4e-06 0 -0 0</wrench>
        </link>
        <link name='neck_1'>
          <pose frame=''>-0.005123 0.03188 0.819281 3.07304 -1.55763 0.100842</pose>
          <velocity>1.4e-05 -6e-06 -2e-06 5.6e-05 -0.000112 -5.8e-05</velocity>
          <acceleration>-0.000542 -0.004054 -0.003077 0.033136 0.02524 -0.013587</acceleration>
          <wrench>-5.4e-05 -0.000405 -0.000308 0 -0 0</wrench>
        </link>
        <link name='neck_2'>
          <pose frame=''>-0.004999 0.031892 0.828772 0.013126 0.000965 1.60309</pose>
          <velocity>1.4e-05 -8e-06 0 -8.3e-05 -0.000116 -5.6e-05</velocity>
          <acceleration>1.8e-05 -0.006085 0.004101 -0.009326 0.025324 -0.012946</acceleration>
          <wrench>2e-06 -0.000609 0.00041 0 -0 0</wrench>
        </link>
        <link name='r_ankle_1'>
          <pose frame=''>-0.001294 -0.071457 0.041971 -1.57117 -1.49081 1.59084</pose>
          <velocity>7e-06 -4e-06 2.8e-05 5.7e-05 0.000175 5e-06</velocity>
          <acceleration>-0.00101 0.015751 -0.010448 0.273046 -0.004256 0.014839</acceleration>
          <wrench>-0.000753 0.01175 -0.007794 0 -0 0</wrench>
        </link>
        <link name='r_ankle_2'>
          <pose frame=''>-0.001293 -0.071458 0.041982 3.13906 -2.9e-05 0.019671</pose>
          <velocity>7e-06 -7e-06 4e-05 0.000256 0.00018 3e-06</velocity>
          <acceleration>-6.7e-05 0.004361 0.001006 -0.1642 -0.013802 0.011178</acceleration>
          <wrench>-1.8e-05 0.001166 0.000269 0 -0 0</wrench>
        </link>
        <link name='r_elbow_1'>
          <pose frame=''>0.094162 -0.131744 0.661125 1.1294 1.23885 -2.23726</pose>
          <velocity>-6.5e-05 7e-06 -7.2e-05 8.8e-05 0.000521 4.4e-05</velocity>
          <acceleration>0.010363 0.026101 -0.005352 0.138485 -0.335517 0.187636</acceleration>
          <wrench>0.001036 0.00261 -0.000535 0 -0 0</wrench>
        </link>
        <link name='r_foot'>
          <pose frame=''>-0.00129 -0.071553 0.004984 3.13906 -2.1e-05 0.01967</pose>
          <velocity>1e-06 0 4.2e-05 8.1e-05 0.000187 0</velocity>
          <acceleration>-0.000106 0.005201 0.002955 -0.155634 -0.004881 -0.016464</acceleration>
          <wrench>-6.3e-05 0.003087 0.001754 0 -0 0</wrench>
        </link>
        <link name='r_forearm'>
          <pose frame=''>0.09114 -0.135587 0.646941 0.146204 0.29908 1.36779</pose>
          <velocity>-7.2e-05 8e-06 -6.8e-05 -4.4e-05 0.000555 6.4e-05</velocity>
          <acceleration>0.022883 0.038092 0.017904 -0.380142 -0.210889 0.263441</acceleration>
          <wrench>0.012013 0.019998 0.009399 0 -0 0</wrench>
        </link>
        <link name='r_hand'>
          <pose frame=''>0.222998 -0.168746 0.627825 -1.9245 0.553583 -0.394738</pose>
          <velocity>-8e-05 1.5e-05 -0.000139 -0.001143 -0.004444 0.001149</velocity>
          <acceleration>-0.011089 5.3e-05 -0.007578 -0.440011 0.857724 -0.919893</acceleration>
          <wrench>-0.002362 1.1e-05 -0.001614 0 -0 0</wrench>
        </link>
        <link name='r_hip_1'>
          <pose frame=''>-0.025977 -0.03724 0.47488 3.13443 1.43249 0.025181</pose>
          <velocity>4e-06 -9e-06 -3e-06 -0.000284 -7.7e-05 -4.8e-05</velocity>
          <acceleration>0.016124 -0.007967 -0.073754 -0.429592 -0.020595 -0.124585</acceleration>
          <wrench>0.012157 -0.006007 -0.05561 0 -0 0</wrench>
        </link>
        <link name='r_hip_2'>
          <pose frame=''>-0.025978 -0.037239 0.474885 3.06063 -0.138304 0.032414</pose>
          <velocity>3e-06 -8e-06 1e-06 -0.000377 -8.2e-05 -6e-05</velocity>
          <acceleration>0.006479 -0.046522 -0.03261 -1.2966 -0.050676 -0.24508</acceleration>
          <wrench>0.003408 -0.024471 -0.017153 0 -0 0</wrench>
        </link>
        <link name='r_hip_3'>
          <pose frame=''>-0.016673 -0.042314 0.409271 3.06063 -0.138308 0.032414</pose>
          <velocity>6e-06 -2.6e-05 2.8e-05 8e-05 -7e-05 3e-06</velocity>
          <acceleration>0.00471 -0.0848 -0.003024 0.299499 0.000841 -0.02344</acceleration>
          <wrench>0.000471 -0.00848 -0.000302 0 -0 0</wrench>
        </link>
        <link name='r_lower_leg'>
          <pose frame=''>0.005316 -0.054315 0.254174 -2.75526 -1.48443 1.20282</pose>
          <velocity>1.7e-05 -1.6e-05 2.4e-05 6e-05 5.3e-05 1.5e-05</velocity>
          <acceleration>0.001728 -0.014003 -0.013533 0.272286 0.030004 0.013308</acceleration>
          <wrench>0.002184 -0.0177 -0.017105 0 -0 0</wrench>
        </link>
        <link name='r_shoulder_1'>
          <pose frame=''>7.5e-05 -0.078315 0.769334 3.12923 -1.07616 -2.83671</pose>
          <velocity>4e-06 -2e-06 -1.3e-05 -0.000113 0.000606 -5.5e-05</velocity>
          <acceleration>-0.002462 0.001047 -0.019886 0.153321 -0.188226 0.078847</acceleration>
          <wrench>-0.000465 0.000198 -0.003758 0 -0 0</wrench>
        </link>
        <link name='r_shoulder_2'>
          <pose frame=''>7.5e-05 -0.078315 0.769331 0.554351 -0.44696 -1.54144</pose>
          <velocity>4e-06 -3e-06 -1.1e-05 7.5e-05 0.000663 5.3e-05</velocity>
          <acceleration>-0.000822 0.002825 -0.016127 0.407343 -0.080378 -0.072964</acceleration>
          <wrench>-0.000147 0.000506 -0.002887 0 -0 0</wrench>
        </link>
        <link name='r_shoulder_3'>
          <pose frame=''>7.5e-05 -0.078315 0.769329 2.77469 -0.606961 0.012779</pose>
          <velocity>4e-06 -4e-06 -9e-06 0.00011 0.00064 5e-06</velocity>
          <acceleration>0.001679 0.007516 -0.010617 0.178336 -0.064429 0.089326</acceleration>
          <wrench>0.00026 0.001165 -0.001646 0 -0 0</wrench>
        </link>
        <link name='r_upper_arm'>
          <pose frame=''>0.048907 -0.102087 0.725744 2.77469 -0.606961 0.012779</pose>
          <velocity>-2.4e-05 0 -3.9e-05 0.000111 0.00064 6e-06</velocity>
          <acceleration>0.005562 0.015107 -0.003955 0.185451 -0.046374 0.10466</acceleration>
          <wrench>0.004055 0.011013 -0.002883 0 -0 0</wrench>
        </link>
        <link name='r_upper_leg'>
          <pose frame=''>-0.02598 -0.037234 0.474911 1.49004 -0.138434 0.030833</pose>
          <velocity>1e-06 -3.2e-05 2.1e-05 6.5e-05 -6.9e-05 2.6e-05</velocity>
          <acceleration>0.004815 -0.061251 -0.011793 0.276321 0.002649 0.018088</acceleration>
          <wrench>0.010472 -0.13322 -0.02565 0 -0 0</wrench>
        </link>
        <link name='r_wrist_1'>
          <pose frame=''>0.222998 -0.168746 0.627826 1.87292 -0.139674 2.89523</pose>
          <velocity>-8.1e-05 1.5e-05 -0.00014 -0.000139 0.000434 -0.000386</velocity>
          <acceleration>0.028164 0.054366 0.038734 -0.504532 -0.376565 -0.367571</acceleration>
          <wrench>0.002816 0.005437 0.003873 0 -0 0</wrench>
        </link>
        <link name='right_eye_link'>
          <pose frame=''>0.052456 -0.00017 0.934076 -3.14063 -0.013131 -3.1093</pose>
          <velocity>1e-06 1e-06 9e-06 -8.3e-05 -8e-05 6.8e-05</velocity>
          <acceleration>-0.000259 -0.008804 -0.000267 -0.008865 -0.040505 -0.059936</acceleration>
          <wrench>-3e-06 -8.8e-05 -3e-06 0 -0 0</wrench>
        </link>
        <link name='root_link'>
          <pose frame=''>-0.018778 0.031237 0.594341 0.000933 -0.078521 -3.10939</pose>
          <velocity>-4e-06 1.9e-05 -2.2e-05 -0.000244 -9.3e-05 -4.6e-05</velocity>
          <acceleration>-0.008066 0.035002 -0.065813 -0.374461 -0.187059 -0.122133</acceleration>
          <wrench>-0.038072 0.165209 -0.310638 0 -0 0</wrench>
        </link>
        <link name='torso_1'>
          <pose frame=''>-0.018777 0.031238 0.594354 -0.035654 -1.54474 0.06791</pose>
          <velocity>-5e-06 2.3e-05 -2.7e-05 -0.000256 6.1e-05 -4.7e-05</velocity>
          <acceleration>-0.0096 0.044022 -0.079199 -2.65106 0.080315 2.19149</acceleration>
          <wrench>-0.00096 0.004402 -0.00792 0 -0 0</wrench>
        </link>
        <link name='torso_2'>
          <pose frame=''>-0.017947 0.031293 0.62631 3.11555 -0.0009 -1.53853</pose>
          <velocity>-2e-06 2.1e-05 -1.9e-05 5.2e-05 7.1e-05 -5.6e-05</velocity>
          <acceleration>-0.006632 0.036886 -0.054544 0.033647 0.004767 -0.146241</acceleration>
          <wrench>-0.000663 0.003689 -0.005454 0 -0 0</wrench>
        </link>
      </model>
      <model name='yarp_camera'>
        <pose frame=''>1.06293 0.935146 0.606963 0.027048 0.070242 -2.36133</pose>
        <scale>1 1 1</scale>
        <link name='link'>
          <pose frame=''>1.06293 0.935146 0.606963 0.027048 0.070242 -2.36133</pose>
          <velocity>0 0 0 0 -0 0</velocity>
          <acceleration>0 0 0 0 -0 0</acceleration>
          <wrench>0 0 0 0 -0 0</wrench>
        </link>
      </model>
      <light name='sun'>
        <pose frame=''>0 0 10 0 -0 0</pose>
      </light>
      <light name='user_point_light_0'>
        <pose frame=''>7.76818 -7.88366 3.95643 0 -0 0</pose>
      </light>
      <light name='user_point_light_1'>
        <pose frame=''>-0.810427 9.3318 3.76267 0 -0 0</pose>
      </light>
    </state>
    <gui fullscreen='0'>
      <camera name='user_camera'>
        <pose frame=''>6.88836 22.633 7.73489 0 0.399643 -1.983</pose>
        <view_controller>orbit</view_controller>
        <projection_type>perspective</projection_type>
      </camera>
    </gui>
    <plugin name='ocra_gui_plugin' filename='libocra_gui_plugin.so'/>
    <model name='yarp_camera'>
      <pose frame=''>0.560453 0.491528 0.5 0 -0 3.14</pose>
      <static>0</static>
      <link name='link'>
        <gravity>0</gravity>
        <visual name='visual'>
          <geometry>
            <box>
              <size>0.1 0.1 0.1</size>
            </box>
          </geometry>
          <transparency>0.6</transparency>
        </visual>
        <sensor name='yarp_camera_sensor' type='camera'>
          <camera name='__default__'>
            <horizontal_fov>0.5</horizontal_fov>
            <image>
              <width>1080</width>
              <height>1920</height>
            </image>
            <clip>
              <near>0.1</near>
              <far>100</far>
            </clip>
          </camera>
          <always_on>1</always_on>
          <update_rate>30</update_rate>
          <visualize>1</visualize>
          <plugin name='yarp_camera_control' filename='libyarp_camera_control.so'/>
        </sensor>
        <kinematic>0</kinematic>
        <self_collide>0</self_collide>
        <inertial>
          <inertia>
            <ixx>1</ixx>
            <ixy>0</ixy>
            <ixz>0</ixz>
            <iyy>1</iyy>
            <iyz>0</iyz>
            <izz>1</izz>
          </inertia>
          <mass>1</mass>
        </inertial>
      </link>
      <plugin name='yarp_model_move' filename='libyarp_model_move.so'/>
    </model>
    <light name='user_point_light_0' type='point'>
      <pose frame=''>7.76818 -7.88366 1 0 -0 0</pose>
      <diffuse>0.5 0.5 0.5 1</diffuse>
      <specular>0.1 0.1 0.1 1</specular>
      <attenuation>
        <range>20</range>
        <constant>0.5</constant>
        <linear>0.01</linear>
        <quadratic>0.001</quadratic>
      </attenuation>
      <cast_shadows>0</cast_shadows>
      <direction>0 0 -1</direction>
    </light>
    <light name='user_point_light_1' type='point'>
      <pose frame=''>-0.810427 9.3318 1 0 -0 0</pose>
      <diffuse>0.5 0.5 0.5 1</diffuse>
      <specular>0.1 0.1 0.1 1</specular>
      <attenuation>
        <range>20</range>
        <constant>0.5</constant>
        <linear>0.01</linear>
        <quadratic>0.001</quadratic>
      </attenuation>
      <cast_shadows>0</cast_shadows>
      <direction>0 0 -1</direction>
    </light>
  </world>
</sdf>
