<sdf version='1.6'>
  <world name='default'>
    <light name='sun' type='directional'>
      <cast_shadows>1</cast_shadows>
      <pose frame=''>0 0 10 0 -0 0</pose>
      <diffuse>0.8 0.8 0.8 1</diffuse>
      <specular>0.2 0.2 0.2 1</specular>
      <attenuation>
        <range>1000</range>
        <constant>0.9</constant>
        <linear>0.01</linear>
        <quadratic>0.001</quadratic>
      </attenuation>
      <direction>-0.5 0.1 -0.9</direction>
    </light>
    <model name='ground_plane'>
      <static>1</static>
      <link name='link'>
        <collision name='collision'>
          <geometry>
            <plane>
              <normal>0 0 1</normal>
              <size>100 100</size>
            </plane>
          </geometry>
          <surface>
            <friction>
              <ode>
                <mu>100</mu>
                <mu2>50</mu2>
              </ode>
              <torsional>
                <ode/>
              </torsional>
            </friction>
            <contact>
              <ode/>
            </contact>
            <bounce/>
          </surface>
          <max_contacts>10</max_contacts>
        </collision>
        <visual name='visual'>
          <cast_shadows>0</cast_shadows>
          <geometry>
            <plane>
              <normal>0 0 1</normal>
              <size>100 100</size>
            </plane>
          </geometry>
          <material>
            <script>
              <uri>file://media/materials/scripts/gazebo.material</uri>
              <name>Gazebo/White</name>
            </script>
          </material>
        </visual>
        <self_collide>0</self_collide>
        <kinematic>0</kinematic>
        <gravity>1</gravity>
      </link>
    </model>
    <physics name='default_physics' default='0' type='ode'>
      <max_step_size>0.001</max_step_size>
      <real_time_factor>1</real_time_factor>
      <real_time_update_rate>1000</real_time_update_rate>
    </physics>
    <scene>
      <ambient>1 1 1 1</ambient>
      <background>1 1 1 1</background>
      <shadows>1</shadows>
    </scene>
    <spherical_coordinates>
      <surface_model>EARTH_WGS84</surface_model>
      <latitude_deg>0</latitude_deg>
      <longitude_deg>0</longitude_deg>
      <elevation>0</elevation>
      <heading_deg>0</heading_deg>
    </spherical_coordinates>
    <model name='chair'>
      <link name='chair::low_part'>
        <pose frame=''>0 0 0.18 0 -0 0</pose>
        <inertial>
          <mass>1</mass>
          <inertia>
            <ixx>1</ixx>
            <ixy>0</ixy>
            <ixz>0</ixz>
            <iyy>1</iyy>
            <iyz>0</iyz>
            <izz>1</izz>
          </inertia>
        </inertial>
        <collision name='collision_low'>
          <pose frame=''>0 0 0 0 -0 0</pose>
          <geometry>
            <box>
              <size>0.05 0.75 0.025</size>
            </box>
          </geometry>
          <max_contacts>10</max_contacts>
          <surface>
            <contact>
              <ode/>
            </contact>
            <bounce/>
            <friction>
              <torsional>
                <ode/>
              </torsional>
              <ode/>
            </friction>
          </surface>
        </collision>
        <visual name='visual_low'>
          <pose frame=''>0 0 0 0 -0 0</pose>
          <geometry>
            <box>
              <size>0.05 0.75 0.025</size>
            </box>
          </geometry>
        </visual>
        <self_collide>0</self_collide>
        <kinematic>0</kinematic>
      </link>
      <link name='chair::high_part'>
        <pose frame=''>0 0 0.205 0 -0 0</pose>
        <inertial>
          <mass>1</mass>
          <inertia>
            <ixx>1</ixx>
            <ixy>0</ixy>
            <ixz>0</ixz>
            <iyy>1</iyy>
            <iyz>0</iyz>
            <izz>1</izz>
          </inertia>
        </inertial>
        <collision name='collision_high'>
          <pose frame=''>0 0 0 0 -0 0</pose>
          <geometry>
            <box>
              <size>0.05 0.75 0.025</size>
            </box>
          </geometry>
          <max_contacts>4</max_contacts>
          <surface>
            <contact>
              <ode>
                <soft_erp>0.2</soft_erp>
                <soft_cfm>0</soft_cfm>
                <kp>1.8e+06</kp>
                <kd>100</kd>
                <max_vel>100</max_vel>
                <min_depth>0.0001</min_depth>
              </ode>
            </contact>
            <friction>
              <ode>
                <mu>1</mu>
                <mu2>1</mu2>
                <fdir1>0 0 0</fdir1>
                <slip1>0</slip1>
                <slip2>0</slip2>
              </ode>
              <torsional>
                <ode/>
              </torsional>
            </friction>
            <bounce>
              <restitution_coefficient>0</restitution_coefficient>
              <threshold>100000</threshold>
            </bounce>
          </surface>
        </collision>
        <visual name='visual_high'>
          <pose frame=''>0 0 0 0 -0 0</pose>
          <material>
            <script>
              <name>Gazebo/Blue</name>
              <uri>__default__</uri>
            </script>
          </material>
          <geometry>
            <box>
              <size>0.05 0.75 0.025</size>
            </box>
          </geometry>
        </visual>
        <self_collide>0</self_collide>
        <kinematic>0</kinematic>
      </link>
      <joint name='chair::sensor_joint' type='fixed'>
        <parent>chair::low_part</parent>
        <child>chair::high_part</child>
        <axis>
          <limit>
            <lower>0</lower>
            <upper>0</upper>
          </limit>
          <xyz>0 0 0</xyz>
          <use_parent_model_frame>0</use_parent_model_frame>
        </axis>
        <sensor name='chair_ft_sensor' type='force_torque'>
          <force_torque>
            <frame>child</frame>
            <measure_direction>parent_to_child</measure_direction>
          </force_torque>
          <always_on>1</always_on>
          <visualize>1</visualize>
          <update_rate>100</update_rate>
          <plugin name='chair_FT_plugin' filename='libgazebo_yarp_forcetorque.so'>
            <yarpConfigurationFile>model://icub_chair_world/chair/chair_gazebo_torque.ini</yarpConfigurationFile>
          </plugin>
        </sensor>
      </joint>
      <joint name='chair::fixed to ground' type='fixed'>
        <parent>world</parent>
        <child>chair::low_part</child>
        <axis>
          <limit>
            <lower>0</lower>
            <upper>0</upper>
          </limit>
          <xyz>0 0 0.18</xyz>
          <use_parent_model_frame>0</use_parent_model_frame>
        </axis>
      </joint>
    </model>
    <model name='iCub'>
      <self_collide>1</self_collide>
      <link name='iCub::root_link'>
        <pose frame=''>0 0 0 0 -0 0</pose>
        <inertial>
          <pose frame=''>0 0 0 0 -0 0</pose>
          <mass>4.72</mass>
          <inertia>
            <ixx>0.01</ixx>
            <ixy>0</ixy>
            <ixz>0</ixz>
            <iyy>0.01</iyy>
            <iyz>0</iyz>
            <izz>0.01</izz>
          </inertia>
        </inertial>
        <collision name='root_link_collision'>
          <pose frame=''>0 0 0 0 -0 0</pose>
          <geometry>
            <mesh>
              <scale>1 1 1</scale>
              <uri>model://icub/meshes/collision/icub_simple_collision_root_link.dae</uri>
            </mesh>
          </geometry>
          <max_contacts>10</max_contacts>
          <surface>
            <contact>
              <ode/>
            </contact>
            <bounce/>
            <friction>
              <torsional>
                <ode/>
              </torsional>
              <ode/>
            </friction>
          </surface>
        </collision>
        <visual name='root_link_visual'>
          <pose frame=''>0 0 0 0 -0 0</pose>
          <geometry>
            <mesh>
              <scale>1 1 1</scale>
              <uri>model://icub/meshes/visual/icub_root_link.dae</uri>
            </mesh>
          </geometry>
        </visual>
        <self_collide>0</self_collide>
        <kinematic>0</kinematic>
      </link>
      <link name='iCub::l_hip_1'>
        <pose frame=''>0 -0.0681 -0.1199 3e-06 1.57079 3.14159</pose>
        <inertial>
          <pose frame=''>0 -0.0782 0 0 -0 0</pose>
          <mass>0.754</mass>
          <inertia>
            <ixx>0.01</ixx>
            <ixy>2.059e-06</ixy>
            <ixz>1.451e-06</ixz>
            <iyy>0.01</iyy>
            <iyz>1.545e-06</iyz>
            <izz>0.01</izz>
          </inertia>
        </inertial>
        <collision name='l_hip_1_collision'>
          <pose frame=''>0 0 0 -0.785403 1.57079 -2.35619</pose>
          <geometry>
            <mesh>
              <scale>1 1 1</scale>
              <uri>model://icub/meshes/collision/icub_simple_collision_l_hip_1.dae</uri>
            </mesh>
          </geometry>
          <max_contacts>10</max_contacts>
          <surface>
            <contact>
              <ode/>
            </contact>
            <bounce/>
            <friction>
              <torsional>
                <ode/>
              </torsional>
              <ode/>
            </friction>
          </surface>
        </collision>
        <visual name='l_hip_1_visual'>
          <pose frame=''>0 0 0 -0.785403 1.57079 -2.35619</pose>
          <geometry>
            <mesh>
              <scale>1 1 1</scale>
              <uri>model://icub/meshes/visual/icub_l_hip_1.dae</uri>
            </mesh>
          </geometry>
        </visual>
        <self_collide>0</self_collide>
        <kinematic>0</kinematic>
      </link>
      <joint name='iCub::l_hip_pitch' type='revolute'>
        <child>iCub::l_hip_1</child>
        <parent>iCub::root_link</parent>
        <axis>
          <xyz>3e-06 1 0</xyz>
          <limit>
            <lower>-0.767945</lower>
            <upper>2.30383</upper>
            <effort>84</effort>
            <velocity>100</velocity>
          </limit>
          <dynamics>
            <damping>1</damping>
            <friction>0</friction>
            <spring_reference>0</spring_reference>
            <spring_stiffness>0</spring_stiffness>
          </dynamics>
          <use_parent_model_frame>1</use_parent_model_frame>
        </axis>
      </joint>
      <link name='iCub::l_hip_2'>
        <pose frame=''>0 -0.0681 -0.1199 3.14159 -7e-06 3.14159</pose>
        <inertial>
          <pose frame=''>0 0 0.03045 0 -0 0</pose>
          <mass>0.526</mass>
          <inertia>
            <ixx>0.01</ixx>
            <ixy>-7.4e-08</ixy>
            <ixz>1.0835e-05</ixz>
            <iyy>0.01</iyy>
            <iyz>-6.2e-08</iyz>
            <izz>0.01</izz>
          </inertia>
        </inertial>
        <collision name='l_hip_2_collision'>
          <pose frame=''>0 0 0 0.785363 -1.57079 2.35623</pose>
          <geometry>
            <mesh>
              <scale>1 1 1</scale>
              <uri>model://icub/meshes/collision/icub_simple_collision_l_hip_2.dae</uri>
            </mesh>
          </geometry>
          <max_contacts>10</max_contacts>
          <surface>
            <contact>
              <ode/>
            </contact>
            <bounce/>
            <friction>
              <torsional>
                <ode/>
              </torsional>
              <ode/>
            </friction>
          </surface>
        </collision>
        <visual name='l_hip_2_visual'>
          <pose frame=''>0 0 0 0.785363 -1.57079 2.35623</pose>
          <geometry>
            <mesh>
              <scale>1 1 1</scale>
              <uri>model://icub/meshes/visual/icub_l_hip_2.dae</uri>
            </mesh>
          </geometry>
        </visual>
        <self_collide>0</self_collide>
        <kinematic>0</kinematic>
      </link>
      <joint name='iCub::l_hip_roll' type='revolute'>
        <child>iCub::l_hip_2</child>
        <parent>iCub::l_hip_1</parent>
        <axis>
          <xyz>-1 3e-06 7e-06</xyz>
          <limit>
            <lower>-0.296706</lower>
            <upper>2.07694</upper>
            <effort>84</effort>
            <velocity>100</velocity>
          </limit>
          <dynamics>
            <damping>1</damping>
            <friction>0</friction>
            <spring_reference>0</spring_reference>
            <spring_stiffness>0</spring_stiffness>
          </dynamics>
          <use_parent_model_frame>1</use_parent_model_frame>
        </axis>
      </joint>
      <link name='iCub::l_hip_3'>
        <pose frame=''>-0 -0.0681 -0.1864 3.14159 -7e-06 3.14159</pose>
        <inertial>
          <pose frame=''>0 0 0 0 -0 0</pose>
          <mass>0.1</mass>
          <inertia>
            <ixx>0.01</ixx>
            <ixy>0</ixy>
            <ixz>0</ixz>
            <iyy>0.01</iyy>
            <iyz>0</iyz>
            <izz>0.01</izz>
          </inertia>
        </inertial>
        <self_collide>0</self_collide>
        <kinematic>0</kinematic>
      </link>
      <joint name='iCub::l_leg_ft_sensor' type='revolute'>
        <child>iCub::l_hip_3</child>
        <parent>iCub::l_hip_2</parent>
        <axis>
          <xyz>0 0 0</xyz>
          <limit>
            <lower>0</lower>
            <upper>0</upper>
            <effort>0</effort>
            <velocity>0</velocity>
          </limit>
          <dynamics>
            <spring_reference>0</spring_reference>
            <spring_stiffness>0</spring_stiffness>
          </dynamics>
          <use_parent_model_frame>1</use_parent_model_frame>
        </axis>
        <sensor name='left_leg_ft' type='force_torque'>
          <always_on>1</always_on>
          <update_rate>100</update_rate>
          <pose frame=''>0 0 0 0 -0 0</pose>
          <plugin name='left_leg_ft_plugin' filename='libgazebo_yarp_forcetorque.so'>
            <yarpConfigurationFile>model://icub/conf/FT/gazebo_icub_left_leg_ft.ini</yarpConfigurationFile>
          </plugin>
        </sensor>
      </joint>
      <link name='iCub::l_upper_leg'>
        <pose frame=''>0 -0.0681 -0.1199 1.57079 -7e-06 3.14159</pose>
        <inertial>
          <pose frame=''>0.00144 -0.15943 -0.00039 0 -0 0</pose>
          <mass>2.175</mass>
          <inertia>
            <ixx>0.01</ixx>
            <ixy>-6.726e-05</ixy>
            <ixz>2.267e-06</ixz>
            <iyy>0.01</iyy>
            <iyz>3.63726e-05</iyz>
            <izz>0.01</izz>
          </inertia>
        </inertial>
        <collision name='l_upper_leg_collision'>
          <pose frame=''>0 0 0 -2.67797 1.57079 -1.10716</pose>
          <geometry>
            <mesh>
              <scale>1 1 1</scale>
              <uri>model://icub/meshes/collision/icub_simple_collision_l_thigh.dae</uri>
            </mesh>
          </geometry>
          <max_contacts>4</max_contacts>
          <surface>
            <contact>
              <ode>
                <soft_erp>0.2</soft_erp>
                <soft_cfm>0</soft_cfm>
                <kp>1.8e+07</kp>
                <kd>100</kd>
                <max_vel>100</max_vel>
                <min_depth>0.0001</min_depth>
              </ode>
            </contact>
            <friction>
              <ode>
                <mu>1</mu>
                <mu2>1</mu2>
                <fdir1>0 0 0</fdir1>
                <slip1>0</slip1>
                <slip2>0</slip2>
              </ode>
              <torsional>
                <ode/>
              </torsional>
            </friction>
            <bounce>
              <restitution_coefficient>0</restitution_coefficient>
              <threshold>100000</threshold>
            </bounce>
          </surface>
        </collision>
        <visual name='l_upper_leg_visual'>
          <pose frame=''>0 0 0 -2.67797 1.57079 -1.10716</pose>
          <geometry>
            <mesh>
              <scale>1 1 1</scale>
              <uri>model://icub/meshes/visual/icub_l_thigh.dae</uri>
            </mesh>
          </geometry>
        </visual>
        <self_collide>0</self_collide>
        <kinematic>0</kinematic>
      </link>
      <joint name='iCub::l_hip_yaw' type='revolute'>
        <child>iCub::l_upper_leg</child>
        <parent>iCub::l_hip_3</parent>
        <axis>
          <xyz>7e-06 -6e-06 1</xyz>
          <limit>
            <lower>-1.37881</lower>
            <upper>1.37881</upper>
            <effort>40</effort>
            <velocity>100</velocity>
          </limit>
          <dynamics>
            <damping>1</damping>
            <friction>0</friction>
            <spring_reference>0</spring_reference>
            <spring_stiffness>0</spring_stiffness>
          </dynamics>
          <use_parent_model_frame>1</use_parent_model_frame>
        </axis>
      </joint>
      <link name='iCub::l_lower_leg'>
        <pose frame=''>-2e-06 -0.068099 -0.3435 2.09198 -1.57078 -0.521189</pose>
        <inertial>
          <pose frame=''>-0.1071 0.00182 0.00211 0 -0 0</pose>
          <mass>1.264</mass>
          <inertia>
            <ixx>0.01</ixx>
            <ixy>-0.000185699</ixy>
            <ixz>-6.3147e-05</ixz>
            <iyy>0.01</iyy>
            <iyz>7.86e-07</iyz>
            <izz>0.01</izz>
          </inertia>
        </inertial>
        <collision name='l_lower_leg_collision'>
          <pose frame=''>0 0 0 -3.14159 -0 1.5708</pose>
          <geometry>
            <mesh>
              <scale>1 1 1</scale>
              <uri>model://icub/meshes/collision/icub_simple_collision_l_shank.dae</uri>
            </mesh>
          </geometry>
          <max_contacts>10</max_contacts>
          <surface>
            <contact>
              <ode/>
            </contact>
            <bounce/>
            <friction>
              <torsional>
                <ode/>
              </torsional>
              <ode/>
            </friction>
          </surface>
        </collision>
        <visual name='l_lower_leg_visual'>
          <pose frame=''>0 0 0 -3.14159 -0 1.5708</pose>
          <geometry>
            <mesh>
              <scale>1 1 1</scale>
              <uri>model://icub/meshes/visual/icub_l_shank.dae</uri>
            </mesh>
          </geometry>
        </visual>
        <self_collide>0</self_collide>
        <kinematic>0</kinematic>
      </link>
      <joint name='iCub::l_knee' type='revolute'>
        <child>iCub::l_lower_leg</child>
        <parent>iCub::l_upper_leg</parent>
        <axis>
          <xyz>5e-06 1 6e-06</xyz>
          <limit>
            <lower>-2.18166</lower>
            <upper>0.401426</upper>
            <effort>30</effort>
            <velocity>100</velocity>
          </limit>
          <dynamics>
            <damping>1</damping>
            <friction>0</friction>
            <spring_reference>0</spring_reference>
            <spring_stiffness>0</spring_stiffness>
          </dynamics>
          <use_parent_model_frame>1</use_parent_model_frame>
        </axis>
      </joint>
      <link name='iCub::l_ankle_1'>
        <pose frame=''>-4e-06 -0.068097 -0.5565 0.52118 -1.57078 -0.521189</pose>
        <inertial>
          <pose frame=''>-0.0054 0.00163 0.0172 0 -0 0</pose>
          <mass>0.746</mass>
          <inertia>
            <ixx>0.01</ixx>
            <ixy>-7.081e-06</ixy>
            <ixz>4.1421e-05</ixz>
            <iyy>0.01</iyy>
            <iyz>2.0817e-05</iyz>
            <izz>0.01</izz>
          </inertia>
        </inertial>
        <collision name='l_ankle_1_collision'>
          <pose frame=''>0 -0 0 1.5708 -0 0</pose>
          <geometry>
            <mesh>
              <scale>1 1 1</scale>
              <uri>model://icub/meshes/collision/icub_simple_collision_l_ankle_1.dae</uri>
            </mesh>
          </geometry>
          <max_contacts>10</max_contacts>
          <surface>
            <contact>
              <ode/>
            </contact>
            <bounce/>
            <friction>
              <torsional>
                <ode/>
              </torsional>
              <ode/>
            </friction>
          </surface>
        </collision>
        <visual name='l_ankle_1_visual'>
          <pose frame=''>0 -0 0 1.5708 -0 0</pose>
          <geometry>
            <mesh>
              <scale>1 1 1</scale>
              <uri>model://icub/meshes/visual/icub_l_ankle_1.dae</uri>
            </mesh>
          </geometry>
        </visual>
        <self_collide>0</self_collide>
        <kinematic>0</kinematic>
      </link>
      <joint name='iCub::l_ankle_pitch' type='revolute'>
        <child>iCub::l_ankle_1</child>
        <parent>iCub::l_lower_leg</parent>
        <axis>
          <xyz>-9e-06 -1 -6e-06</xyz>
          <limit>
            <lower>-0.733038</lower>
            <upper>0.366519</upper>
            <effort>24</effort>
            <velocity>100</velocity>
          </limit>
          <dynamics>
            <damping>1</damping>
            <friction>0</friction>
            <spring_reference>0</spring_reference>
            <spring_stiffness>0</spring_stiffness>
          </dynamics>
          <use_parent_model_frame>1</use_parent_model_frame>
        </axis>
      </joint>
      <link name='iCub::l_ankle_2'>
        <pose frame=''>-4e-06 -0.068097 -0.5565 3.14159 -7e-06 3.14158</pose>
        <inertial>
          <pose frame=''>0 0 0.037 0 -0 0</pose>
          <mass>0.2675</mass>
          <inertia>
            <ixx>0.01</ixx>
            <ixy>0</ixy>
            <ixz>0</ixz>
            <iyy>0.01</iyy>
            <iyz>0</iyz>
            <izz>0.01</izz>
          </inertia>
        </inertial>
        <self_collide>0</self_collide>
        <kinematic>0</kinematic>
      </link>
      <joint name='iCub::l_ankle_roll' type='revolute'>
        <child>iCub::l_ankle_2</child>
        <parent>iCub::l_ankle_1</parent>
        <axis>
          <xyz>-1 9e-06 7e-06</xyz>
          <limit>
            <lower>-0.418879</lower>
            <upper>0.418879</upper>
            <effort>11</effort>
            <velocity>100</velocity>
          </limit>
          <dynamics>
            <damping>1</damping>
            <friction>0</friction>
            <spring_reference>0</spring_reference>
            <spring_stiffness>0</spring_stiffness>
          </dynamics>
          <use_parent_model_frame>1</use_parent_model_frame>
        </axis>
      </joint>
      <link name='iCub::l_foot'>
        <pose frame=''>-4e-06 -0.068097 -0.5935 3.14159 -7e-06 3.14158</pose>
        <inertial>
          <pose frame=''>0.024069 -0.000614 -0.028415 0 -0 0</pose>
          <mass>0.5935</mass>
          <inertia>
            <ixx>0.01</ixx>
            <ixy>-4.51893e-06</ixy>
            <ixz>0.000567785</ixz>
            <iyy>0.01</iyy>
            <iyz>-6.62361e-07</iyz>
            <izz>0.01</izz>
          </inertia>
        </inertial>
        <collision name='l_foot_collision'>
          <pose frame=''>0.03 0 -0.01 0 -0 0</pose>
          <geometry>
            <box>
              <size>0.15 0.07 0.03</size>
            </box>
          </geometry>
          <max_contacts>4</max_contacts>
          <surface>
            <contact>
              <ode>
                <soft_erp>0.2</soft_erp>
                <soft_cfm>0</soft_cfm>
                <kp>1.8e+07</kp>
                <kd>100</kd>
                <max_vel>100</max_vel>
                <min_depth>0.0001</min_depth>
              </ode>
            </contact>
            <friction>
              <ode>
                <mu>1</mu>
                <mu2>1</mu2>
                <fdir1>0 0 0</fdir1>
                <slip1>0</slip1>
                <slip2>0</slip2>
              </ode>
              <torsional>
                <ode/>
              </torsional>
            </friction>
            <bounce>
              <restitution_coefficient>0</restitution_coefficient>
              <threshold>100000</threshold>
            </bounce>
          </surface>
        </collision>
        <visual name='l_foot_visual'>
          <pose frame=''>0 -0 -0.037 -0.785403 1.57079 -0.785403</pose>
          <geometry>
            <mesh>
              <scale>1 1 1</scale>
              <uri>model://icub/meshes/visual/icub_l_foot.dae</uri>
            </mesh>
          </geometry>
        </visual>
        <self_collide>0</self_collide>
        <kinematic>0</kinematic>
      </link>
      <joint name='iCub::l_foot_ft_sensor' type='revolute'>
        <child>iCub::l_foot</child>
        <parent>iCub::l_ankle_2</parent>
        <axis>
          <xyz>0 0 0</xyz>
          <limit>
            <lower>0</lower>
            <upper>0</upper>
            <effort>0</effort>
            <velocity>0</velocity>
          </limit>
          <dynamics>
            <spring_reference>0</spring_reference>
            <spring_stiffness>0</spring_stiffness>
          </dynamics>
          <use_parent_model_frame>1</use_parent_model_frame>
        </axis>
        <sensor name='left_foot_ft' type='force_torque'>
          <always_on>1</always_on>
          <update_rate>100</update_rate>
          <pose frame=''>0 0 0 0 -0 0</pose>
          <plugin name='left_foot_ft_plugin' filename='libgazebo_yarp_forcetorque.so'>
            <yarpConfigurationFile>model://icub/conf/FT/gazebo_icub_left_foot_ft.ini</yarpConfigurationFile>
          </plugin>
        </sensor>
      </joint>
      <link name='iCub::r_hip_1'>
        <pose frame=''>0 0.0681 -0.1199 3.14159 1.57079 -3.14159</pose>
        <inertial>
          <pose frame=''>0 -0.0782 0 0 -0 0</pose>
          <mass>0.754</mass>
          <inertia>
            <ixx>0.01</ixx>
            <ixy>0</ixy>
            <ixz>0</ixz>
            <iyy>0.01</iyy>
            <iyz>0</iyz>
            <izz>0.01</izz>
          </inertia>
        </inertial>
        <collision name='r_hip_1_collision'>
          <pose frame=''>0 0 0 1.76819 -1.57079 2.76109</pose>
          <geometry>
            <mesh>
              <scale>1 1 1</scale>
              <uri>model://icub/meshes/collision/icub_simple_collision_r_hip_1.dae</uri>
            </mesh>
          </geometry>
          <max_contacts>10</max_contacts>
          <surface>
            <contact>
              <ode/>
            </contact>
            <bounce/>
            <friction>
              <torsional>
                <ode/>
              </torsional>
              <ode/>
            </friction>
          </surface>
        </collision>
        <visual name='r_hip_1_visual'>
          <pose frame=''>0 0 0 1.76819 -1.57079 2.76109</pose>
          <geometry>
            <mesh>
              <scale>1 1 1</scale>
              <uri>model://icub/meshes/visual/icub_r_hip_1.dae</uri>
            </mesh>
          </geometry>
        </visual>
        <self_collide>0</self_collide>
        <kinematic>0</kinematic>
      </link>
      <joint name='iCub::r_hip_pitch' type='revolute'>
        <child>iCub::r_hip_1</child>
        <parent>iCub::root_link</parent>
        <axis>
          <xyz>0 1 0</xyz>
          <limit>
            <lower>-0.767945</lower>
            <upper>2.30383</upper>
            <effort>84</effort>
            <velocity>100</velocity>
          </limit>
          <dynamics>
            <damping>1</damping>
            <friction>0</friction>
            <spring_reference>0</spring_reference>
            <spring_stiffness>0</spring_stiffness>
          </dynamics>
          <use_parent_model_frame>1</use_parent_model_frame>
        </axis>
      </joint>
      <link name='iCub::r_hip_2'>
        <pose frame=''>0 0.0681 -0.1199 -3.14159 -7e-06 -3.14159</pose>
        <inertial>
          <pose frame=''>0 0 0.03045 0 -0 0</pose>
          <mass>0.526</mass>
          <inertia>
            <ixx>0.01</ixx>
            <ixy>0</ixy>
            <ixz>0</ixz>
            <iyy>0.01</iyy>
            <iyz>0</iyz>
            <izz>0.01</izz>
          </inertia>
        </inertial>
        <collision name='r_hip_2_collision'>
          <pose frame=''>0 0 0 -2.35627 -1.57079 2.35627</pose>
          <geometry>
            <mesh>
              <scale>1 1 1</scale>
              <uri>model://icub/meshes/collision/icub_simple_collision_r_hip_2.dae</uri>
            </mesh>
          </geometry>
          <max_contacts>10</max_contacts>
          <surface>
            <contact>
              <ode/>
            </contact>
            <bounce/>
            <friction>
              <torsional>
                <ode/>
              </torsional>
              <ode/>
            </friction>
          </surface>
        </collision>
        <visual name='r_hip_2_visual'>
          <pose frame=''>0 0 0 -2.35627 -1.57079 2.35627</pose>
          <geometry>
            <mesh>
              <scale>1 1 1</scale>
              <uri>model://icub/meshes/visual/icub_r_hip_2.dae</uri>
            </mesh>
          </geometry>
        </visual>
        <self_collide>0</self_collide>
        <kinematic>0</kinematic>
      </link>
      <joint name='iCub::r_hip_roll' type='revolute'>
        <child>iCub::r_hip_2</child>
        <parent>iCub::r_hip_1</parent>
        <axis>
          <xyz>1 0 -7e-06</xyz>
          <limit>
            <lower>-0.296706</lower>
            <upper>2.07694</upper>
            <effort>84</effort>
            <velocity>100</velocity>
          </limit>
          <dynamics>
            <damping>1</damping>
            <friction>0</friction>
            <spring_reference>0</spring_reference>
            <spring_stiffness>0</spring_stiffness>
          </dynamics>
          <use_parent_model_frame>1</use_parent_model_frame>
        </axis>
      </joint>
      <link name='iCub::r_hip_3'>
        <pose frame=''>-0 0.0681 -0.1864 -3.14159 -7e-06 -3.14159</pose>
        <inertial>
          <pose frame=''>0 0 0 0 -0 0</pose>
          <mass>0.1</mass>
          <inertia>
            <ixx>0.01</ixx>
            <ixy>0</ixy>
            <ixz>0</ixz>
            <iyy>0.01</iyy>
            <iyz>0</iyz>
            <izz>0.01</izz>
          </inertia>
        </inertial>
        <self_collide>0</self_collide>
        <kinematic>0</kinematic>
      </link>
      <joint name='iCub::r_leg_ft_sensor' type='revolute'>
        <child>iCub::r_hip_3</child>
        <parent>iCub::r_hip_2</parent>
        <axis>
          <xyz>0 0 0</xyz>
          <limit>
            <lower>0</lower>
            <upper>0</upper>
            <effort>0</effort>
            <velocity>0</velocity>
          </limit>
          <dynamics>
            <spring_reference>0</spring_reference>
            <spring_stiffness>0</spring_stiffness>
          </dynamics>
          <use_parent_model_frame>1</use_parent_model_frame>
        </axis>
        <sensor name='right_leg_ft' type='force_torque'>
          <always_on>1</always_on>
          <update_rate>100</update_rate>
          <pose frame=''>0 0 0 0 -0 0</pose>
          <plugin name='right_leg_ft_plugin' filename='libgazebo_yarp_forcetorque.so'>
            <yarpConfigurationFile>model://icub/conf/FT/gazebo_icub_right_leg_ft.ini</yarpConfigurationFile>
          </plugin>
        </sensor>
      </joint>
      <link name='iCub::r_upper_leg'>
        <pose frame=''>0 0.0681 -0.1199 1.57079 -7e-06 3.14159</pose>
        <inertial>
          <pose frame=''>0.00144 -0.15943 0.00039 0 -0 0</pose>
          <mass>2.175</mass>
          <inertia>
            <ixx>0.01</ixx>
            <ixy>0</ixy>
            <ixz>0</ixz>
            <iyy>0.01</iyy>
            <iyz>-2.71051e-20</iyz>
            <izz>0.01</izz>
          </inertia>
        </inertial>
        <collision name='r_upper_leg_collision'>
          <pose frame=''>0 0 0 1.57087 -1.57079 -7.3e-05</pose>
          <geometry>
            <mesh>
              <scale>1 1 1</scale>
              <uri>model://icub/meshes/collision/icub_simple_collision_r_thigh.dae</uri>
            </mesh>
          </geometry>
          <max_contacts>4</max_contacts>
          <surface>
            <contact>
              <ode>
                <soft_erp>0.2</soft_erp>
                <soft_cfm>0</soft_cfm>
                <kp>1.8e+07</kp>
                <kd>100</kd>
                <max_vel>100</max_vel>
                <min_depth>0.0001</min_depth>
              </ode>
            </contact>
            <friction>
              <ode>
                <mu>1</mu>
                <mu2>1</mu2>
                <fdir1>0 0 0</fdir1>
                <slip1>0</slip1>
                <slip2>0</slip2>
              </ode>
              <torsional>
                <ode/>
              </torsional>
            </friction>
            <bounce>
              <restitution_coefficient>0</restitution_coefficient>
              <threshold>100000</threshold>
            </bounce>
          </surface>
        </collision>
        <visual name='r_upper_leg_visual'>
          <pose frame=''>0 0 0 1.57087 -1.57079 -7.3e-05</pose>
          <geometry>
            <mesh>
              <scale>1 1 1</scale>
              <uri>model://icub/meshes/visual/icub_r_thigh.dae</uri>
              <!-- <uri>model://icub/meshes/visual/icub_r_thigh_transparent.dae</uri> -->
            </mesh>
          </geometry>
        </visual>
        <self_collide>0</self_collide>
        <kinematic>0</kinematic>
      </link>
      <joint name='iCub::r_hip_yaw' type='revolute'>
        <child>iCub::r_upper_leg</child>
        <parent>iCub::r_hip_3</parent>
        <axis>
          <xyz>-7e-06 4e-06 -1</xyz>
          <limit>
            <lower>-1.37881</lower>
            <upper>1.37881</upper>
            <effort>40</effort>
            <velocity>100</velocity>
          </limit>
          <dynamics>
            <damping>1</damping>
            <friction>0</friction>
            <spring_reference>0</spring_reference>
            <spring_stiffness>0</spring_stiffness>
          </dynamics>
          <use_parent_model_frame>1</use_parent_model_frame>
        </axis>
      </joint>
      <link name='iCub::r_lower_leg'>
        <pose frame=''>-2e-06 0.068101 -0.3435 1.89254 -1.57078 -0.321751</pose>
        <inertial>
          <pose frame=''>-0.1071 0.00182 -0.00211 0 -0 0</pose>
          <mass>1.264</mass>
          <inertia>
            <ixx>0.01</ixx>
            <ixy>5.42101e-20</ixy>
            <ixz>-5.42101e-20</ixz>
            <iyy>0.01</iyy>
            <iyz>8.47033e-22</iyz>
            <izz>0.01</izz>
          </inertia>
        </inertial>
        <collision name='r_lower_leg_collision'>
          <pose frame=''>0 0 -0 3.14159 -0 1.5708</pose>
          <geometry>
            <mesh>
              <scale>1 1 1</scale>
              <uri>model://icub/meshes/collision/icub_simple_collision_r_shank.dae</uri>
            </mesh>
          </geometry>
          <max_contacts>10</max_contacts>
          <surface>
            <contact>
              <ode/>
            </contact>
            <bounce/>
            <friction>
              <torsional>
                <ode/>
              </torsional>
              <ode/>
            </friction>
          </surface>
        </collision>
        <visual name='r_lower_leg_visual'>
          <pose frame=''>0 0 -0 3.14159 -0 1.5708</pose>
          <geometry>
            <mesh>
              <scale>1 1 1</scale>
              <uri>model://icub/meshes/visual/icub_r_shank.dae</uri>
            </mesh>
          </geometry>
        </visual>
        <self_collide>0</self_collide>
        <kinematic>0</kinematic>
      </link>
      <joint name='iCub::r_knee' type='revolute'>
        <child>iCub::r_lower_leg</child>
        <parent>iCub::r_upper_leg</parent>
        <axis>
          <xyz>3e-06 1 4e-06</xyz>
          <limit>
            <lower>-2.18166</lower>
            <upper>0.401426</upper>
            <effort>30</effort>
            <velocity>100</velocity>
          </limit>
          <dynamics>
            <damping>1</damping>
            <friction>0</friction>
            <spring_reference>0</spring_reference>
            <spring_stiffness>0</spring_stiffness>
          </dynamics>
          <use_parent_model_frame>1</use_parent_model_frame>
        </axis>
      </joint>
      <link name='iCub::r_ankle_1'>
        <pose frame=''>-4e-06 0.068102 -0.5565 -2.81984 -1.57078 -0.321751</pose>
        <inertial>
          <pose frame=''>-0.0054 0.00163 -0.0172 0 -0 0</pose>
          <mass>0.746</mass>
          <inertia>
            <ixx>0.01</ixx>
            <ixy>-1.69407e-21</ixy>
            <ixz>1.35525e-20</ixz>
            <iyy>0.01</iyy>
            <iyz>3.38813e-21</iyz>
            <izz>0.01</izz>
          </inertia>
        </inertial>
        <collision name='r_ankle_1_collision'>
          <pose frame=''>0 -0 -0 -1.5708 -0 0</pose>
          <geometry>
            <mesh>
              <scale>1 1 1</scale>
              <uri>model://icub/meshes/collision/icub_simple_collision_r_ankle_1.dae</uri>
            </mesh>
          </geometry>
          <max_contacts>10</max_contacts>
          <surface>
            <contact>
              <ode/>
            </contact>
            <bounce/>
            <friction>
              <torsional>
                <ode/>
              </torsional>
              <ode/>
            </friction>
          </surface>
        </collision>
        <visual name='r_ankle_1_visual'>
          <pose frame=''>0 -0 -0 -1.5708 -0 0</pose>
          <geometry>
            <mesh>
              <scale>1 1 1</scale>
              <uri>model://icub/meshes/visual/icub_r_ankle_1.dae</uri>
            </mesh>
          </geometry>
        </visual>
        <self_collide>0</self_collide>
        <kinematic>0</kinematic>
      </link>
      <joint name='iCub::r_ankle_pitch' type='revolute'>
        <child>iCub::r_ankle_1</child>
        <parent>iCub::r_lower_leg</parent>
        <axis>
          <xyz>1e-06 -1 -4e-06</xyz>
          <limit>
            <lower>-0.733038</lower>
            <upper>0.366519</upper>
            <effort>24</effort>
            <velocity>100</velocity>
          </limit>
          <dynamics>
            <damping>1</damping>
            <friction>0</friction>
            <spring_reference>0</spring_reference>
            <spring_stiffness>0</spring_stiffness>
          </dynamics>
          <use_parent_model_frame>1</use_parent_model_frame>
        </axis>
      </joint>
      <link name='iCub::r_ankle_2'>
        <pose frame=''>-4e-06 0.068102 -0.5565 3.14159 -1.4e-05 -3.14159</pose>
        <inertial>
          <pose frame=''>0 0 0.037 0 -0 0</pose>
          <mass>0.2675</mass>
          <inertia>
            <ixx>0.01</ixx>
            <ixy>0</ixy>
            <ixz>0</ixz>
            <iyy>0.01</iyy>
            <iyz>0</iyz>
            <izz>0.01</izz>
          </inertia>
        </inertial>
        <self_collide>0</self_collide>
        <kinematic>0</kinematic>
      </link>
      <joint name='iCub::r_ankle_roll' type='revolute'>
        <child>iCub::r_ankle_2</child>
        <parent>iCub::r_ankle_1</parent>
        <axis>
          <xyz>1 3e-06 -1.4e-05</xyz>
          <limit>
            <lower>-0.418879</lower>
            <upper>0.418879</upper>
            <effort>11</effort>
            <velocity>100</velocity>
          </limit>
          <dynamics>
            <damping>1</damping>
            <friction>0</friction>
            <spring_reference>0</spring_reference>
            <spring_stiffness>0</spring_stiffness>
          </dynamics>
          <use_parent_model_frame>1</use_parent_model_frame>
        </axis>
      </joint>
      <link name='iCub::r_foot'>
        <pose frame=''>-5e-06 0.068102 -0.5935 3.14159 -1.4e-05 -3.14159</pose>
        <inertial>
          <pose frame=''>0.024069 0.000614 -0.028415 0 -0 0</pose>
          <mass>0.5935</mass>
          <inertia>
            <ixx>0.01</ixx>
            <ixy>4.51893e-06</ixy>
            <ixz>0.000567784</ixz>
            <iyy>0.01</iyy>
            <iyz>6.62535e-07</iyz>
            <izz>0.01</izz>
          </inertia>
        </inertial>
        <collision name='r_foot_collision'>
          <pose frame=''>0.03 0 -0.01 0 -0 0</pose>
          <geometry>
            <box>
              <size>0.15 0.07 0.03</size>
            </box>
          </geometry>
          <max_contacts>4</max_contacts>
          <surface>
            <contact>
              <ode>
                <soft_erp>0.2</soft_erp>
                <soft_cfm>0</soft_cfm>
                <kp>1.8e+07</kp>
                <kd>100</kd>
                <max_vel>100</max_vel>
                <min_depth>0.0001</min_depth>
              </ode>
            </contact>
            <friction>
              <ode>
                <mu>1</mu>
                <mu2>1</mu2>
                <fdir1>0 0 0</fdir1>
                <slip1>0</slip1>
                <slip2>0</slip2>
              </ode>
              <torsional>
                <ode/>
              </torsional>
            </friction>
            <bounce>
              <restitution_coefficient>0</restitution_coefficient>
              <threshold>100000</threshold>
            </bounce>
          </surface>
        </collision>
        <visual name='r_foot_visual'>
          <pose frame=''>0 0 -0.037 -2.81983 1.57079 0.321763</pose>
          <geometry>
            <mesh>
              <scale>1 1 1</scale>
              <uri>model://icub/meshes/visual/icub_r_foot.dae</uri>
            </mesh>
          </geometry>
        </visual>
        <self_collide>0</self_collide>
        <kinematic>0</kinematic>
      </link>
      <joint name='iCub::r_foot_ft_sensor' type='revolute'>
        <child>iCub::r_foot</child>
        <parent>iCub::r_ankle_2</parent>
        <axis>
          <xyz>0 0 0</xyz>
          <limit>
            <lower>0</lower>
            <upper>0</upper>
            <effort>0</effort>
            <velocity>0</velocity>
          </limit>
          <dynamics>
            <spring_reference>0</spring_reference>
            <spring_stiffness>0</spring_stiffness>
          </dynamics>
          <use_parent_model_frame>1</use_parent_model_frame>
        </axis>
        <sensor name='right_foot_ft' type='force_torque'>
          <always_on>1</always_on>
          <update_rate>100</update_rate>
          <pose frame=''>0 0 0 0 -0 0</pose>
          <plugin name='right_foot_ft_plugin' filename='libgazebo_yarp_forcetorque.so'>
            <yarpConfigurationFile>model://icub/conf/FT/gazebo_icub_right_foot_ft.ini</yarpConfigurationFile>
          </plugin>
        </sensor>
      </joint>
      <link name='iCub::torso_1'>
        <pose frame=''>0 0 0 3.14159 -1.57079 -3e-06</pose>
        <inertial>
          <pose frame=''>0 0 0 0 -0 0</pose>
          <mass>0.1</mass>
          <inertia>
            <ixx>0.01</ixx>
            <ixy>-4.263e-05</ixy>
            <ixz>-3.889e-08</ixz>
            <iyy>0.01</iyy>
            <iyz>0</iyz>
            <izz>0.01</izz>
          </inertia>
        </inertial>
        <collision name='torso_1_collision'>
          <pose frame=''>0 0 0 -1.5708 0 0</pose>
          <geometry>
            <mesh>
              <scale>1 1 1</scale>
              <uri>model://icub/meshes/collision/icub_simple_collision_lap_belt_1.dae</uri>
            </mesh>
          </geometry>
          <max_contacts>10</max_contacts>
          <surface>
            <contact>
              <ode/>
            </contact>
            <bounce/>
            <friction>
              <torsional>
                <ode/>
              </torsional>
              <ode/>
            </friction>
          </surface>
        </collision>
        <visual name='torso_1_visual'>
          <pose frame=''>0 0 0 -1.5708 0 0</pose>
          <geometry>
            <mesh>
              <scale>1 1 1</scale>
              <uri>model://icub/meshes/visual/icub_lap_belt_1.dae</uri>
            </mesh>
          </geometry>
        </visual>
        <self_collide>0</self_collide>
        <kinematic>0</kinematic>
      </link>
      <joint name='iCub::torso_pitch' type='revolute'>
        <child>iCub::torso_1</child>
        <parent>iCub::root_link</parent>
        <axis>
          <xyz>-3e-06 -1 0</xyz>
          <limit>
            <lower>-0.383972</lower>
            <upper>1.46608</upper>
            <effort>36</effort>
            <velocity>100</velocity>
          </limit>
          <dynamics>
            <damping>1</damping>
            <friction>0</friction>
            <spring_reference>0</spring_reference>
            <spring_stiffness>0</spring_stiffness>
          </dynamics>
          <use_parent_model_frame>1</use_parent_model_frame>
        </axis>
      </joint>
      <link name='iCub::torso_2'>
        <pose frame=''>0 -0 0.032 -3.14159 4e-06 1.57079</pose>
        <inertial>
          <pose frame=''>0 0 0 0 -0 0</pose>
          <mass>0.1</mass>
          <inertia>
            <ixx>0.01</ixx>
            <ixy>-1.923e-06</ixy>
            <ixz>5.095e-05</ixz>
            <iyy>0.01</iyy>
            <iyz>-3.849e-07</iyz>
            <izz>0.01</izz>
          </inertia>
        </inertial>
        <self_collide>0</self_collide>
        <kinematic>0</kinematic>
      </link>
      <joint name='iCub::torso_roll' type='revolute'>
        <child>iCub::torso_2</child>
        <parent>iCub::torso_1</parent>
        <axis>
          <xyz>1 -3e-06 -7e-06</xyz>
          <limit>
            <lower>-0.680678</lower>
            <upper>0.680678</upper>
            <effort>80</effort>
            <velocity>100</velocity>
          </limit>
          <dynamics>
            <damping>1</damping>
            <friction>0</friction>
            <spring_reference>0</spring_reference>
            <spring_stiffness>0</spring_stiffness>
          </dynamics>
          <use_parent_model_frame>1</use_parent_model_frame>
        </axis>
      </joint>
      <link name='iCub::chest'>
        <pose frame=''>-0.0055 0 0.032 1.5708 -7e-06 -3.14159</pose>
        <inertial>
          <pose frame=''>0.002229 0.075 -0 0 -0 0</pose>
          <mass>4.81</mass>
          <inertia>
            <ixx>0.07472</ixx>
            <ixy>-3.6e-06</ixy>
            <ixz>-4.705e-05</ixz>
            <iyy>0.08145</iyy>
            <iyz>0.004567</iyz>
            <izz>0.01306</izz>
          </inertia>
        </inertial>
        <collision name='chest_collision'>
          <pose frame=''>-0.0055 -0 -0 -1.10717 -1.57079 2.67798</pose>
          <geometry>
            <mesh>
              <scale>1 1 1</scale>
              <uri>model://icub/meshes/collision/icub_simple_collision_chest.dae</uri>
            </mesh>
          </geometry>
          <max_contacts>10</max_contacts>
          <surface>
            <contact>
              <ode/>
            </contact>
            <bounce/>
            <friction>
              <torsional>
                <ode/>
              </torsional>
              <ode/>
            </friction>
          </surface>
        </collision>
        <visual name='chest_visual'>
          <pose frame=''>-0.0055 -0 -0 -1.10717 -1.57079 2.67798</pose>
          <geometry>
            <mesh>
              <scale>1 1 1</scale>
              <uri>model://icub/meshes/visual/icub_chest.dae</uri>
            </mesh>
          </geometry>
        </visual>
        <self_collide>0</self_collide>
        <kinematic>0</kinematic>
      </link>
      <joint name='iCub::torso_yaw' type='revolute'>
        <child>iCub::chest</child>
        <parent>iCub::torso_2</parent>
        <axis>
          <xyz>-7e-06 0 -1</xyz>
          <limit>
            <lower>-1.02974</lower>
            <upper>1.02974</upper>
            <effort>80</effort>
            <velocity>100</velocity>
          </limit>
          <dynamics>
            <damping>1</damping>
            <friction>0</friction>
            <spring_reference>0</spring_reference>
            <spring_stiffness>0</spring_stiffness>
          </dynamics>
          <use_parent_model_frame>1</use_parent_model_frame>
        </axis>
      </joint>
      <link name='iCub::l_shoulder_1'>
        <pose frame=''>-0.010749 -0.11026 0.1753 -0.261794 -1.57079 -1e-06</pose>
        <inertial>
          <pose frame=''>-5e-06 0.0187 -0.00119 0 -0 0</pose>
          <mass>0.189</mass>
          <inertia>
            <ixx>0.01</ixx>
            <ixy>9e-09</ixy>
            <ixz>0</ixz>
            <iyy>0.01</iyy>
            <iyz>-1.7e-08</iyz>
            <izz>0.01</izz>
          </inertia>
        </inertial>
        <collision name='l_shoulder_1_collision'>
          <pose frame=''>0 0.109285 -0.005211 -0.301063 1.57079 -1.87186</pose>
          <geometry>
            <mesh>
              <scale>1 1 1</scale>
              <uri>model://icub/meshes/collision/icub_simple_collision_l_shoulder_1.dae</uri>
            </mesh>
          </geometry>
          <max_contacts>10</max_contacts>
          <surface>
            <contact>
              <ode/>
            </contact>
            <bounce/>
            <friction>
              <torsional>
                <ode/>
              </torsional>
              <ode/>
            </friction>
          </surface>
        </collision>
        <visual name='l_shoulder_1_visual'>
          <pose frame=''>0 0.109285 -0.005211 -0.301063 1.57079 -1.87186</pose>
          <geometry>
            <mesh>
              <scale>1 1 1</scale>
              <uri>model://icub/meshes/visual/icub_l_shoulder_1.dae</uri>
            </mesh>
          </geometry>
        </visual>
        <self_collide>0</self_collide>
        <kinematic>0</kinematic>
      </link>
      <joint name='iCub::l_shoulder_pitch' type='revolute'>
        <child>iCub::l_shoulder_1</child>
        <parent>iCub::chest</parent>
        <axis>
          <xyz>-0.258815 -0.965927 3e-06</xyz>
          <limit>
            <lower>-1.65806</lower>
            <upper>0.0872665</upper>
            <effort>84</effort>
            <velocity>100</velocity>
          </limit>
          <dynamics>
            <damping>1</damping>
            <friction>0</friction>
            <spring_reference>0</spring_reference>
            <spring_stiffness>0</spring_stiffness>
          </dynamics>
          <use_parent_model_frame>1</use_parent_model_frame>
        </axis>
      </joint>
      <link name='iCub::l_shoulder_2'>
        <pose frame=''>-0.010749 -0.11026 0.1753 3.14159 1e-06 -1.83259</pose>
        <inertial>
          <pose frame=''>9.4e-05 -0.00627 0.0166 0 -0 0</pose>
          <mass>0.179</mass>
          <inertia>
            <ixx>0.01</ixx>
            <ixy>4.66e-07</ixy>
            <ixz>3.65e-07</ixz>
            <iyy>0.01</iyy>
            <iyz>-2.0524e-05</iyz>
            <izz>0.01</izz>
          </inertia>
        </inertial>
        <collision name='l_shoulder_2_collision'>
          <pose frame=''>-0.001545 -0.005211 -0 -2.14033 1.57079 -0.569533</pose>
          <geometry>
            <mesh>
              <scale>1 1 1</scale>
              <uri>model://icub/meshes/collision/icub_simple_collision_l_shoulder_2.dae</uri>
            </mesh>
          </geometry>
          <max_contacts>10</max_contacts>
          <surface>
            <contact>
              <ode/>
            </contact>
            <bounce/>
            <friction>
              <torsional>
                <ode/>
              </torsional>
              <ode/>
            </friction>
          </surface>
        </collision>
        <visual name='l_shoulder_2_visual'>
          <pose frame=''>-0.001545 -0.005211 -0 -2.14033 1.57079 -0.569533</pose>
          <geometry>
            <mesh>
              <scale>1 1 1</scale>
              <uri>model://icub/meshes/visual/icub_l_shoulder_2.dae</uri>
            </mesh>
          </geometry>
        </visual>
        <self_collide>0</self_collide>
        <kinematic>0</kinematic>
      </link>
      <joint name='iCub::l_shoulder_roll' type='revolute'>
        <child>iCub::l_shoulder_2</child>
        <parent>iCub::l_shoulder_1</parent>
        <axis>
          <xyz>-0.965927 0.258815 7e-06</xyz>
          <limit>
            <lower>0</lower>
            <upper>2.80649</upper>
            <effort>84</effort>
            <velocity>100</velocity>
          </limit>
          <dynamics>
            <damping>1</damping>
            <friction>0</friction>
            <spring_reference>0</spring_reference>
            <spring_stiffness>0</spring_stiffness>
          </dynamics>
          <use_parent_model_frame>1</use_parent_model_frame>
        </axis>
      </joint>
      <link name='iCub::l_shoulder_3'>
        <pose frame=''>-0.010749 -0.11026 0.1753 3.14159 -7e-06 -3.14159</pose>
        <inertial>
          <pose frame=''>0.005594 9.8e-05 0.050135 0 -0 0</pose>
          <mass>0.156157</mass>
          <inertia>
            <ixx>0.01</ixx>
            <ixy>-5.662e-08</ixy>
            <ixz>-4.3618e-06</ixz>
            <iyy>0.01</iyy>
            <iyz>-7.42844e-07</iyz>
            <izz>0.01</izz>
          </inertia>
        </inertial>
        <self_collide>0</self_collide>
        <kinematic>0</kinematic>
      </link>
      <joint name='iCub::l_shoulder_yaw' type='revolute'>
        <child>iCub::l_shoulder_3</child>
        <parent>iCub::l_shoulder_2</parent>
        <axis>
          <xyz>-7e-06 3e-06 -1</xyz>
          <limit>
            <lower>-0.645772</lower>
            <upper>1.74533</upper>
            <effort>34</effort>
            <velocity>100</velocity>
          </limit>
          <dynamics>
            <damping>1</damping>
            <friction>0</friction>
            <spring_reference>0</spring_reference>
            <spring_stiffness>0</spring_stiffness>
          </dynamics>
          <use_parent_model_frame>1</use_parent_model_frame>
        </axis>
      </joint>
      <link name='iCub::l_upper_arm'>
        <pose frame=''>-0.025749 -0.11026 0.1073 3.14159 -7e-06 -3.14159</pose>
        <inertial>
          <pose frame=''>-0.000156 -9.9e-05 0.0298 0 -0 0</pose>
          <mass>0.727843</mass>
          <inertia>
            <ixx>0.01</ixx>
            <ixy>-1.08e-06</ixy>
            <ixz>-2.29e-06</ixz>
            <iyy>0.01</iyy>
            <iyz>3.57e-06</iyz>
            <izz>0.01</izz>
          </inertia>
        </inertial>
        <collision name='l_upper_arm_collision'>
          <pose frame=''>-0.020433 0.000144 -0.068 0 0 -1.309</pose>
          <geometry>
            <mesh>
              <scale>1 1 1</scale>
              <uri>model://icub/meshes/collision/icub_simple_collision_l_arm.dae</uri>
            </mesh>
          </geometry>
          <max_contacts>10</max_contacts>
          <surface>
            <contact>
              <ode/>
            </contact>
            <bounce/>
            <friction>
              <torsional>
                <ode/>
              </torsional>
              <ode/>
            </friction>
          </surface>
        </collision>
        <visual name='l_upper_arm_visual'>
          <pose frame=''>-0.020433 0.000144 -0.068 0 0 -1.309</pose>
          <geometry>
            <mesh>
              <scale>1 1 1</scale>
              <uri>model://icub/meshes/visual/icub_l_arm.dae</uri>
            </mesh>
          </geometry>
        </visual>
        <self_collide>0</self_collide>
        <kinematic>0</kinematic>
      </link>
      <joint name='iCub::l_arm_ft_sensor' type='revolute'>
        <child>iCub::l_upper_arm</child>
        <parent>iCub::l_shoulder_3</parent>
        <axis>
          <xyz>0 0 0</xyz>
          <limit>
            <lower>0</lower>
            <upper>0</upper>
            <effort>0</effort>
            <velocity>0</velocity>
          </limit>
          <dynamics>
            <spring_reference>0</spring_reference>
            <spring_stiffness>0</spring_stiffness>
          </dynamics>
          <use_parent_model_frame>1</use_parent_model_frame>
        </axis>
        <sensor name='left_arm_ft' type='force_torque'>
          <always_on>1</always_on>
          <update_rate>100</update_rate>
          <pose frame=''>0 0 0 0 -0 0</pose>
          <plugin name='left_arm_ft_plugin' filename='libgazebo_yarp_forcetorque.so'>
            <yarpConfigurationFile>model://icub/conf/FT/gazebo_icub_left_arm_ft.ini</yarpConfigurationFile>
          </plugin>
        </sensor>
      </joint>
      <link name='iCub::l_elbow_1'>
        <pose frame=''>-0.02575 -0.11026 0.02302 3.14159 -7e-06 -3.14159</pose>
        <inertial>
          <pose frame=''>-0.0013 0.00371 -0.00105 0 -0 0</pose>
          <mass>0.1</mass>
          <inertia>
            <ixx>0.01</ixx>
            <ixy>-5.15e-07</ixy>
            <ixz>-4.08e-07</ixz>
            <iyy>0.01</iyy>
            <iyz>-3.71e-07</iyz>
            <izz>0.01</izz>
          </inertia>
        </inertial>
        <self_collide>0</self_collide>
        <kinematic>0</kinematic>
      </link>
      <joint name='iCub::l_elbow' type='revolute'>
        <child>iCub::l_elbow_1</child>
        <parent>iCub::l_upper_arm</parent>
        <axis>
          <xyz>-1e-06 1 3e-06</xyz>
          <limit>
            <lower>0.0959931</lower>
            <upper>1.85005</upper>
            <effort>20</effort>
            <velocity>100</velocity>
          </limit>
          <dynamics>
            <damping>1</damping>
            <friction>0</friction>
            <spring_reference>0</spring_reference>
            <spring_stiffness>0</spring_stiffness>
          </dynamics>
          <use_parent_model_frame>1</use_parent_model_frame>
        </axis>
      </joint>
      <link name='iCub::l_forearm'>
        <pose frame=''>-0.01075 -0.11026 0.02302 -1.5708 3e-06 -1.57079</pose>
        <inertial>
          <pose frame=''>0.000347 0.066 0.00476 0 -0 0</pose>
          <mass>0.525</mass>
          <inertia>
            <ixx>0.01</ixx>
            <ixy>4.337e-06</ixy>
            <ixz>2.39e-07</ixz>
            <iyy>0.01</iyy>
            <iyz>1.9381e-05</iyz>
            <izz>0.01</izz>
          </inertia>
        </inertial>
        <collision name='l_forearm_collision'>
          <pose frame=''>-0.000144 -0 0.020433 -2.66395 1.57079 -1.09315</pose>
          <geometry>
            <mesh>
              <scale>1 1 1</scale>
              <uri>model://icub/meshes/collision/icub_simple_collision_l_forearm.dae</uri>
            </mesh>
          </geometry>
          <max_contacts>10</max_contacts>
          <surface>
            <contact>
              <ode/>
            </contact>
            <bounce/>
            <friction>
              <torsional>
                <ode/>
              </torsional>
              <ode/>
            </friction>
          </surface>
        </collision>
        <visual name='l_forearm_visual'>
          <pose frame=''>-0.000144 -0 0.020433 -2.66395 1.57079 -1.09315</pose>
          <geometry>
            <mesh>
              <scale>1 1 1</scale>
              <uri>model://icub/meshes/visual/icub_l_forearm.dae</uri>
            </mesh>
          </geometry>
        </visual>
        <self_collide>0</self_collide>
        <kinematic>0</kinematic>
      </link>
      <joint name='iCub::l_wrist_prosup' type='revolute'>
        <child>iCub::l_forearm</child>
        <parent>iCub::l_elbow_1</parent>
        <axis>
          <xyz>-3e-06 3e-06 -1</xyz>
          <limit>
            <lower>-0.872665</lower>
            <upper>0.872665</upper>
            <effort>0.45</effort>
            <velocity>100</velocity>
          </limit>
          <dynamics>
            <damping>1</damping>
            <friction>0</friction>
            <spring_reference>0</spring_reference>
            <spring_stiffness>0</spring_stiffness>
          </dynamics>
          <use_parent_model_frame>1</use_parent_model_frame>
        </axis>
      </joint>
      <link name='iCub::l_wrist_1'>
        <pose frame=''>-0.01075 -0.110259 -0.11428 -2.7153 1.57079 1.99709</pose>
        <inertial>
          <pose frame=''>0 0 0 0 -0 0</pose>
          <mass>0.1</mass>
          <inertia>
            <ixx>0.01</ixx>
            <ixy>0</ixy>
            <ixz>0</ixz>
            <iyy>0.01</iyy>
            <iyz>0</iyz>
            <izz>0.01</izz>
          </inertia>
        </inertial>
        <self_collide>0</self_collide>
        <kinematic>0</kinematic>
      </link>
      <joint name='iCub::l_wrist_pitch' type='revolute'>
        <child>iCub::l_wrist_1</child>
        <parent>iCub::l_forearm</parent>
        <axis>
          <xyz>1 1e-06 -3e-06</xyz>
          <limit>
            <lower>-1.13446</lower>
            <upper>0.174533</upper>
            <effort>0.65</effort>
            <velocity>100</velocity>
          </limit>
          <dynamics>
            <damping>1</damping>
            <friction>0</friction>
            <spring_reference>0</spring_reference>
            <spring_stiffness>0</spring_stiffness>
          </dynamics>
          <use_parent_model_frame>1</use_parent_model_frame>
        </axis>
      </joint>
      <link name='iCub::l_hand'>
        <pose frame=''>-0.01075 -0.110259 -0.11428 -2.7153 1.57079 1.99709</pose>
        <inertial>
          <pose frame=''>0.07023 -0.00805 -0.007 0 -0 0</pose>
          <mass>0.213</mass>
          <inertia>
            <ixx>0.01</ixx>
            <ixy>1.278e-05</ixy>
            <ixz>4.823e-06</ixz>
            <iyy>0.01</iyy>
            <iyz>-1.8188e-05</iyz>
            <izz>0.01</izz>
          </inertia>
        </inertial>
        <collision name='l_hand_collision'>
          <pose frame=''>-0 0.020433 -0.000144 0 -0 0</pose>
          <geometry>
            <mesh>
              <scale>1 1 1</scale>
              <uri>model://icub/meshes/collision/icub_simple_collision_l_hand.dae</uri>
            </mesh>
          </geometry>
          <max_contacts>10</max_contacts>
          <surface>
            <contact>
              <ode/>
            </contact>
            <bounce/>
            <friction>
              <torsional>
                <ode/>
              </torsional>
              <ode/>
            </friction>
          </surface>
        </collision>
        <visual name='l_hand_visual'>
          <pose frame=''>-0 0.020433 -0.000144 0 -0 0</pose>
          <geometry>
            <mesh>
              <scale>1 1 1</scale>
              <uri>model://icub/meshes/visual/icub_l_hand.dae</uri>
            </mesh>
          </geometry>
        </visual>
        <self_collide>0</self_collide>
        <kinematic>0</kinematic>
      </link>
      <joint name='iCub::l_wrist_yaw' type='revolute'>
        <child>iCub::l_hand</child>
        <parent>iCub::l_wrist_1</parent>
        <axis>
          <xyz>1e-06 -1 -6e-06</xyz>
          <limit>
            <lower>-0.436332</lower>
            <upper>0.436332</upper>
            <effort>0.65</effort>
            <velocity>100</velocity>
          </limit>
          <dynamics>
            <damping>1</damping>
            <friction>0</friction>
            <spring_reference>0</spring_reference>
            <spring_stiffness>0</spring_stiffness>
          </dynamics>
          <use_parent_model_frame>1</use_parent_model_frame>
        </axis>
      </joint>
      <link name='iCub::neck_1'>
        <pose frame=''>-0.007808 0 0.2253 6e-06 -1.57079 -1e-06</pose>
        <inertial>
          <pose frame=''>0 0 0 0 -0 0</pose>
          <mass>0.1</mass>
          <inertia>
            <ixx>0.01</ixx>
            <ixy>0</ixy>
            <ixz>0</ixz>
            <iyy>0.01</iyy>
            <iyz>0</iyz>
            <izz>0.01</izz>
          </inertia>
        </inertial>
        <collision name='neck_1_collision'>
          <pose frame=''>-0 0 -0.0055 3.14159 -1.57079 1.5708</pose>
          <geometry>
            <mesh>
              <scale>1 1 1</scale>
              <uri>model://icub/meshes/collision/icub_simple_collision_neck_1.dae</uri>
            </mesh>
          </geometry>
          <max_contacts>10</max_contacts>
          <surface>
            <contact>
              <ode/>
            </contact>
            <bounce/>
            <friction>
              <torsional>
                <ode/>
              </torsional>
              <ode/>
            </friction>
          </surface>
        </collision>
        <visual name='neck_1_visual'>
          <pose frame=''>-0 0 -0.0055 3.14159 -1.57079 1.5708</pose>
          <geometry>
            <mesh>
              <scale>1 1 1</scale>
              <uri>model://icub/meshes/visual/icub_neck_1.dae</uri>
            </mesh>
          </geometry>
        </visual>
        <self_collide>0</self_collide>
        <kinematic>0</kinematic>
      </link>
      <joint name='iCub::neck_pitch' type='revolute'>
        <child>iCub::neck_1</child>
        <parent>iCub::chest</parent>
        <axis>
          <xyz>-5e-06 1 0</xyz>
          <limit>
            <lower>-0.523599</lower>
            <upper>0.383972</upper>
            <effort>20</effort>
            <velocity>100</velocity>
          </limit>
          <dynamics>
            <damping>1</damping>
            <friction>0</friction>
            <spring_reference>0</spring_reference>
            <spring_stiffness>0</spring_stiffness>
          </dynamics>
          <use_parent_model_frame>1</use_parent_model_frame>
        </axis>
        <physics>
          <ode>
            <implicit_spring_damper>1</implicit_spring_damper>
            <cfm_damping>1</cfm_damping>
            <limit>
              <cfm>0</cfm>
              <erp>0.2</erp>
            </limit>
          </ode>
        </physics>
      </joint>
      <link name='iCub::neck_2'>
        <pose frame=''>-0.007808 0 0.2348 -1.5e-05 4e-06 -1.57079</pose>
        <inertial>
          <pose frame=''>0 0 0 0 -0 0</pose>
          <mass>0.1</mass>
          <inertia>
            <ixx>0.01</ixx>
            <ixy>0</ixy>
            <ixz>0</ixz>
            <iyy>0.01</iyy>
            <iyz>0</iyz>
            <izz>0.01</izz>
          </inertia>
        </inertial>
        <collision name='neck_2_collision'>
          <pose frame=''>-0 0.0055 0.0235 -3.14157 -1.57079 -1.57082</pose>
          <geometry>
            <mesh>
              <scale>1 1 1</scale>
              <uri>model://icub/meshes/collision/icub_simple_collision_neck_2.dae</uri>
            </mesh>
          </geometry>
          <max_contacts>10</max_contacts>
          <surface>
            <contact>
              <ode/>
            </contact>
            <bounce/>
            <friction>
              <torsional>
                <ode/>
              </torsional>
              <ode/>
            </friction>
          </surface>
        </collision>
        <visual name='neck_2_visual'>
          <pose frame=''>-0 0.0055 0.0235 -3.14157 -1.57079 -1.57082</pose>
          <geometry>
            <mesh>
              <scale>1 1 1</scale>
              <uri>model://icub/meshes/visual/icub_neck_2.dae</uri>
            </mesh>
          </geometry>
        </visual>
        <self_collide>0</self_collide>
        <kinematic>0</kinematic>
      </link>
      <joint name='iCub::neck_roll' type='revolute'>
        <child>iCub::neck_2</child>
        <parent>iCub::neck_1</parent>
        <axis>
          <xyz>-1 -5e-06 1.5e-05</xyz>
          <limit>
            <lower>-0.349066</lower>
            <upper>0.349066</upper>
            <effort>20</effort>
            <velocity>100</velocity>
          </limit>
          <dynamics>
            <damping>1</damping>
            <friction>0</friction>
            <spring_reference>0</spring_reference>
            <spring_stiffness>0</spring_stiffness>
          </dynamics>
          <use_parent_model_frame>1</use_parent_model_frame>
        </axis>
        <physics>
          <ode>
            <implicit_spring_damper>1</implicit_spring_damper>
            <cfm_damping>1</cfm_damping>
            <limit>
              <cfm>0</cfm>
              <erp>0.2</erp>
            </limit>
          </ode>
        </physics>
      </joint>
      <link name='iCub::head'>
        <pose frame=''>-0.007808 0 0.2348 -1.5708 1.5e-05 8e-06</pose>
        <inertial>
          <pose frame=''>0.0185 -0.1108 0 0 -0 0</pose>
          <mass>3</mass>
          <inertia>
            <ixx>0.01</ixx>
            <ixy>0</ixy>
            <ixz>0</ixz>
            <iyy>0.01</iyy>
            <iyz>0</iyz>
            <izz>0.01</izz>
          </inertia>
        </inertial>
        <collision name='head_collision'>
          <pose frame=''>0.0045 -0.0235 0 -1.32582 1.57079 -2.89662</pose>
          <geometry>
            <mesh>
              <scale>1 1 1</scale>
              <uri>model://icub/meshes/collision/icub_simple_collision_head.dae</uri>
            </mesh>
          </geometry>
          <max_contacts>10</max_contacts>
          <surface>
            <contact>
              <ode/>
            </contact>
            <bounce/>
            <friction>
              <torsional>
                <ode/>
              </torsional>
              <ode/>
            </friction>
          </surface>
        </collision>
        <visual name='head_visual'>
          <pose frame=''>0.0045 -0.0235 0 -2.89662 1.57079 -2.89662</pose>
          <geometry>
            <mesh>
              <scale>1 1 1</scale>
              <uri>model://icub/meshes/visual/icub_head_without_eyes.dae</uri>
            </mesh>
          </geometry>
        </visual>
        <sensor name='imu_sensor' type='imu'>
          <always_on>1</always_on>
          <update_rate>100</update_rate>
          <visualize>1</visualize>
          <imu>
            <angular_velocity/>
            <linear_acceleration/>
          </imu>
          <plugin name='iCub_yarp_gazebo_plugin_IMU' filename='libgazebo_yarp_imu.so'>
            <yarpConfigurationFile>model://icub/conf/gazebo_icub_inertial.ini</yarpConfigurationFile>
          </plugin>
          <pose frame=''>0.0185 -0.1108 0.0066 1.5708 -0 0</pose>
        </sensor>
        <self_collide>0</self_collide>
        <kinematic>0</kinematic>
      </link>
      <joint name='iCub::neck_yaw' type='revolute'>
        <child>iCub::head</child>
        <parent>iCub::neck_2</parent>
        <axis>
          <xyz>1.5e-05 0 1</xyz>
          <limit>
            <lower>-0.767945</lower>
            <upper>0.767945</upper>
            <effort>20</effort>
            <velocity>100</velocity>
          </limit>
          <dynamics>
            <damping>1</damping>
            <friction>0</friction>
            <spring_reference>0</spring_reference>
            <spring_stiffness>0</spring_stiffness>
          </dynamics>
          <use_parent_model_frame>1</use_parent_model_frame>
        </axis>
        <physics>
          <ode>
            <implicit_spring_damper>1</implicit_spring_damper>
            <cfm_damping>1</cfm_damping>
            <limit>
              <cfm>0</cfm>
              <erp>0.2</erp>
            </limit>
          </ode>
        </physics>
      </joint>
      <link name='iCub::eyes_tilt_link'>
        <pose frame=''>-0.06281 0 0.3408 1.57079 -0 0</pose>
        <inertial>
          <pose frame=''>0 0 0 0 -0 0</pose>
          <mass>0.01</mass>
          <inertia>
            <ixx>0.001</ixx>
            <ixy>0</ixy>
            <ixz>0</ixz>
            <iyy>0.001</iyy>
            <iyz>0</iyz>
            <izz>0.001</izz>
          </inertia>
        </inertial>
        <self_collide>0</self_collide>
        <kinematic>0</kinematic>
      </link>
      <link name='iCub::left_eye_link'>
        <pose frame=''>-0.06281 -0.034 0.3408 -3.14159 0 0</pose>
        <inertial>
          <pose frame=''>0 0 0 0 -0 0</pose>
          <mass>0.01</mass>
          <inertia>
            <ixx>0.001</ixx>
            <ixy>0</ixy>
            <ixz>0</ixz>
            <iyy>0.001</iyy>
            <iyz>0</iyz>
            <izz>0.001</izz>
          </inertia>
        </inertial>
        <visual name='left_eye_visual'>
          <pose frame=''>0.055 0.033 -0.14 0 -0 0</pose>
          <geometry>
            <mesh>
              <scale>1 1 1</scale>
              <uri>model://icub/meshes/visual/icub_eye.dae</uri>
            </mesh>
          </geometry>
        </visual>
        <self_collide>0</self_collide>
        <kinematic>0</kinematic>
      </link>
      <link name='iCub::right_eye_link'>
        <pose frame=''>-0.06281 0.034 0.3408 -3.14159 0 0</pose>
        <inertial>
          <pose frame=''>0 0 0 0 -0 0</pose>
          <mass>0.01</mass>
          <inertia>
            <ixx>0.001</ixx>
            <ixy>0</ixy>
            <ixz>0</ixz>
            <iyy>0.001</iyy>
            <iyz>0</iyz>
            <izz>0.001</izz>
          </inertia>
        </inertial>
        <visual name='right_eye_visual'>
          <pose frame=''>0.055 0.033 -0.14 0 -0 0</pose>
          <geometry>
            <mesh>
              <scale>1 1 1</scale>
              <uri>model://icub/meshes/visual/icub_eye.dae</uri>
            </mesh>
          </geometry>
        </visual>
        <self_collide>0</self_collide>
        <kinematic>0</kinematic>
      </link>
      <joint name='iCub::eyes_tilt' type='revolute'>
        <child>iCub::eyes_tilt_link</child>
        <parent>iCub::head</parent>
        <axis>
          <xyz>0 1 0</xyz>
          <limit>
            <lower>-1.5708</lower>
            <upper>1.5708</upper>
            <effort>84</effort>
            <velocity>100</velocity>
          </limit>
          <dynamics>
            <damping>1</damping>
            <friction>0</friction>
            <spring_reference>0</spring_reference>
            <spring_stiffness>0</spring_stiffness>
          </dynamics>
          <use_parent_model_frame>1</use_parent_model_frame>
        </axis>
        <physics>
          <ode>
            <implicit_spring_damper>1</implicit_spring_damper>
            <cfm_damping>1</cfm_damping>
            <limit>
              <cfm>0</cfm>
              <erp>0.2</erp>
            </limit>
          </ode>
        </physics>
      </joint>
      <joint name='iCub::left_eye' type='revolute'>
        <child>iCub::left_eye_link</child>
        <parent>iCub::eyes_tilt_link</parent>
        <axis>
          <xyz>0 0 1</xyz>
          <limit>
            <lower>-1.5708</lower>
            <upper>1.5708</upper>
            <effort>84</effort>
            <velocity>100</velocity>
          </limit>
          <dynamics>
            <damping>1</damping>
            <friction>0</friction>
            <spring_reference>0</spring_reference>
            <spring_stiffness>0</spring_stiffness>
          </dynamics>
          <use_parent_model_frame>1</use_parent_model_frame>
        </axis>
        <physics>
          <ode>
            <implicit_spring_damper>1</implicit_spring_damper>
            <cfm_damping>1</cfm_damping>
            <limit>
              <cfm>0</cfm>
              <erp>0.2</erp>
            </limit>
          </ode>
        </physics>
      </joint>
      <joint name='iCub::right_eye' type='revolute'>
        <child>iCub::right_eye_link</child>
        <parent>iCub::eyes_tilt_link</parent>
        <axis>
          <xyz>0 0 1</xyz>
          <limit>
            <lower>-1.5708</lower>
            <upper>1.5708</upper>
            <effort>84</effort>
            <velocity>100</velocity>
          </limit>
          <dynamics>
            <damping>1</damping>
            <friction>0</friction>
            <spring_reference>0</spring_reference>
            <spring_stiffness>0</spring_stiffness>
          </dynamics>
          <use_parent_model_frame>1</use_parent_model_frame>
        </axis>
        <physics>
          <ode>
            <implicit_spring_damper>1</implicit_spring_damper>
            <cfm_damping>1</cfm_damping>
            <limit>
              <cfm>0</cfm>
              <erp>0.2</erp>
            </limit>
          </ode>
        </physics>
      </joint>
      <link name='iCub::r_shoulder_1'>
        <pose frame=''>-0.010749 0.11026 0.1753 -2.87979 -1.57079 -1e-06</pose>
        <inertial>
          <pose frame=''>5e-06 0.0187 0.00119 0 -0 0</pose>
          <mass>0.189</mass>
          <inertia>
            <ixx>0.01</ixx>
            <ixy>2.1e-08</ixy>
            <ixz>-1e-09</ixz>
            <iyy>0.01</iyy>
            <iyz>4.22e-06</iyz>
            <izz>0.01</izz>
          </inertia>
        </inertial>
        <collision name='r_shoulder_1_collision'>
          <pose frame=''>-0 0.109285 0.005211 3.06003 1.57079 -1.65235</pose>
          <geometry>
            <mesh>
              <scale>1 1 1</scale>
              <uri>model://icub/meshes/collision/icub_simple_collision_r_shoulder_1.dae</uri>
            </mesh>
          </geometry>
          <max_contacts>10</max_contacts>
          <surface>
            <contact>
              <ode/>
            </contact>
            <bounce/>
            <friction>
              <torsional>
                <ode/>
              </torsional>
              <ode/>
            </friction>
          </surface>
        </collision>
        <visual name='r_shoulder_1_visual'>
          <pose frame=''>-0 0.109285 0.005211 3.06003 1.57079 -1.65235</pose>
          <geometry>
            <mesh>
              <scale>1 1 1</scale>
              <uri>model://icub/meshes/visual/icub_r_shoulder_1.dae</uri>
            </mesh>
          </geometry>
        </visual>
        <self_collide>0</self_collide>
        <kinematic>0</kinematic>
      </link>
      <joint name='iCub::r_shoulder_pitch' type='revolute'>
        <child>iCub::r_shoulder_1</child>
        <parent>iCub::chest</parent>
        <axis>
          <xyz>0.258817 -0.965926 -3e-06</xyz>
          <limit>
            <lower>-1.65806</lower>
            <upper>0.0872665</upper>
            <effort>84</effort>
            <velocity>100</velocity>
          </limit>
          <dynamics>
            <damping>1</damping>
            <friction>0</friction>
            <spring_reference>0</spring_reference>
            <spring_stiffness>0</spring_stiffness>
          </dynamics>
          <use_parent_model_frame>1</use_parent_model_frame>
        </axis>
      </joint>
      <link name='iCub::r_shoulder_2'>
        <pose frame=''>-0.010749 0.11026 0.1753 7e-06 1e-06 1.83259</pose>
        <inertial>
          <pose frame=''>-9.4e-05 -0.00627 -0.0166 0 -0 0</pose>
          <mass>0.179</mass>
          <inertia>
            <ixx>0.01</ixx>
            <ixy>-4.53e-07</ixy>
            <ixz>2.03e-07</ixz>
            <iyy>0.01</iyy>
            <iyz>2.07e-05</iyz>
            <izz>0.01</izz>
          </inertia>
        </inertial>
        <collision name='r_shoulder_2_collision'>
          <pose frame=''>-0.001545 -0.005211 -0 -1.00125 -1.57079 2.57205</pose>
          <geometry>
            <mesh>
              <scale>1 1 1</scale>
              <uri>model://icub/meshes/collision/icub_simple_collision_r_shoulder_2.dae</uri>
            </mesh>
          </geometry>
          <max_contacts>10</max_contacts>
          <surface>
            <contact>
              <ode/>
            </contact>
            <bounce/>
            <friction>
              <torsional>
                <ode/>
              </torsional>
              <ode/>
            </friction>
          </surface>
        </collision>
        <visual name='r_shoulder_2_visual'>
          <pose frame=''>-0.001545 -0.005211 -0 -1.00125 -1.57079 2.57205</pose>
          <geometry>
            <mesh>
              <scale>1 1 1</scale>
              <uri>model://icub/meshes/visual/icub_r_shoulder_2.dae</uri>
            </mesh>
          </geometry>
        </visual>
        <self_collide>0</self_collide>
        <kinematic>0</kinematic>
      </link>
      <joint name='iCub::r_shoulder_roll' type='revolute'>
        <child>iCub::r_shoulder_2</child>
        <parent>iCub::r_shoulder_1</parent>
        <axis>
          <xyz>0.965926 0.258817 -7e-06</xyz>
          <limit>
            <lower>0</lower>
            <upper>2.80649</upper>
            <effort>84</effort>
            <velocity>100</velocity>
          </limit>
          <dynamics>
            <damping>1</damping>
            <friction>0</friction>
            <spring_reference>0</spring_reference>
            <spring_stiffness>0</spring_stiffness>
          </dynamics>
          <use_parent_model_frame>1</use_parent_model_frame>
        </axis>
      </joint>
      <link name='iCub::r_shoulder_3'>
        <pose frame=''>-0.010749 0.11026 0.1753 3.14159 -7e-06 -3.14159</pose>
        <inertial>
          <pose frame=''>0.005539 -2.5e-05 0.04939 0 -0 0</pose>
          <mass>0.155</mass>
          <inertia>
            <ixx>0.01</ixx>
            <ixy>3.56977e-07</ixy>
            <ixz>-3.95372e-06</ixz>
            <iyy>0.01</iyy>
            <iyz>-6.5128e-06</iyz>
            <izz>0.01</izz>
          </inertia>
        </inertial>
        <self_collide>0</self_collide>
        <kinematic>0</kinematic>
      </link>
      <joint name='iCub::r_shoulder_yaw' type='revolute'>
        <child>iCub::r_shoulder_3</child>
        <parent>iCub::r_shoulder_2</parent>
        <axis>
          <xyz>7e-06 0 1</xyz>
          <limit>
            <lower>-0.645772</lower>
            <upper>1.74533</upper>
            <effort>34</effort>
            <velocity>100</velocity>
          </limit>
          <dynamics>
            <damping>1</damping>
            <friction>0</friction>
            <spring_reference>0</spring_reference>
            <spring_stiffness>0</spring_stiffness>
          </dynamics>
          <use_parent_model_frame>1</use_parent_model_frame>
        </axis>
      </joint>
      <link name='iCub::r_upper_arm'>
        <pose frame=''>-0.025749 0.11026 0.1073 3.14159 -7e-06 -3.14159</pose>
        <inertial>
          <pose frame=''>-0.000159 8.3e-05 0.029883 0 -0 0</pose>
          <mass>0.729</mass>
          <inertia>
            <ixx>0.01</ixx>
            <ixy>-1.08e-06</ixy>
            <ixz>-2.29e-06</ixz>
            <iyy>0.01</iyy>
            <iyz>3.57e-06</iyz>
            <izz>0.01</izz>
          </inertia>
        </inertial>
        <collision name='r_upper_arm_collision'>
          <pose frame=''>-0.020433 -0.000144 -0.068 -3.14159 -0 1.309</pose>
          <geometry>
            <mesh>
              <scale>1 1 1</scale>
              <uri>model://icub/meshes/collision/icub_simple_collision_r_arm.dae</uri>
            </mesh>
          </geometry>
          <max_contacts>10</max_contacts>
          <surface>
            <contact>
              <ode/>
            </contact>
            <bounce/>
            <friction>
              <torsional>
                <ode/>
              </torsional>
              <ode/>
            </friction>
          </surface>
        </collision>
        <visual name='r_upper_arm_visual'>
          <pose frame=''>-0.020433 -0.000144 -0.068 -3.14159 -0 1.309</pose>
          <geometry>
            <mesh>
              <scale>1 1 1</scale>
              <uri>model://icub/meshes/visual/icub_r_arm.dae</uri>
            </mesh>
          </geometry>
        </visual>
        <self_collide>0</self_collide>
        <kinematic>0</kinematic>
      </link>
      <joint name='iCub::r_arm_ft_sensor' type='revolute'>
        <child>iCub::r_upper_arm</child>
        <parent>iCub::r_shoulder_3</parent>
        <axis>
          <xyz>0 0 0</xyz>
          <limit>
            <lower>0</lower>
            <upper>0</upper>
            <effort>0</effort>
            <velocity>0</velocity>
          </limit>
          <dynamics>
            <spring_reference>0</spring_reference>
            <spring_stiffness>0</spring_stiffness>
          </dynamics>
          <use_parent_model_frame>1</use_parent_model_frame>
        </axis>
        <sensor name='right_arm_ft' type='force_torque'>
          <always_on>1</always_on>
          <update_rate>100</update_rate>
          <pose frame=''>0 0 0 0 -0 0</pose>
          <plugin name='right_arm_ft_plugin' filename='libgazebo_yarp_forcetorque.so'>
            <yarpConfigurationFile>model://icub/conf/FT/gazebo_icub_right_arm_ft.ini</yarpConfigurationFile>
          </plugin>
        </sensor>
      </joint>
      <link name='iCub::r_elbow_1'>
        <pose frame=''>-0.02575 0.11026 0.02302 -3e-06 7e-06 4e-06</pose>
        <inertial>
          <pose frame=''>0.0013 -0.00371 0.00105 0 -0 0</pose>
          <mass>0.1</mass>
          <inertia>
            <ixx>0.01</ixx>
            <ixy>-5.02e-07</ixy>
            <ixz>-3.99e-07</ixz>
            <iyy>0.01</iyy>
            <iyz>-3.71e-07</iyz>
            <izz>0.01</izz>
          </inertia>
        </inertial>
        <self_collide>0</self_collide>
        <kinematic>0</kinematic>
      </link>
      <joint name='iCub::r_elbow' type='revolute'>
        <child>iCub::r_elbow_1</child>
        <parent>iCub::r_upper_arm</parent>
        <axis>
          <xyz>-4e-06 1 -3e-06</xyz>
          <limit>
            <lower>0.0959931</lower>
            <upper>1.85005</upper>
            <effort>20</effort>
            <velocity>100</velocity>
          </limit>
          <dynamics>
            <damping>1</damping>
            <friction>0</friction>
            <spring_reference>0</spring_reference>
            <spring_stiffness>0</spring_stiffness>
          </dynamics>
          <use_parent_model_frame>1</use_parent_model_frame>
        </axis>
      </joint>
      <link name='iCub::r_forearm'>
        <pose frame=''>-0.01075 0.11026 0.02302 1.57079 -3e-06 -1.5708</pose>
        <inertial>
          <pose frame=''>-0.000347 -0.066 -0.00476 0 -0 0</pose>
          <mass>0.525</mass>
          <inertia>
            <ixx>0.01</ixx>
            <ixy>5.66e-06</ixy>
            <ixz>1.4e-06</ixz>
            <iyy>0.01</iyy>
            <iyz>1.82e-05</iyz>
            <izz>0.01</izz>
          </inertia>
        </inertial>
        <collision name='r_forearm_collision'>
          <pose frame=''>0.000144 -0 -0.020433 -1.74165 1.57079 -0.170863</pose>
          <geometry>
            <mesh>
              <scale>1 1 1</scale>
              <uri>model://icub/meshes/collision/icub_simple_collision_r_forearm.dae</uri>
            </mesh>
          </geometry>
          <max_contacts>10</max_contacts>
          <surface>
            <contact>
              <ode/>
            </contact>
            <bounce/>
            <friction>
              <torsional>
                <ode/>
              </torsional>
              <ode/>
            </friction>
          </surface>
        </collision>
        <visual name='r_forearm_visual'>
          <pose frame=''>0.000144 -0 -0.020433 -1.74165 1.57079 -0.170863</pose>
          <geometry>
            <mesh>
              <scale>1 1 1</scale>
              <uri>model://icub/meshes/visual/icub_r_forearm.dae</uri>
            </mesh>
          </geometry>
        </visual>
        <self_collide>0</self_collide>
        <kinematic>0</kinematic>
      </link>
      <joint name='iCub::r_wrist_prosup' type='revolute'>
        <child>iCub::r_forearm</child>
        <parent>iCub::r_elbow_1</parent>
        <axis>
          <xyz>3e-06 3e-06 1</xyz>
          <limit>
            <lower>-0.872665</lower>
            <upper>0.872665</upper>
            <effort>0.45</effort>
            <velocity>100</velocity>
          </limit>
          <dynamics>
            <damping>1</damping>
            <friction>0</friction>
            <spring_reference>0</spring_reference>
            <spring_stiffness>0</spring_stiffness>
          </dynamics>
          <use_parent_model_frame>1</use_parent_model_frame>
        </axis>
      </joint>
      <link name='iCub::r_wrist_1'>
        <pose frame=''>-0.01075 0.11026 -0.11428 0.426292 -1.57079 1.14451</pose>
        <inertial>
          <pose frame=''>0 0 0 0 -0 0</pose>
          <mass>0.1</mass>
          <inertia>
            <ixx>0.01</ixx>
            <ixy>0</ixy>
            <ixz>0</ixz>
            <iyy>0.01</iyy>
            <iyz>0</iyz>
            <izz>0.01</izz>
          </inertia>
        </inertial>
        <self_collide>0</self_collide>
        <kinematic>0</kinematic>
      </link>
      <joint name='iCub::r_wrist_pitch' type='revolute'>
        <child>iCub::r_wrist_1</child>
        <parent>iCub::r_forearm</parent>
        <axis>
          <xyz>-1 -4e-06 3e-06</xyz>
          <limit>
            <lower>-1.13446</lower>
            <upper>0.174533</upper>
            <effort>0.65</effort>
            <velocity>100</velocity>
          </limit>
          <dynamics>
            <damping>1</damping>
            <friction>0</friction>
            <spring_reference>0</spring_reference>
            <spring_stiffness>0</spring_stiffness>
          </dynamics>
          <use_parent_model_frame>1</use_parent_model_frame>
        </axis>
      </joint>
      <link name='iCub::r_hand'>
        <pose frame=''>-0.01075 0.11026 -0.11428 -0.720145 1.57079 -2.29094</pose>
        <inertial>
          <pose frame=''>0.07023 -0.00805 0.007 0 -0 0</pose>
          <mass>0.213</mass>
          <inertia>
            <ixx>0.01</ixx>
            <ixy>1.26e-05</ixy>
            <ixz>-6.08e-06</ixz>
            <iyy>0.01</iyy>
            <iyz>1.76e-05</iyz>
            <izz>0.01</izz>
          </inertia>
        </inertial>
        <collision name='r_hand_collision'>
          <pose frame=''>0 0.020433 0.000144 0 0 -3.14159</pose>
          <geometry>
            <mesh>
              <scale>1 1 1</scale>
              <uri>model://icub/meshes/collision/icub_simple_collision_r_hand.dae</uri>
            </mesh>
          </geometry>
          <max_contacts>10</max_contacts>
          <surface>
            <contact>
              <ode/>
            </contact>
            <bounce/>
            <friction>
              <torsional>
                <ode/>
              </torsional>
              <ode/>
            </friction>
          </surface>
        </collision>
        <visual name='r_hand_visual'>
          <pose frame=''>0 0.020433 0.000144 0 0 -3.14159</pose>
          <geometry>
            <mesh>
              <scale>1 1 1</scale>
              <uri>model://icub/meshes/visual/icub_r_hand.dae</uri>
            </mesh>
          </geometry>
        </visual>
        <self_collide>0</self_collide>
        <kinematic>0</kinematic>
      </link>
      <joint name='iCub::r_wrist_yaw' type='revolute'>
        <child>iCub::r_hand</child>
        <parent>iCub::r_wrist_1</parent>
        <axis>
          <xyz>4e-06 -1 6e-06</xyz>
          <limit>
            <lower>-0.436332</lower>
            <upper>0.436332</upper>
            <effort>0.65</effort>
            <velocity>100</velocity>
          </limit>
          <dynamics>
            <damping>1</damping>
            <friction>0</friction>
            <spring_reference>0</spring_reference>
            <spring_stiffness>0</spring_stiffness>
          </dynamics>
          <use_parent_model_frame>1</use_parent_model_frame>
        </axis>
      </joint>
      <plugin name='controlboard_torso' filename='libgazebo_yarp_controlboard.so'>
        <yarpConfigurationFile>model://icub/conf/gazebo_icub_torso.ini</yarpConfigurationFile>
        <initialConfiguration>0.0 0.0 -0.08</initialConfiguration>
      </plugin>
      <plugin name='controlboard_head' filename='libgazebo_yarp_controlboard.so'>
        <yarpConfigurationFile>model://icub/conf/gazebo_icub_head.ini</yarpConfigurationFile>
      </plugin>
      <plugin name='controlboard_left_arm_no_arm' filename='libgazebo_yarp_controlboard.so'>
        <yarpConfigurationFile>model://icub/conf/gazebo_icub_left_arm_no_hand_for_no_hand_model.ini</yarpConfigurationFile>
        <initialConfiguration>-1.575 0.2094 1.3963 0.2618 0 0 0</initialConfiguration>
      </plugin>
      <plugin name='controlboard_right_arm_no_arm' filename='libgazebo_yarp_controlboard.so'>
        <yarpConfigurationFile>model://icub/conf/gazebo_icub_right_arm_no_hand_for_no_hand_model.ini</yarpConfigurationFile>
        <initialConfiguration>-1.575 0.2094 1.3963 0.2618 0 0 0</initialConfiguration>
      </plugin>
      <plugin name='controlboard_left_leg' filename='libgazebo_yarp_controlboard.so'>
        <yarpConfigurationFile>model://icub/conf/gazebo_icub_left_leg.ini</yarpConfigurationFile>
        <initialConfiguration>1.5908 0.2141 0 -1.8176 -0.2142 0.0</initialConfiguration>
      </plugin>
      <plugin name='controlboard_right_leg' filename='libgazebo_yarp_controlboard.so'>
        <yarpConfigurationFile>model://icub/conf/gazebo_icub_right_leg.ini</yarpConfigurationFile>
        <initialConfiguration>1.5908 0.2141 0 -1.8176 -0.2142 0.0</initialConfiguration>
      </plugin>
      <plugin name='apply_external_wrench' filename='libgazebo_yarp_externalwrench.so'>
        <robotNamefromConfigFile>model://icub/conf/gazebo_icub_robotname.ini</robotNamefromConfigFile>
      </plugin>
    </model>
    <state world_name='default'>
      <sim_time>1591 833000000</sim_time>
      <real_time>396 581917617</real_time>
      <wall_time>1486650885 303268992</wall_time>
      <iterations>389032</iterations>
      <model name='chair'>
        <pose frame=''>0 0 1e-06 0 -0 0</pose>
        <scale>1 1 1</scale>
        <link name='chair::high_part'>
          <pose frame=''>1e-06 -1e-06 0.204996 0 -0 0</pose>
          <velocity>-4.5e-05 4.8e-05 8.6e-05 -1.4e-05 -3e-06 -4e-06</velocity>
          <acceleration>0.012499 0.202785 -0.066146 -0.000152 0.001849 -0.015833</acceleration>
          <wrench>0.012499 0.202785 -0.066146 0 -0 0</wrench>
        </link>
        <link name='chair::low_part'>
          <pose frame=''>0 0 0.180001 0 -0 0</pose>
          <velocity>6e-06 -5e-06 -1.5e-05 3e-06 1e-06 -0</velocity>
          <acceleration>-0.00297 -0.020683 0.012721 9.4e-05 -0.000418 0.000397</acceleration>
          <wrench>-0.00297 -0.020683 0.012721 0 -0 0</wrench>
        </link>
      </model>
      <model name='ground_plane'>
        <pose frame=''>0 0 0 0 -0 0</pose>
        <scale>1 1 1</scale>
        <link name='link'>
          <pose frame=''>0 0 0 0 -0 0</pose>
          <velocity>0 0 0 0 -0 0</velocity>
          <acceleration>0 0 0 0 -0 0</acceleration>
          <wrench>0 0 0 0 -0 0</wrench>
        </link>
      </model>
      <model name='iCub'>
        <pose frame=''>-0.027684 -0.003167 0.391531 0.002167 0.002013 3.08802</pose>
        <scale>1 1 1</scale>
        <link name='iCub::chest'>
          <pose frame=''>-0.024824 -0.003249 0.423819 1.56867 -0.082027 -0.05338</pose>
          <velocity>-0.000163 -3.5e-05 -0.001473 -0.001002 0.001584 -0.001122</velocity>
          <acceleration>-0.182296 -0.204371 -1.08299 -3.02792 0.907759 0.136279</acceleration>
          <wrench>-0.876842 -0.983022 -5.2092 0 -0 0</wrench>
        </link>
        <link name='iCub::eyes_tilt_link'>
          <pose frame=''>0.004247 -0.00416 0.737263 1.57265 0.104876 3.08849</pose>
          <velocity>0.000405 0.000102 -0.001142 0.000461 0.00164 -0.001592</velocity>
          <acceleration>0.11326 -0.002489 -0.621857 -0.546543 1.41458 0.138739</acceleration>
          <wrench>0.001133 -2.5e-05 -0.006219 0 -0 0</wrench>
        </link>
        <link name='iCub::head'>
          <pose frame=''>-0.039309 -0.002042 0.626089 -1.56893 0.104863 3.0885</pose>
          <velocity>0.0001 0.000226 -0.001036 0.000505 0.002797 -0.001598</velocity>
          <acceleration>0.118654 -0.016712 -0.701986 -0.687073 -0.852285 0.138822</acceleration>
          <wrench>0.355961 -0.050136 -2.10596 0 -0 0</wrench>
        </link>
        <link name='iCub::l_ankle_1'>
          <pose frame=''>0.142261 0.095131 0.046866 -2.77242 -1.5255 -0.208547</pose>
          <velocity>-0.000291 -2.8e-05 -0.000609 0.00026 -0.006772 -0.000621</velocity>
          <acceleration>-0.08357 0.039756 -0.237582 1.73135 -0.332496 2.38036</acceleration>
          <wrench>-0.062343 0.029658 -0.177236 0 -0 0</wrench>
        </link>
        <link name='iCub::l_ankle_2'>
          <pose frame=''>0.14226 0.09513 0.046866 -3.12506 0.042254 0.160964</pose>
          <velocity>-0.000293 -1e-05 -0.000623 0.000562 -0.006699 -0.000595</velocity>
          <acceleration>-0.003841 0.052104 -0.284299 2.9449 -0.281583 2.6142</acceleration>
          <wrench>-0.001027 0.013938 -0.07605 0 -0 0</wrench>
        </link>
        <link name='iCub::l_elbow_1'>
          <pose frame=''>0.123479 0.077989 0.586223 -1.36167 -0.393333 -1.99942</pose>
          <velocity>9.7e-05 8.5e-05 -0.000648 -0.000459 -0.004276 0.000615</velocity>
          <acceleration>0.052976 -0.074412 -0.663591 2.89143 -0.47446 -2.53576</acceleration>
          <wrench>0.005298 -0.007441 -0.066359 0 -0 0</wrench>
        </link>
        <link name='iCub::l_foot'>
          <pose frame=''>0.140617 0.095484 0.009904 -3.12506 0.042258 0.16096</pose>
          <velocity>-5e-05 3.7e-05 -0.000633 0.001723 -0.00649 -0.00051</velocity>
          <acceleration>-0.09487 0.049291 -0.212997 2.87693 -0.30026 2.59261</acceleration>
          <wrench>-0.056305 0.029254 -0.126413 0 -0 0</wrench>
        </link>
        <link name='iCub::l_forearm'>
          <pose frame=''>0.129237 0.09059 0.580474 2.67771 -1.12789 1.64787</pose>
          <velocity>0.000113 8.3e-05 -0.000641 -0.000267 -0.004351 0.00066</velocity>
          <acceleration>0.029839 -0.034942 -0.488663 1.71797 -0.901577 -2.80269</acceleration>
          <wrench>0.015666 -0.018344 -0.256548 0 -0 0</wrench>
        </link>
        <link name='iCub::l_hand'>
          <pose frame=''>0.255937 0.044705 0.6068 -0.401193 -0.192935 -0.347462</pose>
          <velocity>2.9e-05 0.000174 -7.5e-05 0.000511 -0.002439 0.000247</velocity>
          <acceleration>-0.012903 -0.020794 -0.288949 -0.437109 -0.009079 -0.586318</acceleration>
          <wrench>-0.002748 -0.004429 -0.061546 0 -0 0</wrench>
        </link>
        <link name='iCub::l_hip_1'>
          <pose frame=''>-0.023811 0.064561 0.271487 -0.002155 0.084851 -0.053759</pose>
          <velocity>-0.00049 0.000396 -0.002358 0.005154 -0.006855 -0.000264</velocity>
          <acceleration>-0.042998 0.503082 -1.55391 1.47063 -1.21683 -2.31156</acceleration>
          <wrench>-0.03242 0.379324 -1.17165 0 -0 0</wrench>
        </link>
        <link name='iCub::l_hip_2'>
          <pose frame=''>-0.023811 0.064561 0.271489 -2.95231 -1.48592 -0.028298</pose>
          <velocity>-0.000489 0.00037 -0.002327 0.00504 -0.006771 -0.001429</velocity>
          <acceleration>0.113286 0.437644 -0.86148 1.55231 -1.13592 -1.26121</acceleration>
          <wrench>0.059588 0.230201 -0.453138 0 -0 0</wrench>
        </link>
        <link name='iCub::l_hip_3'>
          <pose frame=''>0.041593 0.07523 0.265965 -2.95232 -1.48591 -0.02829</pose>
          <velocity>-0.000432 0.000138 -0.001677 0.00506 -0.006677 -0.001197</velocity>
          <acceleration>-0.081977 0.180589 -0.640597 1.5147 -1.11649 -1.12273</acceleration>
          <wrench>-0.008198 0.018059 -0.06406 0 -0 0</wrench>
        </link>
        <link name='iCub::l_lower_leg'>
          <pose frame=''>0.196107 0.100426 0.25288 -1.50642 -1.31397 0.09801</pose>
          <velocity>-0.000337 0.0001 -0.000595 -0.000787 -0.000251 -0.000544</velocity>
          <acceleration>-0.045152 0.141655 -0.307748 1.23352 -1.46645 2.61104</acceleration>
          <wrench>-0.057072 0.179052 -0.388993 0 -0 0</wrench>
        </link>
        <link name='iCub::l_shoulder_1'>
          <pose frame=''>-0.025405 0.107505 0.566829 -0.019222 0.083971 2.82548</pose>
          <velocity>0.000193 0.000133 -0.001486 -0.002903 -0.004555 -0.001242</velocity>
          <acceleration>0.082628 -0.1479 -1.09281 0.430629 -0.605862 -2.94286</acceleration>
          <wrench>0.015617 -0.027953 -0.20654 0 -0 0</wrench>
        </link>
        <link name='iCub::l_shoulder_2'>
          <pose frame=''>-0.025405 0.107505 0.566828 1.48467 -0.001299 1.46494</pose>
          <velocity>0.000197 0.000142 -0.001444 -0.002967 -0.004578 -0.000721</velocity>
          <acceleration>0.092106 -0.145071 -1.06429 0.430189 -0.606394 3.12733</acceleration>
          <wrench>0.016487 -0.025968 -0.190507 0 -0 0</wrench>
        </link>
        <link name='iCub::l_shoulder_3'>
          <pose frame=''>-0.025406 0.107505 0.566826 -1.47587 -0.433267 -1.71672</pose>
          <velocity>0.000202 0.000152 -0.001396 -0.000427 -0.004848 -0.000504</velocity>
          <acceleration>0.069072 -0.107894 -0.955855 2.90469 -0.317108 -2.87356</acceleration>
          <wrench>0.010786 -0.016848 -0.149263 0 -0 0</wrench>
        </link>
        <link name='iCub::l_upper_arm'>
          <pose frame=''>0.039983 0.08687 0.578974 -1.47587 -0.433267 -1.71672</pose>
          <velocity>0.000132 0.00012 -0.001088 -0.000415 -0.004795 -0.000531</velocity>
          <acceleration>0.048348 -0.097023 -0.82899 2.90339 -0.314797 -2.86584</acceleration>
          <wrench>0.03519 -0.070617 -0.603375 0 -0 0</wrench>
        </link>
        <link name='iCub::l_upper_leg'>
          <pose frame=''>-0.023812 0.064564 0.271503 1.76457 -1.48582 -0.032813</pose>
          <velocity>-0.000471 3.9e-05 -0.002158 -0.000127 -0.007076 0.000352</velocity>
          <acceleration>-0.068568 0.219891 -0.469368 1.54946 0.23244 -2.06709</acceleration>
          <wrench>-0.149134 0.478264 -1.02088 0 -0 0</wrench>
        </link>
        <link name='iCub::l_wrist_1'>
          <pose frame=''>0.255937 0.044705 0.6068 -0.401193 -0.192935 -0.347463</pose>
          <velocity>3e-05 0.000174 -7.2e-05 0.000524 -0.002619 -0.000131</velocity>
          <acceleration>0.007017 0.011093 -0.303156 -0.441934 -0.040747 -0.642513</acceleration>
          <wrench>0.000702 0.001109 -0.030316 0 -0 0</wrench>
        </link>
        <link name='iCub::left_eye_link'>
          <pose frame=''>0.006058 0.029792 0.7372 -3.13973 0.104876 3.08849</pose>
          <velocity>0.00046 9.9e-05 -0.001136 0.000517 0.001637 -0.00219</velocity>
          <acceleration>0.109931 -0.003048 -0.649154 -0.546433 1.41467 0.06594</acceleration>
          <wrench>0.001099 -3e-05 -0.006492 0 -0 0</wrench>
        </link>
        <link name='iCub::neck_1'>
          <pose frame=''>-0.038318 -0.002116 0.616646 0.020297 -1.46592 3.06786</pose>
          <velocity>9.7e-05 0.000206 -0.001144 -0.000941 0.002871 -0.001125</velocity>
          <acceleration>0.249604 -0.105943 -0.769301 -0.832494 -0.842818 0.344215</acceleration>
          <wrench>0.02496 -0.010594 -0.07693 0 -0 0</wrench>
        </link>
        <link name='iCub::neck_2'>
          <pose frame=''>-0.039308 -0.002042 0.626086 -0.104864 0.001834 1.51727</pose>
          <velocity>9.3e-05 0.000232 -0.000948 0.000431 0.00282 -0.00098</velocity>
          <acceleration>0.199619 -0.079799 -0.594185 -0.721648 -0.843545 0.357117</acceleration>
          <wrench>0.019962 -0.00798 -0.059419 0 -0 0</wrench>
        </link>
        <link name='iCub::r_ankle_1'>
          <pose frame=''>0.130387 -0.120595 0.047258 -0.454835 -1.52304 0.186842</pose>
          <velocity>-0.000489 -0.000745 -0.002701 -0.003792 -0.003919 -0.002617</velocity>
          <acceleration>-0.264996 0.216518 -2.12687 -0.321206 -1.30169 -1.37692</acceleration>
          <wrench>-0.197687 0.161522 -1.58664 0 -0 0</wrench>
        </link>
        <link name='iCub::r_ankle_2'>
          <pose frame=''>0.130387 -0.120595 0.047258 3.12034 0.042903 -0.268443</pose>
          <velocity>-0.000488 -0.000746 -0.002698 -0.003171 -0.00409 -0.002644</velocity>
          <acceleration>-0.237454 0.177195 -2.15489 -1.88358 -0.871424 -1.30652</acceleration>
          <wrench>-0.063519 0.0474 -0.576432 0 -0 0</wrench>
        </link>
        <link name='iCub::r_elbow_1'>
          <pose frame=''>0.113981 -0.099187 0.5866 1.77824 0.389371 -1.24994</pose>
          <velocity>-0.000113 0.000135 -0.00057 0.000937 -0.003831 -0.000942</velocity>
          <acceleration>0.135802 0.018384 -0.585234 -3.06689 -1.06878 2.36818</acceleration>
          <wrench>0.01358 0.001838 -0.058523 0 -0 0</wrench>
        </link>
        <link name='iCub::r_foot'>
          <pose frame=''>0.128649 -0.120932 0.0103 3.12034 0.042903 -0.268443</pose>
          <velocity>-0.000338 -0.000857 -0.002706 -0.003154 -0.004095 -0.00265</velocity>
          <acceleration>-0.270098 0.194472 -2.11822 -2.04536 -0.85079 -1.49594</acceleration>
          <wrench>-0.160303 0.115419 -1.25716 0 -0 0</wrench>
        </link>
        <link name='iCub::r_forearm'>
          <pose frame=''>0.118358 -0.112356 0.580904 -0.465193 1.13211 1.38542</pose>
          <velocity>-9.1e-05 0.000148 -0.000536 0.002193 -0.003505 -0.000685</velocity>
          <acceleration>0.137214 -0.023012 -0.447201 -2.9618 -1.08219 2.36059</acceleration>
          <wrench>0.072037 -0.012082 -0.23478 0 -0 0</wrench>
        </link>
        <link name='iCub::r_hand'>
          <pose frame=''>0.249243 -0.08017 0.607065 -2.74455 -0.191704 0.241134</pose>
          <velocity>-0.000155 6e-06 3e-06 0.001518 -0.001575 0.000324</velocity>
          <acceleration>0.122407 -0.06302 -0.260947 -0.249727 -0.809511 0.093082</acceleration>
          <wrench>0.026073 -0.013423 -0.055582 0 -0 0</wrench>
        </link>
        <link name='iCub::r_hip_1'>
          <pose frame=''>-0.031104 -0.071442 0.271782 3.13938 0.085535 -0.053762</pose>
          <velocity>-0.000517 0.000377 -0.003282 0.006147 -0.006358 -0.000215</velocity>
          <acceleration>0.087346 0.559922 -1.35508 1.157 -0.196952 -2.41008</acceleration>
          <wrench>0.065859 0.422181 -1.02173 0 -0 0</wrench>
        </link>
        <link name='iCub::r_hip_2'>
          <pose frame=''>-0.031104 -0.071442 0.27178 2.90109 -1.48523 -0.027933</pose>
          <velocity>-0.000522 0.000382 -0.003198 0.005817 -0.006388 -0.003928</velocity>
          <acceleration>-0.145695 0.502829 -2.0086 1.06887 -0.18024 3.06869</acceleration>
          <wrench>-0.076635 0.264488 -1.05652 0 -0 0</wrench>
        </link>
        <link name='iCub::r_hip_3'>
          <pose frame=''>0.032778 -0.089073 0.266259 2.90106 -1.48523 -0.027906</pose>
          <velocity>-0.000567 0.000161 -0.002822 0.005862 -0.006384 -0.003419</velocity>
          <acceleration>-0.197422 0.434903 -2.1135 1.1824 -0.19995 -2.29542</acceleration>
          <wrench>-0.019742 0.04349 -0.21135 0 -0 0</wrench>
        </link>
        <link name='iCub::r_lower_leg'>
          <pose frame=''>0.183693 -0.130726 0.253231 -1.65323 -1.31322 -0.187823</pose>
          <velocity>-0.000527 -0.000327 -0.002672 -0.002729 -4.4e-05 -0.00271</velocity>
          <acceleration>-0.186014 0.175184 -2.17509 0.281433 0.893241 -1.4064</acceleration>
          <wrench>-0.235121 0.221433 -2.74931 0 -0 0</wrench>
        </link>
        <link name='iCub::r_shoulder_1'>
          <pose frame=''>-0.03721 -0.112699 0.567302 -3.11825 0.082867 -2.93225</pose>
          <velocity>-6e-05 0.000121 -0.001348 0.000228 -0.004271 -0.000978</velocity>
          <acceleration>0.136339 -0.170952 -0.976155 -2.21219 -0.273913 -2.37527</acceleration>
          <wrench>0.025768 -0.03231 -0.184493 0 -0 0</wrench>
        </link>
        <link name='iCub::r_shoulder_2'>
          <pose frame=''>-0.03721 -0.112698 0.567299 1.6567 -0.00554 -1.57205</pose>
          <velocity>-5.2e-05 0.000136 -0.001308 0.000157 -0.004256 -0.000145</velocity>
          <acceleration>0.170066 -0.133956 -0.944095 -2.20671 -0.302502 -2.05572</acceleration>
          <wrench>0.030442 -0.023978 -0.168993 0 -0 0</wrench>
        </link>
        <link name='iCub::r_shoulder_3'>
          <pose frame=''>-0.03721 -0.112698 0.567297 1.4763 -0.429029 1.60942</pose>
          <velocity>-4.4e-05 0.000149 -0.00127 0.00087 -0.004236 -9.6e-05</velocity>
          <acceleration>0.14857 -0.095923 -0.863062 3.06798 -0.287329 -2.2268</acceleration>
          <wrench>0.023028 -0.014868 -0.133775 0 -0 0</wrench>
        </link>
        <link name='iCub::r_upper_arm'>
          <pose frame=''>0.030012 -0.099122 0.579368 1.4763 -0.429029 1.60942</pose>
          <velocity>-8.1e-05 0.00015 -0.000926 0.00087 -0.004229 -0.000103</velocity>
          <acceleration>0.141925 -0.032319 -0.737966 3.04597 -0.308187 -2.23048</acceleration>
          <wrench>0.103464 -0.02356 -0.537977 0 -0 0</wrench>
        </link>
        <link name='iCub::r_upper_leg'>
          <pose frame=''>-0.031104 -0.071442 0.271793 1.32332 -1.48506 -0.020943</pose>
          <velocity>-0.000429 0.000441 -0.004069 -0.003893 -0.005389 -0.003256</velocity>
          <acceleration>-0.01406 0.129669 -2.04094 -2.99766 1.3779 2.37655</acceleration>
          <wrench>-0.030579 0.282029 -4.43905 0 -0 0</wrench>
        </link>
        <link name='iCub::r_wrist_1'>
          <pose frame=''>0.249243 -0.08017 0.607065 2.74456 0.191703 -2.90046</pose>
          <velocity>-0.00016 2e-06 -4e-06 0.001531 -0.001506 0.000172</velocity>
          <acceleration>0.124426 -0.075045 -0.306594 -0.232153 -0.691877 -0.166269</acceleration>
          <wrench>0.012443 -0.007505 -0.030659 0 -0 0</wrench>
        </link>
        <link name='iCub::right_eye_link'>
          <pose frame=''>0.002436 -0.038111 0.737326 -3.13973 0.104877 3.08849</pose>
          <velocity>0.000354 0.000103 -0.001173 0.000501 0.001641 -0.002217</velocity>
          <acceleration>0.121791 -0.005083 -0.616664 -0.566737 1.41624 0.066798</acceleration>
          <wrench>0.001218 -5.1e-05 -0.006167 0 -0 0</wrench>
        </link>
        <link name='iCub::root_link'>
          <pose frame=''>-0.027684 -0.003167 0.391531 0.002167 0.002013 3.08802</pose>
          <velocity>-0.00023 -0.000251 -0.002758 0.005532 0.002308 -0.000294</velocity>
          <acceleration>-0.659761 -0.315933 -1.45331 1.1013 0.73486 -2.50769</acceleration>
          <wrench>-3.11407 -1.4912 -6.85963 0 -0 0</wrench>
        </link>
        <link name='iCub::torso_1'>
          <pose frame=''>-0.027684 -0.003167 0.391542 -3.11514 -1.48874 3.06165</pose>
          <velocity>-0.000236 -0.000326 -0.00302 0.005345 0.001278 -0.000304</velocity>
          <acceleration>-0.667873 -0.38244 -1.53873 2.70312 -0.499279 2.43666</acceleration>
          <wrench>-0.066787 -0.038244 -0.153873 0 -0 0</wrench>
        </link>
        <link name='iCub::torso_2'>
          <pose frame=''>-0.030298 -0.002957 0.423408 -3.05957 -0.00212 -1.62437</pose>
          <velocity>-0.000182 -0.000302 -0.002381 -0.001029 0.001632 -0.000825</velocity>
          <acceleration>-0.527644 -0.464064 -1.34859 2.87347 -1.07545 -0.328693</acceleration>
          <wrench>-0.052764 -0.046406 -0.134859 0 -0 0</wrench>
        </link>
      </model>
      <model name='yarp_camera'>
        <pose frame=''>0.2425 -1.40629 0.617837 -0 0.14729 1.67502</pose>
        <scale>1 1 1</scale>
        <link name='link'>
          <pose frame=''>0.2425 -1.40629 0.617837 -0 0.14729 1.67502</pose>
          <velocity>0 0 0 0 -0 0</velocity>
          <acceleration>0 0 0 0 -0 0</acceleration>
          <wrench>0 0 0 0 -0 0</wrench>
        </link>
      </model>
      <light name='sun'>
        <pose frame=''>0 0 10 0 -0 0</pose>
      </light>
      <light name='user_point_light_0'>
        <pose frame=''>6.59805 -14.4305 8.53586 0 -0 0</pose>
      </light>
      <light name='user_point_light_1'>
        <pose frame=''>-0.696301 12.2137 5.84185 0 -0 0</pose>
      </light>
    </state>
    <gui fullscreen='0'>
      <camera name='user_camera'>
        <pose frame=''>5.59663 -2.00407 2.11883 0 0.179645 2.94819</pose>
        <view_controller>orbit</view_controller>
        <projection_type>perspective</projection_type>
      </camera>
    </gui>
    <plugin name='ocra_gui_plugin' filename='libocra_gui_plugin.so'/>
    <gravity>0 0 -9.8</gravity>
    <magnetic_field>6e-06 2.3e-05 -4.2e-05</magnetic_field>
    <atmosphere type='adiabatic'/>
    <model name='yarp_camera'>
      <pose frame=''>0.908638 0.645102 0.5 0 -0 3.14</pose>
      <static>0</static>
      <link name='link'>
        <gravity>0</gravity>
        <visual name='visual'>
          <geometry>
            <box>
              <size>0.1 0.1 0.1</size>
            </box>
          </geometry>
          <transparency>0.6</transparency>
        </visual>
        <sensor name='yarp_camera_sensor' type='camera'>
          <camera name='__default__'>
            <horizontal_fov>0.5</horizontal_fov>
            <image>
              <width>1080</width>
              <height>1920</height>
            </image>
            <clip>
              <near>0.1</near>
              <far>100</far>
            </clip>
          </camera>
          <always_on>1</always_on>
          <update_rate>30</update_rate>
          <visualize>1</visualize>
          <plugin name='yarp_camera_control' filename='libyarp_camera_control.so'/>
        </sensor>
        <kinematic>0</kinematic>
        <self_collide>0</self_collide>
        <inertial>
          <inertia>
            <ixx>1</ixx>
            <ixy>0</ixy>
            <ixz>0</ixz>
            <iyy>1</iyy>
            <iyz>0</iyz>
            <izz>1</izz>
          </inertia>
          <mass>1</mass>
        </inertial>
      </link>
      <plugin name='yarp_model_move' filename='libyarp_model_move.so'/>
    </model>
    <light name='user_point_light_0' type='point'>
      <pose frame=''>-2.58082 -14.4305 1 0 -0 0</pose>
      <diffuse>0.5 0.5 0.5 1</diffuse>
      <specular>0.1 0.1 0.1 1</specular>
      <attenuation>
        <range>20</range>
        <constant>0.5</constant>
        <linear>0.01</linear>
        <quadratic>0.001</quadratic>
      </attenuation>
      <cast_shadows>0</cast_shadows>
      <direction>0 0 -1</direction>
    </light>
    <light name='user_point_light_1' type='point'>
      <pose frame=''>-0.696301 12.2137 1 0 -0 0</pose>
      <diffuse>0.5 0.5 0.5 1</diffuse>
      <specular>0.1 0.1 0.1 1</specular>
      <attenuation>
        <range>20</range>
        <constant>0.5</constant>
        <linear>0.01</linear>
        <quadratic>0.001</quadratic>
      </attenuation>
      <cast_shadows>0</cast_shadows>
      <direction>0 0 -1</direction>
    </light>
  </world>
</sdf>
